Workbook

Sheet Issue
A1: Rev | B1: Data | C1: Descrizione
A2: 1.0 | B2: 46190 | C2: Presentazione bozza
A3: 1.x | C3: Aggiornamenti template e integrazione documenti
A4: 1.7 | B4: 46244 | C4: Integrata funzione AI per recupero info da FRS
A5: 1.8 | B5: 46259 | C5: Aggiornamento doc BL 2.9 VZ_ES e BL 4.4_14 VZI_New14

Sheet ToDo
A1: Data | B1: Chi | C1: Priorità | D1: Descrizione | E1: Note
A2: 46190 | B2: Federico | C2: Alta | D2: protezione azionamenti | E2: da ricercare all'interno dei documenti, una volta collezionati tutti i doc disponibili sulla trazione
A3: 46190 | B3: Federico | C3: Alta | D3: ricerca doc propulsion | E3: in corso sui vari SGF
A4: 46190 | B4: Maurizio | C4: Alta | D4: legare manuali e CPR a documenti CONF | E4: eseguito manualmente, TBD legame automatico (vedi pt sotto)
A5: 46190 | B5: Federico | C5: Alta | D5: provare integrazione copilot | E5: Eseguita prova su FRS_Line_Voltage con compilazione automatica colonna B di Funzioni. Riutilizzabile per prossime FUNC ID
A6: 46189 | B6: Maurizio | C6: Bassa | D6: Definire struttura codice FUNC ID | E6: Valutare se necessario
A7: 46189 | B7: Maurizio | C7: Media | D7: Diagnostica: - Reperire documentazione diagnostica EVENTI + AWO per flotta - Definire modalità archiviazione file diagnostici per flotta e referenziazione in FUNZIONI | E7: Alcuni doc già recuperati, da definire criterio di archiviazione
A8: 46189 | B8: Maurizio | C8: Bassa | D8: Rivedere/Completare PBS | E8: TBD
A9: 46189 | B9: Maurizio | C9: Bassa | D9: Legare FUNZIONI a PBS ??? | E9: TBD
A10: 46189 | B10: Maurizio | C10: Bassa | D10: Pensare a come gestire in Funzioni, l'aggiornamento dei documenti richiamati. ES aggiungere campo data??? | E10: TBD
A11: 46196 | B11: Maurizio | C11: Alta | D11: Valutare se inserire colonna File Type in Conf Sheet per poter referenziare anche documenti diversi da pdf (es. file excel degli annex ICD) In tal caso modificare la costruzione del link in Funzioni | E11: la diversa tipologia di doc a disposizione potrebbe generare problemi nel referenziare i doc tramite link. Agganciare i link ad una colonna che indica il tipo di documento bypassa il problema del formato
A12: 46196 | B12: Maurizio | C12: Alta | D12: Inserire in Funzioni una colonna Doc Type che specifica la tipologia di documenti da linkare (es. CONFIG, MR_CPR, GENERAL, DIAGNOSTIC…) al quale è associato il foglio excel per la ricerca del documento (automatica nella formula del link) e la cartella di archiviazione per la costruzione del link (automatica) | E12: Dato che la costruzione del file DB e delle cartelle su Sharepoint (criterio di archiviazione) può essere ancora modificabile sulla base della tipologia di documenti che sarà necessario tracciare/archiviare, potrebbe essere utili introdurre un Doc Type che venga utilizzato sia per tracciare i doc su un foglio del DB dedicato sia per creare dinamicamente il link su cartelle ad oggi ancora "flessibili"
A13: 46197 | B13: Federico | C13: Media | D13: Pensare a come esportare il file in formato di HTML per poter essere navigabile via broswer | E13: Potrebbe essere utile in caso sia necessario reperire informazioni quando siamo a bordo treno anche da Telefono

Sheet Cartelle
A1: DESCRIZIONE | B1: NOME | C1: Livello | D1: INDIRIZZO | E1: LINK
A2: Root Sharepoint | B2: Sharepoint | C2: 0 | D2: https://gruppofsitaliane.sharepoint.com/:f:/r/sites/IngegneriaETReMezziLeggeri-Trenitalia/ | E2: =HYPERLINK(D2,"🔗") -> 🔗
A3: Cartella Documenti Ingegneria | B3: Shared%20Documents/ | C3: 1 | D3: =CONCATENATE($D$2,B3) -> https://gruppofsitaliane.sharepoint.com/:f:/r/sites/IngegneriaETReMezziLeggeri-Trenitalia/Shared%20Documents/ | E3: =HYPERLINK(D3,"🔗") -> 🔗
A4: Cartella Archiviazione doc ETR1000 | B4: DB_ETR1000/ | C4: 2 | D4: =CONCATENATE($D$3,B4) -> https://gruppofsitaliane.sharepoint.com/:f:/r/sites/IngegneriaETReMezziLeggeri-Trenitalia/Shared%20Documents/DB_ETR1000/ | E4: =HYPERLINK(D4,"🔗") -> 🔗
A5: Documenti di configurazione | B5: DOC_FLOTTE/ | C5: 3 | D5: =CONCATENATE($D$4,B5) -> https://gruppofsitaliane.sharepoint.com/:f:/r/sites/IngegneriaETReMezziLeggeri-Trenitalia/Shared%20Documents/DB_ETR1000/DOC_FLOTTE/ | E5: =HYPERLINK(D5,"🔗") -> 🔗
A6: Raccolta documentazione Funzioni | B6: DOC_FUNC/ | C6: 3 | D6: =CONCATENATE($D$4,B6) -> https://gruppofsitaliane.sharepoint.com/:f:/r/sites/IngegneriaETReMezziLeggeri-Trenitalia/Shared%20Documents/DB_ETR1000/DOC_FUNC/ | E6: =HYPERLINK(D6,"🔗") -> 🔗
A10: VINCOLI
A11: Id Flotta | B11: Riga 1
A12: DOC ID | B12: Colonna B
A13: DOC EXT | B13: Colonna C

Sheet Flotte
A1: Nome flotta | B1: ID flotta | C1: ID flotta "nativa" | D1: Ultima BL rilasciata | E1: Conf Sheet aggiornata a BL | F1: TOT Treni | G1: NUMERI TRENO
A2: VZI-50_IT Flotta base | B2: VZI_Base | C2: VZI_Base | D2: 6.3 ? | E2: 6.0 27/09/24 | F2: =COUNTIF(G2:BW2,"<>") -> 44 | G2: 1 | H2: 2 | I2: 3 | J2: 4 | K2: 5 | L2: 6 | M2: 7 | N2: 8 | O2: 9 | P2: 10 | Q2: 11 | R2: 12 | S2: 13 | T2: 14 | V2: 16 | W2: 17 | X2: 18 | Y2: 19 | AA2: 21 | AB2: 22 | AD2: 24 | AF2: 26 | AG2: 27 | AI2: 29 | AJ2: 30 | AL2: 32 | AM2: 33 | AN2: 34 | AP2: 36 | AQ2: 37 | AR2: 38 | AS2: 39 | AT2: 40 | AU2: 41 | AV2: 42 | AW2: 43 | AY2: 45 | AZ2: 46 | BB2: 48 | BE2: 46 | BF2: 47 | BG2: 48 | BH2: 49 | BI2: 50
A3: VZI-51-58_IT (New 14) | B3: VZI_New14 | C3: VZI_Base | D3: 4.4_14 09/07/2026 | E3: 4.4_14 09/07/2026 | F3: =COUNTIF(G3:BW3,"<>") -> 8 | BJ3: 51 | BK3: 52 | BL3: 53 | BM3: 54 | BN3: 55 | BO3: 56 | BP3: 57 | BQ3: 58
A4: VZ_IF Francia | B4: VZ_IF | C4: VZI_Base | D4: 4.3_IF 04/04/2025 | E4: 4.0_F 10/04/2024 | F4: =COUNTIF(G4:BW4,"<>") -> 8 | U4: 15 | AC4: 23 | AE4: 25 | AH4: 28 | AK4: 31 | BA4: 47 | BC4: 49 | BD4: 50
A5: VZ_ES Spagna | B5: VZ_ES | C5: VZI_New14 | D5: 2.9 30/06/2026 | E5: 2.9 30/06/2026 | F5: =COUNTIF(G5:BW5,"<>") -> 20 | G5: 1 | H5: 2 | I5: 3 | J5: 4 | K5: 5 | L5: 6 | M5: 7 | N5: 8 | O5: 9 | P5: 10 | Q5: 11 | R5: 12 | S5: 13 | T5: 14 | U5: 15 | V5: 16 | W5: 17 | X5: 18 | Y5: 19 | Z5: 20
A6: VZI-6_IT Full HRI (New 14) | B6: VZI-6_R1 | C6: VZI-6_R1 | D6: 5.0 15/04/2026 | E6: 4.0 ? xx/07/2025 | F6: =COUNTIF(G6:BW6,"<>") -> 6 | G6: 101 | H6: 102 | I6: 103 | J6: 104 | K6: 105 | L6: 106
A7: VZI-4_IT Full HRI | B7: VZI-4_R1 | C7: VZI-6_R1 | D7: 1.0 15/04/2026 | E7: ? | F7: =COUNTIF(G7:BW7,"<>") -> 40 | M7: 107 | N7: 108 | O7: 109 | P7: 110 | Q7: 111 | R7: 112 | S7: 113 | T7: 114 | U7: 115 | V7: 116 | W7: 117 | X7: 118 | Y7: 119 | Z7: 120 | AA7: 121 | AB7: 122 | AC7: 123 | AD7: 124 | AE7: 125 | AF7: 126 | AG7: 127 | AH7: 128 | AI7: 129 | AJ7: 130 | AK7: 131 | AL7: 132 | AM7: 133 | AN7: 134 | AO7: 135 | AP7: 136 | AQ7: 137 | AR7: 138 | AS7: 139 | AT7: 140 | AU7: 141 | AV7: 142 | AW7: 143 | AX7: 144 | AY7: 145 | AZ7: 146
A8: VZ_ES Spagna Full HRI | B8: VZ_ESxx | C8: VZI-6_R1 | F8: =COUNTIF(G8:BW8,"<>") -> 3 | AA8: 21 | AB8: 22 | AC8: 23
A9: VZ_DAI | B9: VZ_DAI | C9: VZI-6_R1 | F9: =COUNTIF(G9:BW9,"<>") -> 3 | Z9: 20 | AO9: 35 | AX9: 44

Sheet CONFIG
A1: DOC DESCRIPTION | B1: DOC ID | C1: DOC EXT | D1: VZI_Base | G1: VZI_New14 | J1: VZ_FR | M1: VZ_ES | P1: VZI-6_R1 | R1: VZI-4_R1 | T1: VZ_DAI | V1: VZ_Esxx
D2: Conf Sheet BD130033980 - BL 6.0 | G2: Conf Sheet BD140050695 - BL 4.4 | J2: Conf Sheet 3ECP414415-0001 - BL 4.0 | M2: Conf Sheet BD140047828 - BL 2.9 | P2: VZI-6_IT [R1] BL 4.0 | R2: VZI-4_IT [R1] BL 1.0 | T2: VZ-DAI BL xxx | V2: VZ_ES Full HRI BL xxx
D3: File/Codice | E3: Rev | F3: Codice Config | G3: File/Codice | H3: Rev | I3: Codice Config | J3: File/Codice | K3: Rev | L3: Codice Config | M3: File/Codice | N3: Rev | O3: Codice Config | P3: Codice | Q3: Rev | R3: Codice | S3: Rev | T3: Codice | U3: Rev | V3: Codice | W3: Rev
A4: SW Configuration
A5: SW Config. Matrix | B5: SW_Config | C5: pdf | D5: BD130033981 | E5: _ | G5: BD140050698 | H5: _ | J5: 3ECP414332-0001 | K5: _ | M5: BD140047861 | N5: \ | P5: FT080031387 | Q5: 4.3 | R5: FT080031387 | S5: 4.3
A6: Functional principle diagrams (VISIO)
A7: Drive Control | B7: FPD_Drive Control | C7: pdf | D7: 3ECP410467-0001 | E7: B | G7: 3ECP400500-0005 | H7: _ | J7: 3ECP410467-0001 | K7: B | M7: 3ECP413651-0005 | N7: _ | P7: FA010024090 | Q7: 00.2 | R7: FA010024090 | S7: 00.2
A8: Conventional Train Control | B8: FPD_Conventional Train Control | C8: pdf | D8: 3ECP410476-0001 | E8: C | G8: 3ECP400500-0014 | H8: A | J8: 3ECP307072-0001 | K8: C | M8: 3ECP413651-0014 | N8: A | P8: FA010024089 | Q8: 03.2 | R8: FA010024089 | S8: 03.2
A9: Train Protection - ATP | B9: FPD_Train Protection - ATP | C9: pdf | D9: 3ECP410482-0001 | E9: C | G9: 3ECP400500-0020 | H9: A | J9: 3ECP410482-0001 | K9: C | M9: 3ECP413651-0020 | N9: D | P9: FA010024100 | Q9: 03.2 | R9: FA010024100 | S9: 03.2
A10: TCMS Architecture | B10: FPD_TCMS Architecture | C10: pdf | D10: \ | E10: \ | G10: \ | H10: \ | J10: 3ECP307076-0001 | K10: _ | M10: 3ECP307255-0001 | N10: D | P10: FA010024104 | Q10: 00.2 | R10: FA010024104 | S10: 00.2
A11: Propulsion and Auxiliary | B11: FPD_Propulsion and Auxiliary | C11: pdf | D11: \ | E11: \ | G11: \ | H11: \ | M11: \ | N11: \ | P11: FA010024103 | Q11: 01.2 | R11: FA010024103 | S11: 01.2
A12: Line Voltage | B12: FPD_Line Voltage | C12: pdf | D12: 3ECP410475-0001 | E12: B | G12: 3ECP400500-0013 | H12: C | J12: 3ECP307079-0001 | K12: A | M12: 3ECP413651-0013 | N12: _ | P12: FA010024096 | Q12: 03.2 | R12: FA010024096 | S12: 03.2
A13: Auxiliary Electrical Supply | B13: FPD_Auxiliary Electrical Supply | C13: pdf | D13: 3ECP410465-0001 | E13: B | G13: 3ECP400500-0003 | H13: C | J13: 3ECP410465-0001 | K13: B | M13: 3ECP413651-0003 | N13: A | P13: FA010024083 | Q13: 01.2 | R13: FA010024083 | S13: 01.2
A14: Battery | B14: FPD_Battery | C14: pdf | D14: 3ECP410477-0001 | E14: B | G14: 3ECP400500-0015 | H14: _ | J14: 3ECP410477-0001 | K14: B | M14: 3ECP413651-0015 | N14: _ | P14: FA010024084 | Q14: 01.2 | R14: FA010024084 | S14: 01.2
A15: Air Supply | B15: FPD_Air Supply | C15: pdf | D15: 3ECP410463-0001 | E15: B | G15: 3ECP400500-0002 | H15: A | J15: 3ECP410463-0001 | K15: B | M15: 3ECP413651-0002 | N15: A | P15: FA010024081 | Q15: 01.2 | R15: FA010024081 | S15: 01.2
A16: Brake Control | B16: FPD_Brake Control | C16: pdf | D16: 3ECP410480-0001 | E16: C | G16: 3ECP400500-0018 | H16: B | J16: 3ECP307074-0001 | K16: E | M16: 3ECP413651-0018 | N16: A | P16: FA010024086 | Q16: 02.2 | R16: FA010024086 | S16: 02.2
A17: Bogie | B17: FPD_Bogie | C17: pdf | D17: 3ECP410466-0001 | E17: D | G17: 3ECP400500-0004 | H17: B | J17: 3ECP307081-0001 | K17: B | M17: 3ECP413651-0004 | N17: _ | P17: FA010024085 | Q17: 01.2 | R17: FA010024085 | S17: 01.2
A18: Wash Wiper | B18: FPD_Wash Wiper | C18: pdf | D18: 3ECP410473-0001 | E18: B | G18: 3ECP400500-0011 | H18: _ | J18: 3ECP307082-0001 | K18: _ | M18: 3ECP413651-0011 | N18: _ | P18: FA010024101 | Q18: 00.2 | R18: FA010024101 | S18: 00.2
A19: Windscreen heater | B19: FPD_Windscreen heater | C19: pdf | D19: 3ECP410474-0001 | E19: B | G19: 3ECP400500-0012 | H19: _ | J19: 3ECP410474-0001 | K19: B | M19: 3ECP413651-0012 | N19: _ | P19: FA010024102 | Q19: 00.2 | R19: FA010024102 | S19: 00.2
A20: Automatic Coupler | B20: FPD_Automatic Coupler | C20: pdf | D20: 3ECP410481-0001 | E20: C | G20: 3ECP400500-0019 | H20: A | J20: 3ECP307077-0001 | K20: B | M20: 3ECP413651-0019 | N20: A | P20: FA010024082 | Q20: 02.2 | R20: FA010024082 | S20: 02.2
A21: Horn | B21: FPD_Horn | C21: pdf | D21: 3ECP410468-0001 | E21: B | G21: 3ECP400500-0006 | H21: _ | J21: 3ECP410468-0001 | K21: B | M21: 3ECP413651-0006 | N21: _ | P21: FA010024094 | Q21: 00.2 | R21: FA010024094 | S21: 00.2
A22: Exterior and Interior Doors | B22: FPD_Exterior and Interior Doors | C22: pdf | D22: 3ECP410462-0001 | E22: C | G22: 3ECP400500-0001 | H22: A | J22: 3ECP307073-0001 | K22: D | M22: 3ECP413651-0001 | N22: A | P22: FA010024091 | Q22: 02.2 | R22: FA010024091 | S22: 02.2
A23: Cab HVAC | B23: FPD_Cab HVAC | C23: pdf | D23: 3ECP410470-0001 | E23: B | G23: 3ECP400500-0008 | H23: A | J23: 3ECP307084-0001 | K23: _ | M23: 3ECP413651-0008 | N23: A | P23: FA010024087 | Q23: 00.2 | R23: FA010024087 | S23: 00.2
... A30: Interior Lighting | B30: FPD_Interior Lighting | C30: pdf | D30: 3ECP410478-0001 | E30: B | G30: 3ECP400500-0016 | H30: _ | J30: 3ECP410478-0001 | K30: B | M30: 3ECP413651-0016 | N30: A | P30: FA010024095 | Q30: 01.2 | R30: FA010024095 | S30: 01.2
A31: Train Control Design System | B31: FPD_Train Control | C31: pdf | D31: \ | E31: \ | J31: 3ECP307076-0001 | K31: A | L31: manca
A32: Schematic diagram for French ATP MU | B32: FPD_ATP-MU | C32: pdf | J32: 90000056.D04 | K32: 5.0 | L32: manca
A33: Energy Meter System | B33: FPD_EMS | C33: pdf | J33: FA010031914 | K33: 00.1
A34: Functional Requirement Specification (FRS)
A35: Functional Vehicle Requirement Specification | B35: FRS_Vehicle | C35: pdf | D35: 3EST000224-9984 | E35: C | F35: 3EST000224-9984 | M35: 3ECP413839-0001 | N35: B | O35: 3ECP413839-0001 | P35: \ | Q35: \ | S35: \
A36: Drive Control | B36: FRS_Drive Control | C36: pdf | D36: 3EST000225-7909 | E36: A | F36: 3EST000225-7909 | G36: 3EST000225-7909 | H36: A | J36: 3ECP413571-0501 | K36: _ | M36: 3EST000225-7909 | N36: A | O36: 3EST000225-7909 | P36: FA020022675 | Q36: 03.2 4.0? | R36: FA020022675 | S36: 03.2 4.0?
A37: Conventional Train Control | B37: FRS_Conventional Train Control | C37: pdf | D37: 3EST000225-7916 | E37: A | F37: 3EST000225-7916 | G37: 3ECP413719-0903 | H37: _ | I37: manca | J37: FA02P021958B | K37: 2.0 | L37: 3ECP413719-0903 | M37: 3ECP413922-0903 | N37: _ | O37: 3ECP413922-0903 | P37: FA020023107 | Q37: 06.3 | R37: FA020023107 | S37: 06.3
A38: Train Protection - ATP | B38: FRS_Train Protection - ATP | C38: pdf | D38: FA020013231 | E38: 01 | F38: 3EST000225-7889 EC01P008999B | G38: FA020013231 | H38: 01 | I38: 3ECP414246-0902 | J38: FA020013231 | K38: 01 | L38: 3EST000225-7889 EC01P008999B | M38: FA020007630 | N38: 04 | O38: 3ECP413922-0902 | P38: FA020025863 | Q38: 01.3 | R38: FA020025863 | S38: 01.3
A39: Diagnostics | B39: FRS_Diagnostics | C39: pdf | D39: 3EST000225-7918 | E39: B | F39: 3EST000225-7918 | G39: 3EST000225-7918 | H39: B | I39: 3EST000225-7918 | J39: 3EST000225-7918 | K39: B | L39: 3EST000225-7918 | M39: 3ECP413922-1001 | N39: _ | O39: 3ECP413922-1001 | P39: FA020023413 | Q39: 01.2 | R39: FA020023413 | S39: 01.2
A40: Visualisation - MMI | B40: FRS_Visualisation - MMI | C40: pdf | D40: 3EST000225-7919 | E40: B | F40: 3EST000225-7919 | G40: 3EST000225-7919 | H40: B | I40: 3EST000225-7919 | J40: 3EST000225-7919 | K40: B | L40: 3EST000225-7919 | M40: 3ECP413922-1003 | N40: _ | O40: 3ECP413922-1003 | P40: FA020027681 | Q40: 03.2 | R40: FA020027681 | S40: 03.2
A41: TCMS - Operational | B41: FRS_TCMS - Operational | C41: pdf | D41: 3EST000225-7917 | E41: B | F41: 3EST000225-7917 | G41: 3EST000225-7917 | H41: B | I41: 3EST000225-7917 | J41: 3EST000225-7917 | K41: B | L41: 3EST000225-7917 | M41: 3ECP413922-0904 | N41: _ | O41: 3ECP413922-0904 | P41: FA020026278 | Q41: 02.2 | R41: FA020026278 | S41: 02.2
A42: Train to Wayside Communication (Teledia) | B42: FRS_Teledia | C42: pdf | D42: 3ECP413176-0001 | E42: _ | F42: 3ECP413176-0001 | G42: 3ECP413719-1200 | H42: _ | I42: 3ECP413719-1200 | J42: 3ECP413176-0001 | K42: _ | L42: 3ECP413176-0001 | M42: 3ECP413719-1200 | N42: _ | O42: 3ECP413719-1200 | P42: \ | Q42: \ | R42: \ | S42: \
A43: Line Voltage | B43: FRS_Line Voltage | C43: pdf | D43: 3EST000225-7907 | E43: C | F43: 3EST000225-7907 | G43: 3ECP413719-0401 | H43: _ | I43: manca | J43: 3ECP413571-0401 | K43: A | M43: 3EGH489028-2358 | N43: B | O43: 3EGH489028-2358 | P43: FA020022045 | Q43: 06.2 | R43: FA020022045 | S43: 06.2
A44: Aux Electrical Supply | B44: FRS_Aux Electrical Supply | C44: pdf | D44: 3EST000225-7914 | E44: B | F44: 3EST000225-7914 | G44: 3EST000225-7914 | H44: B | I44: 3EST000225-7914 | J44: 3ECP413571-0601 | K44: _ | M44: 3EST000225-7914 | N44: B | O44: 3EST000225-7914 | P44: FA020024537 | Q44: 03.2 | R44: FA020024537 | S44: 03.2
A45: Battery | B45: FRS_Battery | C45: pdf | D45: 3EST000225-7908 | E45: B | F45: 3EST000225-7908 | G45: 3EST000225-7908 | H45: B | I45: 3EST000225-7908 | J45: 3EST000225-7908 | K45: B | L45: 3EST000225-7908 | M45: 3EST000225-7908 | N45: B | O45: 3EST000225-7908 | P45: FA020024538 | Q45: 03.2 | R45: FA020024538 | S45: 03.2
A46: Air Supply | B46: FRS_Air Supply | C46: pdf | D46: 3EST000225-7915 | E46: D | F46: 3EST000225-7915 | G46: 3ECP413719-0603 | H46: _ | I46: 3ECP413719-0603 | J46: 3EST000225-7915 | K46: D | L46: 3EST000225-7915 | M46: 3ECP413719-0603 | N46: _ | O46: 3ECP413719-0603 | P46: FA020024531 | Q46: 01.3 | R46: FA020024531 | S46: 01.3
...

Sheet GENERAL
A1: DOC DESCRIPTION | B1: DOC ID | C1: DOC EXT | D1: VZI_Base | F1: VZI_New14 | H1: VZ_FR | J1: VZ_ES | L1: VZI-6_R1 | N1: VZI-4_R1 | P1: VZ_DAI | R1: VZ_Esxx
D2: File/Codice | E2: Rev | F2: File/Codice | G2: Rev | H2: File/Codice | I2: Rev | J2: File/Codice | K2: Rev | L2: Codice | M2: Rev | N2: Codice | O2: Rev | P2: Codice | Q2: Rev | R2: Codice | S2: Rev
A3: Functional Doc & Specification
A4: Architettura di Controllo Treno ed Interfacce di Comando | B4: FD_TCMS | C4: pdf | D4: 3ECP410429-0001 | E4: L | F4: 3ECP413973-0001 | G4: A | L4: FE010019098 | M4: 1.02
A5: Brake System | B5: FD_Brake | C5: pdf | D5: 3EGH489013-3044 | E5: F
A6: Air Supply | B6: FD_Air Supply | C6: pdf | D6: 3EGH489013-4928 | E6: A
A7: Descrizione SW PCU | B7: FD_PCU | C7: pdf | D7: 3EST000225-5111 | E7: C
A8: Descrizione SW Alta Tensione | B8: FD_High Voltage | C8: pdf | D8: 3EST000225-5113 | E8: C
A9: Descrizione SW Propulsione | B9: FD_Propulsion | C9: pdf | D9: 3EST000225-5115 | E9: C
A10: Descrizione SW DCU/L | B10: FD_DCU/L | C10: pdf | D10: 3EST000225-5117 | E10: B
A11: Descrizione SW DCU/M | B11: FD_DCU/M | C11: pdf | D11: 3EST000225-5118 | E11: G
A12: Descrizione SW ACM | B12: FD_ACM | C12: pdf | D12: 3EST000225-5119 | E12: E
A13: Descrizione SW DCU/C | B13: FD_DCU/C | C13: pdf | D13: 3EST000225-5120 | E13: C
A14: Descrizione SW LIM | B14: FD_LIM | C14: pdf | D14: 3EST000225-5132 | E14: _
A16: Product Description
A17: Converter unit TC1120 | B17: PDES_Converter | C17: pdf | D17: 3EST000228-5653 | E17: B
A18: Auxiliary converter module, CM-C S 15/10 WA V02 | B18: PDES_Auxiliary module | C18: pdf | D18: 3EST000226-1993 | E18: A
A19: Chopper converter module, CM-C L 30/07 WC V01 | B19: PDES_Chopper module | C19: pdf | D19: 3EST000226-1995 | E19: B
A20: Line converter module, CM-C M 15/15 WL V06 | B20: PDES_Line Module | C20: pdf | D20: 3EST000226-1994 | E20: B
A21: Motor converter module, CM-C S 15/10 WM V02 | B21: PDES_Motor Module | C21: pdf | D21: 3EST000226-1992 | E21: B
A22: TCMS Tech Description | B22: PDES_TCMS | C22: pdf | D22: 3EST000225-4855 | E22: E
A23: Brake Tech Description | B23: PDES_Brake | C23: pdf | D23: FTIT10002-I01TDE | E23: F00
A25: Test Specification & Report
A26: System Test Specification | B26: TS_VZI_Base | C26: pdf | D26: 3EST000225-6042 | E26: C
A27: EPVE63 Test Intervento protezioni azionamento | B27: TS_Test Protezioni azionamento EPVE63 | C27: pdf | L27: DC08060VE63 | M27: 01
A28: EPVE63 Report Intervento protezioni azionamento | B28: TS_Report Protezioni azionamento EPVE63 | C28: pdf | L28: DD04060VE63 | M28: 00
A29: Test Report HVSP | B29: TS_Report HVSP | C29: pdf | L29: DD040031058 | M29: 00.6
A30: Test High Voltage | B30: TS_Test High Voltage | C30: pdf | L30: EC070028470 | M30: 1.0
A31: Test Driver Control | B31: TS_Test Driver Control | C31: pdf | L31: EC070028753 | M31: 1.0
A32: Test Intervento protezioni azionamento | B32: TS_Test Protezioni azionamento | C32: pdf | L32: EC070045631 | M32: 2.0
A33: Combined test specification | B33: TS_Test Combined | C33: pdf | L33: EC070027996 | M33: 2.0
A34: Prove HVSP in combined test | B34: TS_Test HVSP Combined | C34: pdf | L34: EC070030298 | M34: 00.2
A35: Manuals (other)
A36: Manuale uso e depannage - Apparecchiature Segnalamento Francia | B36: MAN_GDA-VZI_Base | C36: pdf | J36: ETR1000V300_FR-DC100002740 | K36: 03

Sheet MAN_CPR
A1: DOC DESCRIPTION | B1: DOC ID | C1: DOC EXT | D1: TIPO | E1: VOLUME SUBVOLUME _TOMO | F1: VZI_Base | J1: VZI_New14 | N1: VZ_FR | R1: VZ-ES | V1: VZI-6_R1 | Z1: VZI-4_R1
F2: NOME FILE | G2: CODICE | H2: REV | I2: DATA | J2: NOME FILE | K2: CODICE | L2: REV | M2: DATA | N2: NOME FILE | O2: CODICE | P2: REV | Q2: DATA | R2: NOME FILE | S2: CODICE | T2: REV | U2: DATA | V2: NOME FILE | W2: CODICE | X2: REV | Y2: DATA | Z2: NOME FILE | AA2: CODICE | AB2: REV | AC2: DATA
A3: Descrizione generale e funzionamento | B3: =CONCATENATE(D3,"_",E3) -> PBC_01A | C3: pdf | D3: PBC | E3: 01A | F3: =CONCATENATE("ETR1000V300-",$D3,"-",$E3) -> ETR1000V300-PBC-01A | G3: =CONCATENATE(F3,"-",H3) -> ETR1000V300-PBC-01A-14 | H3: 14 | I3: 46113 | J3: =$F3 -> ETR1000V300-PBC-01A | K3: =$G3 -> ETR1000V300-PBC-01A-14 | L3: =$H3 -> 14 | M3: =$I3 -> 46113 | N3: =CONCATENATE("ETR1000V300_FR-",$D3,"-",$E3) -> ETR1000V300_FR-PBC-01A | O3: =CONCATENATE(N3,"-",P3) -> ETR1000V300_FR-PBC-01A-03 | P3: 03 | Q3: 43922 | R3: =CONCATENATE("ETR1000V300_ES-",$D3,"-",$E3) -> ETR1000V300_ES-PBC-01A | S3: =CONCATENATE(R3,"-",T3) -> ETR1000V300_ES-PBC-01A-03 | T3: 03 | U3: 45566 | V3: =CONCATENATE("ETR1000V300_R1-",$D3,"-",$E3) -> ETR1000V300_R1-PBC-01A | W3: =CONCATENATE(V3,"-",X3) -> ETR1000V300_R1-PBC-01A-06 | X3: 06 | Y3: 45870 | Z3: =V3 -> ETR1000V300_R1-PBC-01A | AA3: =W3 -> ETR1000V300_R1-PBC-01A-06 | AB3: =X3 -> 06 | AC3: =Y3 -> 45870
A4: Norme d’Uso ed Interventi di Emergenza | B4: =CONCATENATE(D4,"_",E4) -> PBC_01B | C4: pdf | D4: PBC | E4: 01B | F4: =CONCATENATE("ETR1000V300-",$D4,"-",$E4) -> ETR1000V300-PBC-01B | G4: =CONCATENATE(F4,"-",H4) -> ETR1000V300-PBC-01B-14 | H4: 14 | I4: 45748 | J4: =$F4 -> ETR1000V300-PBC-01B | K4: =$G4 -> ETR1000V300-PBC-01B-14 | L4: =$H4 -> 14 | M4: =$I4 -> 45748 | N4: =CONCATENATE("ETR1000V300_FR-",$D4,"-",$E4) -> ETR1000V300_FR-PBC-01B | O4: =CONCATENATE(N4,"-",P4) -> ETR1000V300_FR-PBC-01B-03 | P4: 03 | Q4: 43922 | R4: =CONCATENATE("ETR1000V300_ES-",$D4,"-",$E4) -> ETR1000V300_ES-PBC-01B | S4: =CONCATENATE(R4,"-",T4) -> ETR1000V300_ES-PBC-01B-03 | T4: 03 | U4: 45566 | V4: =CONCATENATE("ETR1000V300_R1-",$D4,"-",$E4) -> ETR1000V300_R1-PBC-01B | W4: =CONCATENATE(V4,"-",X4) -> ETR1000V300_R1-PBC-01B-09 | X4: 09 | Y4: 45870 | Z4: =V4 -> ETR1000V300_R1-PBC-01B | AA4: =W4 -> ETR1000V300_R1-PBC-01B-09 | AB4: =X4 -> 09 | AC4: =Y4 -> 45870
A5: Manuale per il Personale di Bordo addetto alla Scorta | B5: =CONCATENATE(D5,"_",E5) -> PBS_01A | C5: pdf | D5: PBS | E5: 01A | F5: =CONCATENATE("ETR1000V300-",$D5,"-",$E5) -> ETR1000V300-PBS-01A | G5: =CONCATENATE(F5,"-",H5) -> ETR1000V300-PBS-01A-04 | H5: 04 | I5: 45748 | J5: =$F5 -> ETR1000V300-PBS-01A | K5: =$G5 -> ETR1000V300-PBS-01A-04 | L5: =$H5 -> 04 | M5: =$I5 -> 45748 | N5: =CONCATENATE("ETR1000V300_FR-",$D5,"-",$E5) -> ETR1000V300_FR-PBS-01A | O5: =CONCATENATE(N5,"-",P5) -> ETR1000V300_FR-PBS-01A-01 | P5: 01 | Q5: 43922 | R5: =CONCATENATE("ETR1000V300_ES-",$D5,"-",$E5) -> ETR1000V300_ES-PBS-01A | S5: =CONCATENATE(R5,"-",T5) -> ETR1000V300_ES-PBS-01A-03 | T5: 03 | U5: 45566 | V5: =CONCATENATE("ETR1000V300_R1-",$D5,"-",$E5) -> ETR1000V300_R1-PBS-01A | W5: =CONCATENATE(V5,"-",X5) -> ETR1000V300_R1-PBS-01A-03 | X5: 03 | Y5: 45901 | Z5: =V5 -> ETR1000V300_R1-PBS-01A | AA5: =W5 -> ETR1000V300_R1-PBS-01A-03 | AB5: =X5 -> 03 | AC5: =Y5 -> 45901
A6: Cassa | B6: =CONCATENATE(D6,"_",E6) -> MR1_01A | C6: pdf | D6: MR1 | E6: 01A | F6: =CONCATENATE("ETR1000V300-",$D6,"-",$E6) -> ETR1000V300-MR1-01A | G6: =CONCATENATE(F6,"-",H6) -> ETR1000V300-MR1-01A-08 | H6: 08 | I6: 46113 | J6: =$F6 -> ETR1000V300-MR1-01A | K6: =$G6 -> ETR1000V300-MR1-01A-08 | L6: =$H6 -> 08 | M6: =$I6 -> 46113 | N6: =CONCATENATE("ETR1000V300_FR-",$D6,"-",$E6) -> ETR1000V300_FR-MR1-01A | O6: =CONCATENATE(N6,"-",P6) -> ETR1000V300_FR-MR1-01A-01 | P6: 01 | Q6: 44105 | R6: TBD | V6: =CONCATENATE("ETR1000V300_R1-",$D6,"-",$E6) -> ETR1000V300_R1-MR1-01A | W6: =CONCATENATE(V6,"-",X6) -> ETR1000V300_R1-MR1-01A-05 | X6: 05 | Y6: gen-2026 | Z6: =V6 -> ETR1000V300_R1-MR1-01A | AA6: =W6 -> ETR1000V300_R1-MR1-01A-05 | AB6: =X6 -> 05 | AC6: =Y6 -> gen-2026
A7: Carrello | B7: =CONCATENATE(D7,"_",E7) -> MR1_02A | C7: pdf | D7: MR1 | E7: 02A | F7: =CONCATENATE("ETR1000V300-",$D7,"-",$E7) -> ETR1000V300-MR1-02A | G7: =CONCATENATE(F7,"-",H7) -> ETR1000V300-MR1-02A-14 | H7: 14 | I7: 46113 | J7: =$F7 -> ETR1000V300-MR1-02A | K7: =$G7 -> ETR1000V300-MR1-02A-14 | L7: =$H7 -> 14 | M7: =$I7 -> 46113 | N7: =CONCATENATE("ETR1000V300_FR-",$D7,"-",$E7) -> ETR1000V300_FR-MR1-02A | O7: =CONCATENATE(N7,"-",P7) -> ETR1000V300_FR-MR1-02A-02 | P7: 02 | Q7: 44713 | V7: =CONCATENATE("ETR1000V300_R1-",$D7,"-",$E7) -> ETR1000V300_R1-MR1-02A | W7: =CONCATENATE(V7,"-",X7) -> ETR1000V300_R1-MR1-02A-08 | X7: 08 | Y7: gen-2026 | Z7: =V7 -> ETR1000V300_R1-MR1-02A | AA7: =W7 -> ETR1000V300_R1-MR1-02A-08 | AB7: =X7 -> 08 | AC7: =Y7 -> gen-2026
A8: Impianto pneumatico e freno | B8: =CONCATENATE(D8,"_",E8) -> MR1_03A | C8: pdf | D8: MR1 | E8: 03A | F8: =CONCATENATE("ETR1000V300-",$D8,"-",$E8) -> ETR1000V300-MR1-03A | G8: =CONCATENATE(F8,"-",H8) -> ETR1000V300-MR1-03A-09 | H8: 09 | I8: 46113 | J8: =$F8 -> ETR1000V300-MR1-03A | K8: =$G8 -> ETR1000V300-MR1-03A-09 | L8: =$H8 -> 09 | M8: =$I8 -> 46113 | N8: =CONCATENATE("ETR1000V300_FR-",$D8,"-",$E8) -> ETR1000V300_FR-MR1-03A | O8: =CONCATENATE(N8,"-",P8) -> ETR1000V300_FR-MR1-03A-02 | P8: 02 | Q8: 44713 | V8: =CONCATENATE("ETR1000V300_R1-",$D8,"-",$E8) -> ETR1000V300_R1-MR1-03A | W8: =CONCATENATE(V8,"-",X8) -> ETR1000V300_R1-MR1-03A-04 | X8: 04 | Y8: 45992 | Z8: =V8 -> ETR1000V300_R1-MR1-03A | AA8: =W8 -> ETR1000V300_R1-MR1-03A-04 | AB8: =X8 -> 04 | AC8: =Y8 -> 45992
A9: Equipaggiamento elettrico ed elettropneumatico | B9: =CONCATENATE(D9,"_",E9) -> MR1_04A | C9: pdf | D9: MR1 | E9: 04A | F9: =CONCATENATE("ETR1000V300-",$D9,"-",$E9) -> ETR1000V300-MR1-04A | G9: =CONCATENATE(F9,"-",H9) -> ETR1000V300-MR1-04A-10 | H9: 10 | I9: 46113 | J9: =$F9 -> ETR1000V300-MR1-04A | K9: =$G9 -> ETR1000V300-MR1-04A-10 | L9: =$H9 -> 10 | M9: =$I9 -> 46113 | N9: =CONCATENATE("ETR1000V300_FR-",$D9,"-",$E9) -> ETR1000V300_FR-MR1-04A | O9: =CONCATENATE(N9,"-",P9) -> ETR1000V300_FR-MR1-04A-05 | P9: 05 | Q9: 45931 | V9: =CONCATENATE("ETR1000V300_R1-",$D9,"-",$E9) -> ETR1000V300_R1-MR1-04A | W9: =CONCATENATE(V9,"-",X9) -> ETR1000V300_R1-MR1-04A-05 | X9: 05 | Y9: gen-2026 | Z9: =V9 -> ETR1000V300_R1-MR1-04A | AA9: =W9 -> ETR1000V300_R1-MR1-04A-05 | AB9: =X9 -> 05 | AC9: =Y9 -> gen-2026
A10: Logica di comando | B10: =CONCATENATE(D10,"_",E10) -> MR1_05A | C10: pdf | D10: MR1 | E10: 05A | F10: =CONCATENATE("ETR1000V300-",$D10,"-",$E10) -> ETR1000V300-MR1-05A | G10: =CONCATENATE(F10,"-",H10) -> ETR1000V300-MR1-05A-04 | H10: 04 | I10: 46113 | J10: =$F10 -> ETR1000V300-MR1-05A | K10: =$G10 -> ETR1000V300-MR1-05A-04 | L10: =$H10 -> 04 | M10: =$I10 -> 46113 | N10: =$F10 -> ETR1000V300-MR1-05A | O10: =$G10 -> ETR1000V300-MR1-05A-04 | P10: =$H10 -> 04 | Q10: =$I10 -> 46113 | V10: =CONCATENATE("ETR1000V300_R1-",$D10,"-",$E10) -> ETR1000V300_R1-MR1-05A | W10: =CONCATENATE(V10,"-",X10) -> ETR1000V300_R1-MR1-05A-03 | X10: 03 | Y10: 45931 | Z10: =V10 -> ETR1000V300_R1-MR1-05A | AA10: =W10 -> ETR1000V300_R1-MR1-05A-03 | AB10: =X10 -> 03 | AC10: =Y10 -> 45931
A11: Logica di comando - Nodo TCN | B11: =CONCATENATE(D11,"_",E11) -> MR1_05B | C11: pdf | D11: MR1 | E11: 05B | F11: =CONCATENATE("ETR1000V300-",$D11,"-",$E11) -> ETR1000V300-MR1-05B | G11: =CONCATENATE(F11,"-",H11) -> ETR1000V300-MR1-05B-02 | H11: 02 | I11: giu-17 | J11: =$F11 -> ETR1000V300-MR1-05B | K11: =$G11 -> ETR1000V300-MR1-05B-02 | L11: =$H11 -> 02 | M11: =$I11 -> giu-17 | N11: =$F11 -> ETR1000V300-MR1-05B | O11: =$G11 -> ETR1000V300-MR1-05B-02 | P11: =$H11 -> 02 | Q11: =$I11 -> giu-17 | V11: \ | W11: \ | X11: \ | Y11: \ | Z11: =V11 -> \ | AA11: =W11 -> \ | AB11: =X11 -> \ | AC11: =Y11 -> \
A12: Azionamento di trazione | B12: =CONCATENATE(D12,"_",E12) -> MR1_06A | C12: pdf | D12: MR1 | E12: 06A | F12: =CONCATENATE("ETR1000V300-",$D12,"-",$E12) -> ETR1000V300-MR1-06A | G12: =CONCATENATE(F12,"-",H12) -> ETR1000V300-MR1-06A-05 | H12: 05 | I12: 46113 | J12: =$F12 -> ETR1000V300-MR1-06A | K12: =$G12 -> ETR1000V300-MR1-06A-05 | L12: =$H12 -> 05 | M12: =$I12 -> 46113 | N12: =$F12 -> ETR1000V300-MR1-06A | O12: =$G12 -> ETR1000V300-MR1-06A-05 | P12: =$H12 -> 05 | Q12: =$I12 -> 46113 | V12: =CONCATENATE("ETR1000V300_R1-",$D12,"-",$E12) -> ETR1000V300_R1-MR1-06A | W12: =CONCATENATE(V12,"-",X12) -> ETR1000V300_R1-MR1-06A-04 | X12: 04 | Y12: 45992 | Z12: =V12 -> ETR1000V300_R1-MR1-06A | AA12: =W12 -> ETR1000V300_R1-MR1-06A-04 | AB12: =X12 -> 04 | AC12: =Y12 -> 45992
A13: Motore di trazione | B13: =CONCATENATE(D13,"_",E13) -> MR1_07A | C13: pdf | D13: MR1 | E13: 07A | F13: =CONCATENATE("ETR1000V300-",$D13,"-",$E13) -> ETR1000V300-MR1-07A | G13: =CONCATENATE(F13,"-",H13) -> ETR1000V300-MR1-07A-07 | H13: 07 | I13: 46113 | J13: =$F13 -> ETR1000V300-MR1-07A | K13: =$G13 -> ETR1000V300-MR1-07A-07 | L13: =$H13 -> 07 | M13: =$I13 -> 46113 | N13: =$F13 -> ETR1000V300-MR1-07A | O13: =$G13 -> ETR1000V300-MR1-07A-07 | P13: =$H13 -> 07 | Q13: =$I13 -> 46113 | V13: =CONCATENATE("ETR1000V300_R1-",$D13,"-",$E13) -> ETR1000V300_R1-MR1-07A | W13: =CONCATENATE(V13,"-",X13) -> ETR1000V300_R1-MR1-07A-04 | X13: 04 | Y13: 45931 | Z13: =V13 -> ETR1000V300_R1-MR1-07A | AA13: =W13 -> ETR1000V300_R1-MR1-07A-04 | AB13: =X13 -> 04 | AC13: =Y13 -> 45931
A14: Passaggi esterni | B14: =CONCATENATE(D14,"_",E14) -> MR1_08A | C14: pdf | D14: MR1 | E14: 08A | F14: =CONCATENATE("ETR1000V300-",$D14,"-",$E14) -> ETR1000V300-MR1-08A | G14: =CONCATENATE(F14,"-",H14) -> ETR1000V300-MR1-08A-05 | H14: 05 | I14: 46113 | J14: =$F14 -> ETR1000V300-MR1-08A | K14: =$G14 -> ETR1000V300-MR1-08A-05 | L14: =$H14 -> 05 | M14: =$I14 -> 46113 | N14: =$F14 -> ETR1000V300-MR1-08A | O14: =$G14 -> ETR1000V300-MR1-08A-05 | P14: =$H14 -> 05 | Q14: =$I14 -> 46113 | V14: =CONCATENATE("ETR1000V300_R1-",$D14,"-",$E14) -> ETR1000V300_R1-MR1-08A | W14: =CONCATENATE(V14,"-",X14) -> ETR1000V300_R1-MR1-08A-04 | X14: 04 | Y14: 45931 | Z14: =V14 -> ETR1000V300_R1-MR1-08A | AA14: =W14 -> ETR1000V300_R1-MR1-08A-04 | AB14: =X14 -> 04 | AC14: =Y14 -> 45931
A15: Sottosistema di climatizzazione | B15: =CONCATENATE(D15,"_",E15) -> MR1_09A | C15: pdf | D15: MR1 | E15: 09A | F15: =CONCATENATE("ETR1000V300-",$D15,"-",$E15) -> ETR1000V300-MR1-09A | G15: =CONCATENATE(F15,"-",H15) -> ETR1000V300-MR1-09A-05 | H15: 05 | I15: 46113 | J15: =$F15 -> ETR1000V300-MR1-09A | K15: =$G15 -> ETR1000V300-MR1-09A-05 | L15: =$H15 -> 05 | M15: =$I15 -> 46113 | N15: =$F15 -> ETR1000V300-MR1-09A | O15: =$G15 -> ETR1000V300-MR1-09A-05 | P15: =$H15 -> 05 | Q15: =$I15 -> 46113 | V15: =CONCATENATE("ETR1000V300_R1-",$D15,"-",$E15) -> ETR1000V300_R1-MR1-09A | W15: =CONCATENATE(V15,"-",X15) -> ETR1000V300_R1-MR1-09A-04 | X15: 04 | Y15: 45931 | Z15: =V15 -> ETR1000V300_R1-MR1-09A | AA15: =W15 -> ETR1000V300_R1-MR1-09A-04 | AB15: =X15 -> 04 | AC15: =Y15 -> 45931
A16: Sottosistema di comunicazione | B16: =CONCATENATE(D16,"_",E16) -> MR1_10A | C16: pdf | D16: MR1 | E16: 10A | F16: =CONCATENATE("ETR1000V300-",$D16,"-",$E16) -> ETR1000V300-MR1-10A | G16: =CONCATENATE(F16,"-",H16) -> ETR1000V300-MR1-10A-05 | H16: 05 | I16: 46113 | J16: =$F16 -> ETR1000V300-MR1-10A | K16: =$G16 -> ETR1000V300-MR1-10A-05 | L16: =$H16 -> 05 | M16: =$I16 -> 46113 | N16: =$F16 -> ETR1000V300-MR1-10A | O16: =$G16 -> ETR1000V300-MR1-10A-05 | P16: =$H16 -> 05 | Q16: =$I16 -> 46113 | V16: =CONCATENATE("ETR1000V300_R1-",$D16,"-",$E16) -> ETR1000V300_R1-MR1-10A | W16: =CONCATENATE(V16,"-",X16) -> ETR1000V300_R1-MR1-10A-03 | X16: 03 | Y16: 45901 | Z16: =V16 -> ETR1000V300_R1-MR1-10A | AA16: =W16 -> ETR1000V300_R1-MR1-10A-03 | AB16: =X16 -> 03 | AC16: =Y16 -> 45901
A17: Convertitore servizi ausiliari e caricabatterie | B17: =CONCATENATE(D17,"_",E17) -> MR1_11A | C17: pdf | D17: MR1 | E17: 11A | F17: =CONCATENATE("ETR1000V300-",$D17,"-",$E17) -> ETR1000V300-MR1-11A | G17: =CONCATENATE(F17,"-",H17) -> ETR1000V300-MR1-11A-03 | H17: 03 | I17: 46113 | J17: =$F17 -> ETR1000V300-MR1-11A | K17: =$G17 -> ETR1000V300-MR1-11A-03 | L17: =$H17 -> 03 | M17: =$I17 -> 46113 | N17: =$F17 -> ETR1000V300-MR1-11A | O17: =$G17 -> ETR1000V300-MR1-11A-03 | P17: =$H17 -> 03 | Q17: =$I17 -> 46113 | V17: =CONCATENATE("ETR1000V300_R1-",$D17,"-",$E17) -> ETR1000V300_R1-MR1-11A | W17: =CONCATENATE(V17,"-",X17) -> ETR1000V300_R1-MR1-11A-03 | X17: 03 | Y17: 45992 | Z17: =V17 -> ETR1000V300_R1-MR1-11A | AA17: =W17 -> ETR1000V300_R1-MR1-11A-03 | AB17: =X17 -> 03 | AC17: =Y17 -> 45992
A18: Sottosistema diagnostica di bordo | B18: =CONCATENATE(D18,"_",E18) -> MR1_13A | C18: pdf | D18: MR1 | E18: 13A | F18: =CONCATENATE("ETR1000V300-",$D18,"-",$E18) -> ETR1000V300-MR1-13A | G18: =CONCATENATE(F18,"-",H18) -> ETR1000V300-MR1-13A-03 | H18: 03 | I18: 46113 | J18: =$F18 -> ETR1000V300-MR1-13A | K18: =$G18 -> ETR1000V300-MR1-13A-03 | L18: =$H18 -> 03 | M18: =$I18 -> 46113 | N18: =$F18 -> ETR1000V300-MR1-13A | O18: =$G18 -> ETR1000V300-MR1-13A-03 | P18: =$H18 -> 03 | Q18: =$I18 -> 46113 | V18: =CONCATENATE("ETR1000V300_R1-",$D18,"-",$E18) -> ETR1000V300_R1-MR1-13A | W18: =CONCATENATE(V18,"-",X18) -> ETR1000V300_R1-MR1-13A-03 | X18: 03 | Y18: 45931 | Z18: =V18 -> ETR1000V300_R1-MR1-13A | AA18: =W18 -> ETR1000V300_R1-MR1-13A-03 | AB18: =X18 -> 03 | AC18: =Y18 -> 45931
A19: Allestimenti interni | B19: =CONCATENATE(D19,"_",E19) -> MR1_14A | C19: pdf | D19: MR1 | E19: 14A | F19: =CONCATENATE("ETR1000V300-",$D19,"-",$E19) -> ETR1000V300-MR1-14A | G19: =CONCATENATE(F19,"-",H19) -> ETR1000V300-MR1-14A-06 | H19: 06 | I19: 46113 | J19: =$F19 -> ETR1000V300-MR1-14A | K19: =$G19 -> ETR1000V300-MR1-14A-06 | L19: =$H19 -> 06 | M19: =$I19 -> 46113 | N19: =$F19 -> ETR1000V300-MR1-14A | O19: =$G19 -> ETR1000V300-MR1-14A-06 | P19: =$H19 -> 06 | Q19: =$I19 -> 46113
A20: Allestimenti interni - Arredi comparto e cabina di guida | B20: =CONCATENATE(D20,"_",E20) -> MR1_14B | C20: pdf | D20: MR1 | E20: 14B | F20: =CONCATENATE("ETR1000V300-",$D20,"-",$E20) -> ETR1000V300-MR1-14B | G20: \ | H20: \ | I20: \ | J20: =$F20 -> ETR1000V300-MR1-14B | K20: =$G20 -> \ | L20: =$H20 -> \ | M20: =$I20 -> \ | N20: =$G20 -> \ | O20: =$G20 -> \ | P20: =$H20 -> \ | Q20: =$I20 -> \ | V20: =CONCATENATE("ETR1000V300_R1-",$D20,"-",$E20) -> ETR1000V300_R1-MR1-14B | W20: =CONCATENATE(V20,"-",X20) -> ETR1000V300_R1-MR1-14B-03 | X20: 03 | Y20: 45992 | Z20: =V20 -> ETR1000V300_R1-MR1-14B | AA20: =W20 -> ETR1000V300_R1-MR1-14B-03 | AB20: =X20 -> 03 | AC20: =Y20 -> 45992
A21: Servizi Generali di Bordo - Toilette | B21: =CONCATENATE(D21,"_",E21) -> MR1_15A | C21: pdf | D21: MR1 | E21: 15A | F21: =CONCATENATE("ETR1000V300-",$D21,"-",$E21) -> ETR1000V300-MR1-15A | G21: =CONCATENATE(F21,"-",H21) -> ETR1000V300-MR1-15A-06 | H21: 06 | I21: 46113 | J21: =$F21 -> ETR1000V300-MR1-15A | K21: =$G21 -> ETR1000V300-MR1-15A-06 | L21: =$H21 -> 06 | M21: =$I21 -> 46113 | N21: =$F21 -> ETR1000V300-MR1-15A | O21: =$G21 -> ETR1000V300-MR1-15A-06 | P21: =$H21 -> 06 | Q21: =$I21 -> 46113 | V21: =CONCATENATE("ETR1000V300_R1-",$D21,"-",$E21) -> ETR1000V300_R1-MR1-15A | W21: =CONCATENATE(V21,"-",X21) -> ETR1000V300_R1-MR1-15A-03 | X21: 03 | Y21: gen-2026 | Z21: =V21 -> ETR1000V300_R1-MR1-15A | AA21: =W21 -> ETR1000V300_R1-MR1-15A-03 | AB21: =X21 -> 03 | AC21: =Y21 -> gen-2026
A22: Servizi Generali di Bordo - Bar Bistrot | B22: =CONCATENATE(D22,"_",E22) -> MR1_15B | C22: pdf | D22: MR1 | E22: 15B | F22: =CONCATENATE("ETR1000V300-",$D22,"-",$E22) -> ETR1000V300-MR1-15B | G22: \ | H22: \ | I22: \ | J22: =$F22 -> ETR1000V300-MR1-15B | K22: =$G22 -> \ | L22: =$H22 -> \ | M22: =$I22 -> \ | N22: =$G22 -> \ | O22: =$G22 -> \ | P22: =$H22 -> \ | Q22: =$I22 -> \
A23: Emergenza e recupero | B23: =CONCATENATE(D23,"_",E23) -> MR1_16A | C23: pdf | D23: MR1 | E23: 16A | F23: =CONCATENATE("ETR1000V300-",$D23,"-",$E23) -> ETR1000V300-MR1-16A | G23: =CONCATENATE(F23,"-",H23) -> ETR1000V300-MR1-16A-07 | H23: 07 | I23: 44228 | J23: =$F23 -> ETR1000V300-MR1-16A | K23: =$G23 -> ETR1000V300-MR1-16A-07 | L23: =$H23 -> 07 | M23: =$I23 -> 44228 | N23: =$F23 -> ETR1000V300-MR1-16A | O23: =$G23 -> ETR1000V300-MR1-16A-07 | P23: =$H23 -> 07 | Q23: =$I23 -> 44228
A24: Telecomunicazioni TT | B24: =CONCATENATE(D24,"_",E24) -> MR1_18A | C24: pdf | D24: MR1 | E24: 18A | F24: =CONCATENATE("ETR1000V300-",$D24,"-",$E24) -> ETR1000V300-MR1-18A | G24: =CONCATENATE(F24,"-",H24) -> ETR1000V300-MR1-18A-05 | H24: 05 | I24: 46113 | J24: =$F24 -> ETR1000V300-MR1-18A | K24: =$G24 -> ETR1000V300-MR1-18A-05 | L24: =$H24 -> 05 | M24: =$I24 -> 46113 | N24: =$F24 -> ETR1000V300-MR1-18A | O24: =$G24 -> ETR1000V300-MR1-18A-05 | P24: =$H24 -> 05 | Q24: =$I24 -> 46113 | V24: =CONCATENATE("ETR1000V300_R1-",$D24,"-",$E24) -> ETR1000V300_R1-MR1-18A | W24: =CONCATENATE(V24,"-",X24) -> ETR1000V300_R1-MR1-18A-03 | X24: 03 | Y24: 45931 | Z24: =V24 -> ETR1000V300_R1-MR1-18A | AA24: =W24 -> ETR1000V300_R1-MR1-18A-03 | AB24: =X24 -> 03 | AC24: =Y24 -> 45931
A25: Sottosistema di bordo generale | B25: =CONCATENATE(D25,"_",E25) -> MR1_20A | C25: pdf | D25: MR1 | E25: 20A | F25: =CONCATENATE("ETR1000V300-",$D25,"-",$E25) -> ETR1000V300-MR1-20A | G25: =CONCATENATE(F25,"-",H25) -> ETR1000V300-MR1-20A-03 | H25: 03 | I25: giu-20 | J25: =$F25 -> ETR1000V300-MR1-20A | K25: =$G25 -> ETR1000V300-MR1-20A-03 | L25: =$H25 -> 03 | M25: =$I25 -> giu-20 | N25: \ | O25: \ | P25: \ | Q25: \ | V25: =CONCATENATE("ETR1000V300_R1-",$D25,"-",$E25) -> ETR1000V300_R1-MR1-20A | W25: =CONCATENATE(V25,"-",X25) -> ETR1000V300_R1-MR1-20A-05 | X25: 05 | Y25: gen-2026 | Z25: =V25 -> ETR1000V300_R1-MR1-20A | AA25: =W25 -> ETR1000V300_R1-MR1-20A-05 | AB25: =X25 -> 05 | AC25: =Y25 -> gen-2026
A26: Sottosistema di bordo ETCS specifico del treno | B26: =CONCATENATE(D26,"_",E26) -> MR1_20B | C26: pdf | D26: MR1 | E26: 20B | F26: =CONCATENATE("ETR1000V300-",$D26,"-",$E26) -> ETR1000V300-MR1-20B | G26: =CONCATENATE(F26,"-",H26) -> ETR1000V300-MR1-20B-01 | H26: 01 | I26: lug-17 | J26: =$F26 -> ETR1000V300-MR1-20B | K26: =$G26 -> ETR1000V300-MR1-20B-01 | L26: =$H26 -> 01 | M26: =$I26 -> lug-17 | N26: \ | O26: \ | P26: \ | Q26: \ | V26: =CONCATENATE("ETR1000V300_R1-",$D26,"-",$E26) -> ETR1000V300_R1-MR1-20B | W26: =CONCATENATE(V26,"-",X26) -> ETR1000V300_R1-MR1-20B-02 | X26: 02 | Y26: 45931 | Z26: =V26 -> ETR1000V300_R1-MR1-20B | AA26: =W26 -> ETR1000V300_R1-MR1-20B-02 | AB26: =X26 -> 02 | AC26: =Y26 -> 45931
A27: Sottosistema di bordo generale - Linea francese | B27: =CONCATENATE(D27,"_",E27) -> MR1_20C | C27: pdf | D27: MR1 | E27: 20C | F27: \ | G27: \ | H27: \ | I27: \ | J27: =$F27 -> \ | K27: =$G27 -> \ | L27: =$H27 -> \ | M27: =$I27 -> \ | N27: =CONCATENATE("ETR1000V300_FR-",$D27,"-",$E27) -> ETR1000V300_FR-MR1-20C | O27: =CONCATENATE(N27,"-",P27) -> ETR1000V300_FR-MR1-20C-02 | P27: 02 | Q27: 44409 | V27: \ | W27: \ | X27: \ | Y27: \ | Z27: =V27 -> \ | AA27: =W27 -> \ | AB27: =X27 -> \ | AC27: =Y27 -> \
A28: Sottosistema di bordo specifico - Linea francese | B28: =CONCATENATE(D28,"_",E28) -> MR1_20D | C28: pdf | D28: MR1 | E28: 20D | F28: \ | G28: \ | H28: \ | I28: \ | J28: =$F28 -> \ | K28: =$G28 -> \ | L28: =$H28 -> \ | M28: =$I28 -> \ | N28: =CONCATENATE("ETR1000V300_FR-",$D28,"-",$E28) -> ETR1000V300_FR-MR1-20D | O28: =CONCATENATE(N28,"-",P28) -> ETR1000V300_FR-MR1-20D-01 | P28: 01 | Q28: 44136 | V28: \ | W28: \ | X28: \ | Y28: \ | Z28: =V28 -> \ | AA28: =W28 -> \ | AB28: =X28 -> \ | AC28: =Y28 -> \
A29: SSB ERTMS/SCMT (ALA) - MANUALE GENERICO USO E MANUTENZIONE (B60A.000012.640.06I) | B29: =CONCATENATE(D29,"_",E29) -> MR1_20A_ALA | C29: pdf | D29: MR1 | E29: 20A_ALA | F29: =CONCATENATE("ETR1000V300-",$D29,"-",$E29) -> ETR1000V300-MR1-20A_ALA | G29: =CONCATENATE(F29,"-",H29) -> ETR1000V300-MR1-20A_ALA-08 | H29: 08 | I29: 43966 | J29: =$F29 -> ETR1000V300-MR1-20A_ALA | K29: =$G29 -> ETR1000V300-MR1-20A_ALA-08 | L29: =$H29 -> 08 | M29: =$I29 -> 43966 | N29: \ | O29: \ | P29: \ | Q29: \
A30: SSB ERTMS/SCMT (ELO) - MANUALE GENERICO USO E MANUTENZIONE (B60X.0100506.G00.00IT rev.02.00) | B30: =CONCATENATE(D30,"_",E30) -> MR1_20A_ELO | C30: pdf | D30: MR1 | E30: 20A_ELO | F30: =CONCATENATE("ETR1000V300-",$D30,"-",$E30) -> ETR1000V300-MR1-20A_ELO | G30: =CONCATENATE(F30,"-",H30) -> ETR1000V300-MR1-20A_ELO-05 | H30: 05 | I30: 46113 | J30: =$F30 -> ETR1000V300-MR1-20A_ELO | K30: =$G30 -> ETR1000V300-MR1-20A_ELO-05 | L30: =$H30 -> 05 | M30: =$I30 -> 46113 | N30: \ | O30: \ | P30: \ | Q30: \
A31: Sotto Sistema di Bordo ERTMS BL3 CON SCMT INTEGRATO (B60A.0100914.G00.00IT) | B31: =CONCATENATE(D31,"_",E31) -> MR1_20B_ELO | C31: pdf | D31: MR1 | E31: 20B_ELO | F31: =CONCATENATE("ETR1000V300-",$D31,"-",$E31) -> ETR1000V300-MR1-20B_ELO | G31: =CONCATENATE(F31,"-",H31) -> ETR1000V300-MR1-20B_ELO-02 | H31: 02 | I31: 45717 | J31: =$F31 -> ETR1000V300-MR1-20B_ELO | K31: =$G31 -> ETR1000V300-MR1-20B_ELO-02 | L31: =$H31 -> 02 | M31: =$I31 -> 45717 | N31: \ | O31: \ | P31: \ | Q31: \
A32: PGDJ DIS-JRU FTP - PRODOTTO GENERICO DIS-JRU (FT11P035105GE03B) | B32: =CONCATENATE(D32,"_",E32) -> MR1_31A_JRU | C32: pdf | D32: MR1 | E32: 31A_JRU | F32: =CONCATENATE("ETR1000V300-",$D32,"-",$E32) -> ETR1000V300-MR1-31A_JRU | G32: =CONCATENATE(F32,"-",H32) -> ETR1000V300-MR1-31A_JRU-\ | H32: \ | I32: 44256 | J32: =$F32 -> ETR1000V300-MR1-31A_JRU | K32: =$G32 -> ETR1000V300-MR1-31A_JRU-\ | L32: =$H32 -> \ | M32: =$I32 -> 44256 | N32: \ | O32: \ | P32: \ | Q32: \
A33: Sistema informativo di condotta Generale (DIS) | B33: =CONCATENATE(D33,"_",E33) -> MR1_31A | C33: pdf | D33: MR1 | E33: 31A | F33: =CONCATENATE("ETR1000V300-",$D33,"-",$E33) -> ETR1000V300-MR1-31A | G33: =CONCATENATE(F33,"-",H33) -> ETR1000V300-MR1-31A-02 | H33: 02 | I33: gen-18 | J33: =$F33 -> ETR1000V300-MR1-31A | K33: =$G33 -> ETR1000V300-MR1-31A-02 | L33: =$H33 -> 02 | M33: =$I33 -> gen-18 | N33: =CONCATENATE("ETR1000V300_FR-",$D33,"-",$E33) -> ETR1000V300_FR-MR1-31A | O33: =CONCATENATE(N33,"-",P33) -> ETR1000V300_FR-MR1-31A-01 | P33: 01 | Q33: 44136 | V33: =CONCATENATE("ETR1000V300_R1-",$D33,"-",$E33) -> ETR1000V300_R1-MR1-31A | W33: =CONCATENATE(V33,"-",X33) -> ETR1000V300_R1-MR1-31A-04 | X33: 04 | Y33: gen-2026 | Z33: =V33 -> ETR1000V300_R1-MR1-31A | AA33: =W33 -> ETR1000V300_R1-MR1-31A-04 | AB33: =X33 -> 04 | AC33: =Y33 -> gen-2026
A34: Cassa | B34: =CONCATENATE(D34,"_",E34) -> MR2_01A | C34: pdf | D34: MR2 | E34: 01A | F34: =CONCATENATE("ETR1000V300-",$D34,"-",$E34) -> ETR1000V300-MR2-01A | G34: =CONCATENATE(F34,"-",H34) -> ETR1000V300-MR2-01A-07 | H34: 07 | I34: 46113 | J34: =$F34 -> ETR1000V300-MR2-01A | K34: =$G34 -> ETR1000V300-MR2-01A-07 | L34: =$H34 -> 07 | M34: =$I34 -> 46113 | N34: =CONCATENATE("ETR1000V300_FR-",$D34,"-",$E34) -> ETR1000V300_FR-MR2-01A | O34: =CONCATENATE(N34,"-",P34) -> ETR1000V300_FR-MR2-01A-01 | P34: 01 | Q34: 44105 | V34: =CONCATENATE("ETR1000V300_R1-",$D34,"-",$E34) -> ETR1000V300_R1-MR2-01A | W34: =CONCATENATE(V34,"-",X34) -> ETR1000V300_R1-MR2-01A-02 | X34: 02 | Y34: 45809 | Z34: =V34 -> ETR1000V300_R1-MR2-01A | AA34: =W34 -> ETR1000V300_R1-MR2-01A-02 | AB34: =X34 -> 02 | AC34: =Y34 -> 45809
A35: Carrello | B35: =CONCATENATE(D35,"_",E35) -> MR2_02A | C35: pdf | D35: MR2 | E35: 02A | F35: =CONCATENATE("ETR1000V300-",$D35,"-",$E35) -> ETR1000V300-MR2-02A | G35: =CONCATENATE(F35,"-",H35) -> ETR1000V300-MR2-02A-13 | H35: 13 | I35: 46113 | J35: =$F35 -> ETR1000V300-MR2-02A | K35: =$G35 -> ETR1000V300-MR2-02A-13 | L35: =$H35 -> 13 | M35: =$I35 -> 46113 | N35: =CONCATENATE("ETR1000V300_FR-",$D35,"-",$E35) -> ETR1000V300_FR-MR2-02A | O35: =CONCATENATE(N35,"-",P35) -> ETR1000V300_FR-MR2-02A-03 | P35: 03 | Q35: 44713 | V35: =CONCATENATE("ETR1000V300_R1-",$D35,"-",$E35) -> ETR1000V300_R1-MR2-02A | W35: =CONCATENATE(V35,"-",X35) -> ETR1000V300_R1-MR2-02A-04 | X35: 04 | Y35: 45901 | Z35: =V35 -> ETR1000V300_R1-MR2-02A | AA35: =W35 -> ETR1000V300_R1-MR2-02A-04 | AB35: =X35 -> 04 | AC35: =Y35 -> 45901
A36: Impianto pneumatico e freno | B36: =CONCATENATE(D36,"_",E36) -> MR2_03A | C36: pdf | D36: MR2 | E36: 03A | F36: =CONCATENATE("ETR1000V300-",$D36,"-",$E36) -> ETR1000V300-MR2-03A | G36: =CONCATENATE(F36,"-",H36) -> ETR1000V300-MR2-03A-06 | H36: 06 | I36: 46113 | J36: =$F36 -> ETR1000V300-MR2-03A | K36: =$G36 -> ETR1000V300-MR2-03A-06 | L36: =$H36 -> 06 | M36: =$I36 -> 46113 | N36: =CONCATENATE("ETR1000V300_FR-",$D36,"-",$E36) -> ETR1000V300_FR-MR2-03A | O36: =CONCATENATE(N36,"-",P36) -> ETR1000V300_FR-MR2-03A-02 | P36: 02 | Q36: 44713 | V36: =CONCATENATE("ETR1000V300_R1-",$D36,"-",$E36) -> ETR1000V300_R1-MR2-03A | W36: =CONCATENATE(V36,"-",X36) -> ETR1000V300_R1-MR2-03A-02 | X36: 02 | Y36: 45809 | Z36: =V36 -> ETR1000V300_R1-MR2-03A | AA36: =W36 -> ETR1000V300_R1-MR2-03A-02 | AB36: =X36 -> 02 | AC36: =Y36 -> 45809
A37: Equipaggiamento elettrico ed elettropneumatico | B37: =CONCATENATE(D37,"_",E37) -> MR2_04A | C37: pdf | D37: MR2 | E37: 04A | F37: =CONCATENATE("ETR1000V300-",$D37,"-",$E37) -> ETR1000V300-MR2-04A | G37: =CONCATENATE(F37,"-",H37) -> ETR1000V300-MR2-04A-10 | H37: 10 | I37: 46113 | J37: =$F37 -> ETR1000V300-MR2-04A | K37: =$G37 -> ETR1000V300-MR2-04A-10 | L37: =$H37 -> 10 | M37: =$I37 -> 46113 | N37: =CONCATENATE("ETR1000V300_FR-",$D37,"-",$E37) -> ETR1000V300_FR-MR2-04A | O37: =CONCATENATE(N37,"-",P37) -> ETR1000V300_FR-MR2-04A-05 | P37: 05 | Q37: 45931 | V37: =CONCATENATE("ETR1000V300_R1-",$D37,"-",$E37) -> ETR1000V300_R1-MR2-04A | W37: =CONCATENATE(V37,"-",X37) -> ETR1000V300_R1-MR2-04A-02 | X37: 02 | Y37: 45809 | Z37: =V37 -> ETR1000V300_R1-MR2-04A | AA37: =W37 -> ETR1000V300_R1-MR2-04A-02 | AB37: =X37 -> 02 | AC37: =Y37 -> 45809
A38: Logica di comando | B38: =CONCATENATE(D38,"_",E38) -> MR2_05A | C38: pdf | D38: MR2 | E38: 05A | F38: =CONCATENATE("ETR1000V300-",$D38,"-",$E38) -> ETR1000V300-MR2-05A | G38: =CONCATENATE(F38,"-",H38) -> ETR1000V300-MR2-05A-03 | H38: 03 | I38: 46113 | J38: =$F38 -> ETR1000V300-MR2-05A | K38: =$G38 -> ETR1000V300-MR2-05A-03 | L38: =$H38 -> 03 | M38: =$I38 -> 46113 | N38: =$F38 -> ETR1000V300-MR2-05A | O38: =$G38 -> ETR1000V300-MR2-05A-03 | P38: =$H38 -> 03 | Q38: =$I38 -> 46113 | V38: =CONCATENATE("ETR1000V300_R1-",$D38,"-",$E38) -> ETR1000V300_R1-MR2-05A | W38: =CONCATENATE(V38,"-",X38) -> ETR1000V300_R1-MR2-05A-03 | X38: 03 | Y38: 45931 | Z38: =V38 -> ETR1000V300_R1-MR2-05A | AA38: =W38 -> ETR1000V300_R1-MR2-05A-03 | AB38: =X38 -> 03 | AC38: =Y38 -> 45931
A39: Logica di comando - Nodo TCN | B39: =CONCATENATE(D39,"_",E39) -> MR2_05B | C39: pdf | D39: MR2 | E39: 05B | F39: =CONCATENATE("ETR1000V300-",$D39,"-",$E39) -> ETR1000V300-MR2-05B | G39: =CONCATENATE(F39,"-",H39) -> ETR1000V300-MR2-05B-02 | H39: 02 | I39: giu-17 | J39: =$F39 -> ETR1000V300-MR2-05B | K39: =$G39 -> ETR1000V300-MR2-05B-02 | L39: =$H39 -> 02 | M39: =$I39 -> giu-17 | N39: =$F39 -> ETR1000V300-MR2-05B | O39: =$G39 -> ETR1000V300-MR2-05B-02 | P39: =$H39 -> 02 | Q39: =$I39 -> giu-17
A40: Azionamento di trazione | B40: =CONCATENATE(D40,"_",E40) -> MR2_06A | C40: pdf | D40: MR2 | E40: 06A | F40: =CONCATENATE("ETR1000V300-",$D40,"-",$E40) -> ETR1000V300-MR2-06A | G40: =CONCATENATE(F40,"-",H40) -> ETR1000V300-MR2-06A-04 | H40: 04 | I40: 46113 | J40: =$F40 -> ETR1000V300-MR2-06A | K40: =$G40 -> ETR1000V300-MR2-06A-04 | L40: =$H40 -> 04 | M40: =$I40 -> 46113 | N40: =$F40 -> ETR1000V300-MR2-06A | O40: =$G40 -> ETR1000V300-MR2-06A-04 | P40: =$H40 -> 04 | Q40: =$I40 -> 46113 | V40: =CONCATENATE("ETR1000V300_R1-",$D40,"-",$E40) -> ETR1000V300_R1-MR2-06A | W40: =CONCATENATE(V40,"-",X40) -> ETR1000V300_R1-MR2-06A-02 | X40: 02 | Y40: 45809 | Z40: =V40 -> ETR1000V300_R1-MR2-06A | AA40: =W40 -> ETR1000V300_R1-MR2-06A-02 | AB40: =X40 -> 02 | AC40: =Y40 -> 45809
...

Sheet DIAGNOSTIC
A1: DOC DESCRIPTION | B1: DOC ID | C1: DOC EXT | D1: VZI_Base | F1: VZI_New14 | H1: VZ_FR | J1: VZ_ES | L1: VZI-6_R1 | N1: VZI-4_R1 | P1: VZ_DAI | R1: VZ_Esxx
D2: File/Codice | E2: Rev | F2: File/Codice | G2: Rev | H2: File/Codice | I2: Rev | J2: File/Codice | K2: Rev | L2: Codice | M2: Rev | N2: Codice | O2: Rev | P2: Codice | Q2: Rev | R2: Codice | S2: Rev
A3: Telediagnostica
A4: Sviluppo regole (Algoritmi Diagnostici) | B4: DIA_Regole | C4: xlsm | D4: Sviluppo_Regole_TI_rev1.1 | E4: \ | F4: SVILUPPO REGOLE_ 14_FR_SP_Rev_0.1 | G4: \ | H4: SVILUPPO REGOLE_ 14_FR_SP_Rev_0.1 | I4: \ | J4: SVILUPPO REGOLE_ 14_FR_SP_Rev_0.1 | K4: \
A5: Event Report/List | B5: DIA_Event | C5: xlsx | D5: EventReport_VZI_3.9.0.3 | E5: \ | F5: EventReport_VZI14_BL3_5.1.0.3 2 | G5: \ | H5: EventReport VZIF 11.4.0 | I5: \ | J5: EventReport_VZS 21.2.0.3 | L5: FP010036055 | M5: 3.44
A6: Teledia Signal List | B6: DIA_Signal | C6: xlsx | L6: FP020046917 | M6: 3.44
A7: PropulsionDiagnosticDataset | B7: DIA_Dataset_Propulsion | C7: xlsx | L7: PropulsionDiagnosticDataset | M7: 00.12
A8: EMS ICD diagnostic event | B8: DIA_Event EMS | C8: xlsx | H8: EC130034365 | I8: 00

Sheet Funzioni
A1: FUNC ID | B1: DESCRIZIONE FUNZIONE | C1: DOC CARTELLA | D1: DOC ID | E1: Info DOC | F1: VZI_Base | G1: VZI_New14 | H1: VZ_FR | I1: VZ_ES | J1: VZI-6_R1 | K1: VZI-4_R1 | L1: VZ_DAI
A2: Func_XXX | B2: xxxxx | C2: HW + SW | D2: \
C3: CONFIG | D3: FS_DM1 | E3: Link | F3: {=HYPERLINK(CONCATENATE(Cartelle!$D$5,F$1,"/",$C3,"/",MID($D3,1,FIND("_",$D3)-1),"/",INDIRECT(CONCATENATE("'" & $C3 & "'!",ADDRESS(MATCH($D3, INDIRECT("'" & $C3 & "'!$B:$B"), 0),MATCH(F$1, INDIRECT("'" & $C3 & "'!$1:$1"), 0)))),".",INDIRECT(CONCATENATE("'"&$C3&"'!",ADDRESS(MATCH($D3,INDIRECT("'"&$C3&"'!$B:$B"),0),3))),"#page=",F4),CONCATENATE("#Sharepoint//",$D3))} -> #Sharepoint//FS_DM1 | J3: {=HYPERLINK(CONCATENATE(Cartelle!$D$5,INDEX(INDIRECT("'" & $C3 & "'!$1:$1"), 1, MATCH(INDIRECT(CONCATENATE("'" & $C3 & "'!",ADDRESS(MATCH($D3, INDIRECT("'" & $C3 & "'!$B:$B"), 0),MATCH(J$1, INDIRECT("'" & $C3 & "'!$1:$1"), 0)))),INDIRECT(CONCATENATE("'" & $C3 & "'!",MATCH($D3, INDIRECT("'" & $C3 & "'!$B:$B"), 0),":",MATCH($D3, INDIRECT("'" & $C3 & "'!$B:$B"), 0))),0)),"/",$C3,"/",MID($D3,1,FIND("_",$D3)-1),"/",INDIRECT(CONCATENATE("'" & $C3 & "'!",ADDRESS(MATCH($D3, INDIRECT("'" & $C3 & "'!$B:$B"), 0),MATCH(J$1, INDIRECT("'" & $C3 & "'!$1:$1"), 0)))),".",INDIRECT(CONCATENATE("'"&$C3&"'!",ADDRESS(MATCH($D3,INDIRECT("'"&$C3&"'!$B:$B"),0),3))),"#page=",J4),CONCATENATE("#Sharepoint//",$D3))} -> #Sharepoint//FS_DM1
B4: {=INDIRECT("'" & $C9 & "'!B5")} -> PBS_01A | E4: Rif. Pagina | F4: 1 | J4: 1
C5: CONFIG | D5: FRS_xx | E5: Link | F5: {=HYPERLINK(CONCATENATE(Cartelle!$D$5,F$1,"/CONFIG/",MID($D5,1,FIND("_",$D5)-1),"/",INDIRECT(CONCATENATE("'CONFIG'!",ADDRESS(MATCH($D5, CONFIG!$B:$B, 0),MATCH(F$1, CONFIG!$1:$1, 0)))),".pdf#page=",F6),CONCATENATE("#Sharepoint//",$D5))} -> #N/A | J5: {=HYPERLINK(CONCATENATE(Cartelle!$D$5,J$1,"/CONFIG/",MID($D5,1,FIND("_",$D5)-1),"/",INDIRECT(CONCATENATE("'CONFIG'!",ADDRESS(MATCH($D5, CONFIG!$B:$B, 0),MATCH(J$1, CONFIG!$1:$1, 0)))),".pdf#page=",J6),CONCATENATE("#Sharepoint//",$D5))} -> #N/A
E6: Rif. Pagina | F6: 1 | J6: 1
C7: CONFIG | D7: FPD_xx | E7: Link | F7: {=HYPERLINK(CONCATENATE(Cartelle!$D$5,F$1,"/CONFIG/",MID($D7,1,FIND("_",$D7)-1),"/",INDIRECT(CONCATENATE("'CONFIG'!",ADDRESS(MATCH($D7, CONFIG!$B:$B, 0),MATCH(F$1, CONFIG!$1:$1, 0)))),".pdf#page=",F8),CONCATENATE("#Sharepoint//",$D7))} -> #N/A | J7: {=HYPERLINK(CONCATENATE(Cartelle!$D$5,J$1,"/CONFIG/",MID($D7,1,FIND("_",$D7)-1),"/",INDIRECT(CONCATENATE("'CONFIG'!",ADDRESS(MATCH($D7, CONFIG!$B:$B, 0),MATCH(J$1, CONFIG!$1:$1, 0)))),".pdf#page=",J8),CONCATENATE("#Sharepoint//",$D7))} -> #N/A
E8: Rif. Pagina | F8: 1 | J8: 1
C9: MAN_CPR | D9: PBC_01A | E9: Link | F9: {=HYPERLINK(CONCATENATE(Cartelle!$D$5,F$1,"/",$C9,"/",MID($D9,1,FIND("_",$D9)-1),"/",INDIRECT(CONCATENATE("'" & $C9 & "'!",ADDRESS(MATCH($D9, INDIRECT("'" & $C9 & "'!$B:$B"), 0),MATCH(F$1, INDIRECT("'" & $C9 & "'!$1:$1"), 0)))),".",INDIRECT(CONCATENATE("'"&$C9&"'!",ADDRESS(MATCH($D9,INDIRECT("'"&$C9&"'!$B:$B"),0),3))),"#page=",F10),CONCATENATE("#Sharepoint//",$D9))} -> #Sharepoint//PBC_01A | G9: {=HYPERLINK(CONCATENATE(Cartelle!$D$5,INDEX(INDIRECT("'" & $C9 & "'!$1:$1"), 1, MATCH(INDIRECT(CONCATENATE("'" & $C9 & "'!",ADDRESS(MATCH($D9, INDIRECT("'" & $C9 & "'!$B:$B"), 0),MATCH(G$1, INDIRECT("'" & $C9 & "'!$1:$1"), 0)))),INDIRECT(CONCATENATE("'" & $C9 & "'!",MATCH($D9, INDIRECT("'" & $C9 & "'!$B:$B"), 0),":",MATCH($D9, INDIRECT("'" & $C9 & "'!$B:$B"), 0))),0)),"/",$C9,"/",MID($D9,1,FIND("_",$D9)-1),"/",INDIRECT(CONCATENATE("'" & $C9 & "'!",ADDRESS(MATCH($D9, INDIRECT("'" & $C9 & "'!$B:$B"), 0),MATCH(G$1, INDIRECT("'" & $C9 & "'!$1:$1"), 0)))),".",INDIRECT(CONCATENATE("'"&$C9&"'!",ADDRESS(MATCH($D9,INDIRECT("'"&$C9&"'!$B:$B"),0),3))),"#page=",G10),CONCATENATE("#Sharepoint//",$D9))} -> #Sharepoint//PBC_01A
E10: Rif. Pagina | F10: 1 | G10: 1
E11: Descrizione
C12: DIAGNOSTIC | D12: DIA_Regole | E12: Link | F12: {=HYPERLINK(CONCATENATE(Cartelle!$D$5,F$1,"/",$C12,"/",MID($D12,1,FIND("_",$D12)-1),"/",INDIRECT(CONCATENATE("'" & $C12 & "'!",ADDRESS(MATCH($D12, INDIRECT("'" & $C12 & "'!$B:$B"), 0),MATCH(F$1, INDIRECT("'" & $C12 & "'!$1:$1"), 0)))),".",INDIRECT(CONCATENATE("'"&$C12&"'!",ADDRESS(MATCH($D12,INDIRECT("'"&$C12&"'!$B:$B"),0),3))),"#page=",F13),CONCATENATE("#Sharepoint//",$D12))} -> #Sharepoint//DIA_Regole
E13: Pagina | F13: 1
B14: TBD Sottocartelle GENERAL sulla base del prefisso | C14: GENERAL | D14: FD_TCMS | E14: Link | F14: {=HYPERLINK(CONCATENATE(Cartelle!$D$5,F$1,"/",$C14,"/",MID($D14,1,FIND("_",$D14)-1),"/",INDIRECT(CONCATENATE("'" & $C14 & "'!",ADDRESS(MATCH($D14, INDIRECT("'" & $C14 & "'!$B:$B"), 0),MATCH(F$1, INDIRECT("'" & $C14 & "'!$1:$1"), 0)))),".",INDIRECT(CONCATENATE("'"&$C14&"'!",ADDRESS(MATCH($D14,INDIRECT("'"&$C14&"'!$B:$B"),0),3))),"#page=",F15),CONCATENATE("#Sharepoint//",$D14))} -> #Sharepoint//FD_TCMS
E15: Pagina | F15: 1
A16: LV_Country_code_selection | B16: Selezione su IDU del paese corrente, per informare la PCU sui pantografi selezionabili | D16: \
C17: CONFIG | D17: FRS_Line Voltage | E17: Link | F17: {=HYPERLINK(CONCATENATE(Cartelle!$D$5,F$1,"/",$C17,"/",MID($D17,1,FIND("_",$D17)-1),"/",INDIRECT(CONCATENATE("'" & $C17 & "'!",ADDRESS(MATCH($D17, INDIRECT("'" & $C17 & "'!$B:$B"), 0),MATCH(F$1, INDIRECT("'" & $C17 & "'!$1:$1"), 0)))),".",INDIRECT(CONCATENATE("'"&$C17&"'!",ADDRESS(MATCH($D17,INDIRECT("'"&$C17&"'!$B:$B"),0),3))),"#page=",F18),CONCATENATE("#Sharepoint//",$D17))} -> #Sharepoint//FRS_Line Voltage | H17: {=HYPERLINK(CONCATENATE(Cartelle!$D$5,INDEX(INDIRECT("'" & $C17 & "'!$1:$1"), 1, MATCH(INDIRECT(CONCATENATE("'" & $C17 & "'!",ADDRESS(MATCH($D17, INDIRECT("'" & $C17 & "'!$B:$B"), 0),MATCH(H$1, INDIRECT("'" & $C17 & "'!$1:$1"), 0)))),INDIRECT(CONCATENATE("'" & $C17 & "'!",MATCH($D17, INDIRECT("'" & $C17 & "'!$B:$B"), 0),":",MATCH($D17, INDIRECT("'" & $C17 & "'!$B:$B"), 0))),0)),"/",$C17,"/",MID($D17,1,FIND("_",$D17)-1),"/",INDIRECT(CONCATENATE("'" & $C17 & "'!",ADDRESS(MATCH($D17, INDIRECT("'" & $C17 & "'!$B:$B"), 0),MATCH(H$1, INDIRECT("'" & $C17 & "'!$1:$1"), 0)))),".",INDIRECT(CONCATENATE("'"&$C17&"'!",ADDRESS(MATCH($D17,INDIRECT("'"&$C17&"'!$B:$B"),0),3))),"#page=",H18),CONCATENATE("#Sharepoint//",$D17))} -> #Sharepoint//FRS_Line Voltage | I17: {=HYPERLINK(CONCATENATE(Cartelle!$D$5,INDEX(INDIRECT("'" & $C17 & "'!$1:$1"), 1, MATCH(INDIRECT(CONCATENATE("'" & $C17 & "'!",ADDRESS(MATCH($D17, INDIRECT("'" & $C17 & "'!$B:$B"), 0),MATCH(I$1, INDIRECT("'" & $C17 & "'!$1:$1"), 0)))),INDIRECT(CONCATENATE("'" & $C17 & "'!",MATCH($D17, INDIRECT("'" & $C17 & "'!$B:$B"), 0),":",MATCH($D17, INDIRECT("'" & $C17 & "'!$B:$B"), 0))),0)),"/",$C17,"/",MID($D17,1,FIND("_",$D17)-1),"/",INDIRECT(CONCATENATE("'" & $C17 & "'!",ADDRESS(MATCH($D17, INDIRECT("'" & $C17 & "'!$B:$B"), 0),MATCH(I$1, INDIRECT("'" & $C17 & "'!$1:$1"), 0)))),".",INDIRECT(CONCATENATE("'"&$C17&"'!",ADDRESS(MATCH($D17,INDIRECT("'"&$C17&"'!$B:$B"),0),3))),"#page=",I18),CONCATENATE("#Sharepoint//",$D17))} -> #Sharepoint//FRS_Line Voltage | J17: {=HYPERLINK(CONCATENATE(Cartelle!$D$5,INDEX(INDIRECT("'" & $C17 & "'!$1:$1"), 1, MATCH(INDIRECT(CONCATENATE("'" & $C17 & "'!",ADDRESS(MATCH($D17, INDIRECT("'" & $C17 & "'!$B:$B"), 0),MATCH(J$1, INDIRECT("'" & $C17 & "'!$1:$1"), 0)))),INDIRECT(CONCATENATE("'" & $C17 & "'!",MATCH($D17, INDIRECT("'" & $C17 & "'!$B:$B"), 0),":",MATCH($D17, INDIRECT("'" & $C17 & "'!$B:$B"), 0))),0)),"/",$C17,"/",MID($D17,1,FIND("_",$D17)-1),"/",INDIRECT(CONCATENATE("'" & $C17 & "'!",ADDRESS(MATCH($D17, INDIRECT("'" & $C17 & "'!$B:$B"), 0),MATCH(J$1, INDIRECT("'" & $C17 & "'!$1:$1"), 0)))),".",INDIRECT(CONCATENATE("'"&$C17&"'!",ADDRESS(MATCH($D17,INDIRECT("'"&$C17&"'!$B:$B"),0),3))),"#page=",J18),CONCATENATE("#Sharepoint//",$D17))} -> #Sharepoint//FRS_Line Voltage
E18: Rif. Pagina | F18: 7 | H18: 7 | I18: 7 | J18: 12
E19: Funzioni AI
A20: LV_Pantograph_Lifting | B20: Comando di alzamento pantografo 1 o 2 sulla base di tensione di linea (switch) e paese (IDU) selezionati | D20: \
C21: CONFIG | D21: FRS_Line Voltage | E21: Link | F21: {=HYPERLINK(CONCATENATE(Cartelle!$D$5,F$1,"/",$C21,"/",MID($D21,1,FIND("_",$D21)-1),"/",INDIRECT(CONCATENATE("'" & $C21 & "'!",ADDRESS(MATCH($D21, INDIRECT("'" & $C21 & "'!$B:$B"), 0),MATCH(F$1, INDIRECT("'" & $C21 & "'!$1:$1"), 0)))),".",INDIRECT(CONCATENATE("'"&$C21&"'!",ADDRESS(MATCH($D21,INDIRECT("'"&$C21&"'!$B:$B"),0),3))),"#page=",F22),CONCATENATE("#Sharepoint//",$D21))} -> #Sharepoint//FRS_Line Voltage | H21: {=HYPERLINK(CONCATENATE(Cartelle!$D$5,INDEX(INDIRECT("'" & $C21 & "'!$1:$1"), 1, MATCH(INDIRECT(CONCATENATE("'" & $C21 & "'!",ADDRESS(MATCH($D21, INDIRECT("'" & $C21 & "'!$B:$B"), 0),MATCH(H$1, INDIRECT("'" & $C21 & "'!$1:$1"), 0)))),INDIRECT(CONCATENATE("'" & $C21 & "'!",MATCH($D21, INDIRECT("'" & $C21 & "'!$B:$B"), 0),":",MATCH($D21, INDIRECT("'" & $C21 & "'!$B:$B"), 0))),0)),"/",$C21,"/",MID($D21,1,FIND("_",$D21)-1),"/",INDIRECT(CONCATENATE("'" & $C21 & "'!",ADDRESS(MATCH($D21, INDIRECT("'" & $C21 & "'!$B:$B"), 0),MATCH(H$1, INDIRECT("'" & $C21 & "'!$1:$1"), 0)))),".",INDIRECT(CONCATENATE("'"&$C21&"'!",ADDRESS(MATCH($D21,INDIRECT("'"&$C21&"'!$B:$B"),0),3))),"#page=",H22),CONCATENATE("#Sharepoint//",$D21))} -> #Sharepoint//FRS_Line Voltage | I21: {=HYPERLINK(CONCATENATE(Cartelle!$D$5,INDEX(INDIRECT("'" & $C21 & "'!$1:$1"), 1, MATCH(INDIRECT(CONCATENATE("'" & $C21 & "'!",ADDRESS(MATCH($D21, INDIRECT("'" & $C21 & "'!$B:$B"), 0),MATCH(I$1, INDIRECT("'" & $C21 & "'!$1:$1"), 0)))),INDIRECT(CONCATENATE("'" & $C21 & "'!",MATCH($D21, INDIRECT("'" & $C21 & "'!$B:$B"), 0),":",MATCH($D21, INDIRECT("'" & $C21 & "'!$B:$B"), 0))),0)),"/",$C21,"/",MID($D21,1,FIND("_",$D21)-1),"/",INDIRECT(CONCATENATE("'" & $C21 & "'!",ADDRESS(MATCH($D21, INDIRECT("'" & $C21 & "'!$B:$B"), 0),MATCH(I$1, INDIRECT("'" & $C21 & "'!$1:$1"), 0)))),".",INDIRECT(CONCATENATE("'"&$C21&"'!",ADDRESS(MATCH($D21,INDIRECT("'"&$C21&"'!$B:$B"),0),3))),"#page=",I22),CONCATENATE("#Sharepoint//",$D21))} -> #Sharepoint//FRS_Line Voltage | J21: {=HYPERLINK(CONCATENATE(Cartelle!$D$5,INDEX(INDIRECT("'" & $C21 & "'!$1:$1"), 1, MATCH(INDIRECT(CONCATENATE("'" & $C21 & "'!",ADDRESS(MATCH($D21, INDIRECT("'" & $C21 & "'!$B:$B"), 0),MATCH(J$1, INDIRECT("'" & $C21 & "'!$1:$1"), 0)))),INDIRECT(CONCATENATE("'" & $C21 & "'!",MATCH($D21, INDIRECT("'" & $C21 & "'!$B:$B"), 0),":",MATCH($D21, INDIRECT("'" & $C21 & "'!$B:$B"), 0))),0)),"/",$C21,"/",MID($D21,1,FIND("_",$D21)-1),"/",INDIRECT(CONCATENATE("'" & $C21 & "'!",ADDRESS(MATCH($D21, INDIRECT("'" & $C21 & "'!$B:$B"), 0),MATCH(J$1, INDIRECT("'" & $C21 & "'!$1:$1"), 0)))),".",INDIRECT(CONCATENATE("'"&$C21&"'!",ADDRESS(MATCH($D21,INDIRECT("'"&$C21&"'!$B:$B"),0),3))),"#page=",J22),CONCATENATE("#Sharepoint//",$D21))} -> #Sharepoint//FRS_Line Voltage
E22: Rif. Pagina | F22: 8 | H22: 8 | I22: 8 | J22: 13
E23: Funzioni AI
A24: LV_Pantograph_Lowering | B24: Comando di abbassamento pantografo manuale/automatico | D24: \
