Workbook

Sheet Tipologie di flotta
A1: Tipo di flotta | B1: ID flotta | C1: Ultima BL installata | D1: Conf Sheet aggiornata a BL | E1: TOT Treni | F1: NUMERI TRENO
A2: VZI-50_IT Flotta base | B2: VZI_IT_Base | C2: 5.9 ? | D2: 5.6 06/02/2020 | E2: =COUNTIF(F2:BV2,"<>") -> 44 | F2: 1 | G2: 2 | H2: 3 | I2: 4 | J2: 5 | K2: 6 | L2: 7 | M2: 8 | N2: 9 | O2: 10 | P2: 11 | Q2: 12 | R2: 13 | S2: 14 | U2: 16 | V2: 17 | W2: 18 | X2: 19 | Z2: 21 | AA2: 22 | AC2: 24 | AE2: 26 | AF2: 27 | AH2: 29 | AI2: 30 | AK2: 32 | AL2: 33 | AM2: 34 | AO2: 36 | AP2: 37 | AQ2: 38 | AR2: 39 | AS2: 40 | AT2: 41 | AU2: 42 | AV2: 43 | AX2: 45 | AY2: 46 | BA2: 48 | BD2: 46 | BE2: 47 | BF2: 48 | BG2: 49 | BH2: 50
A3: VZI-51-58_IT (New 14) | B3: VZI_IT_New14 | C3: 4.3_14 17/12/2025 | D3: 4.2_14 30/01/2025 | E3: =COUNTIF(F3:BV3,"<>") -> 8 | BI3: 51 | BJ3: 52 | BK3: 53 | BL3: 54 | BM3: 55 | BN3: 56 | BO3: 57 | BP3: 58
A4: VZI-6_IT Full HRI (New 14) | B4: VZI-6_IT_R1 | C4: 5.0 15/04/2026 | D4: 4.0 ? xx/07/2025 | E4: =COUNTIF(F4:BV4,"<>") -> 6 | F4: 101 | G4: 102 | H4: 103 | I4: 104 | J4: 105 | K4: 106
A5: VZI-4_IT Full HRI | B5: VZI-4_IT_R1 | C5: 1.0 15/04/2026 | D5: ? | E5: =COUNTIF(F5:BV5,"<>") -> 40 | L5: 107 | M5: 108 | N5: 109 | O5: 110 | P5: 111 | Q5: 112 | R5: 113 | S5: 114 | T5: 115 | U5: 116 | V5: 117 | W5: 118 | X5: 119 | Y5: 120 | Z5: 121 | AA5: 122 | AB5: 123 | AC5: 124 | AD5: 125 | AE5: 126 | AF5: 127 | AG5: 128 | AH5: 129 | AI5: 130 | AJ5: 131 | AK5: 132 | AL5: 133 | AM5: 134 | AN5: 135 | AO5: 136 | AP5: 137 | AQ5: 138 | AR5: 139 | AS5: 140 | AT5: 141 | AU5: 142 | AV5: 143 | AW5: 144 | AX5: 145 | AY5: 146
A6: VZ_IF Francia | B6: VZ_IF | E6: =COUNTIF(F6:BV6,"<>") -> 8 | T6: 15 | AB6: 23 | AD6: 25 | AG6: 28 | AJ6: 31 | AZ6: 47 | BB6: 49 | BC6: 50
A7: VZ_ES Spagna | B7: VZ_ES | C7: 2.8 16/04/2025 | D7: 2.4 09/03/2023 | E7: =COUNTIF(F7:BV7,"<>") -> 22 | F7: 1 | G7: 2 | H7: 3 | I7: 4 | J7: 5 | K7: 6 | L7: 7 | M7: 8 | N7: 9 | O7: 10 | P7: 11 | Q7: 12 | R7: 13 | S7: 14 | T7: 15 | U7: 16 | V7: 17 | W7: 18 | X7: 19 | Y7: 20 | Z7: 21 | AB7: 23
A8: VZ_DAI | B8: VZ_DAI | E8: =COUNTIF(F8:BV8,"<>") -> 3 | Y8: 20 | AN8: 35 | AW8: 44

Sheet Conf Sheet
A1: Doc Description | B1: Doc ID | C1: VZI_IT_Base | F1: VZI_IT_New14 | H1: VZI-6_IT_R1 | J1: VZI-4_IT_R1 | L1: VZ-FR | N1: VZ-ES | Q1: VZ-DAI
C2: VZI-50_ IT Flotta base BL 5.6 | F2: VZI-51-58_IT New 14 BL 4.2 | H2: VZI-6_IT [R1] BL 4.0 | J2: VZI-4_IT [R1] BL 1.0 | L2: VZ-FR | N2: VZ-ES Spagna BL 2.4 | Q2: VZ-DAI
C3: File/Codice | D3: Rev | E3: Codice Config | F3: Codice | G3: Rev | H3: Codice | I3: Rev | J3: Codice | K3: Rev | L3: Codice | M3: Rev | N3: Codice BB | O3: Codice HRI | P3: Rev | Q3: Codice | R3: Rev
A4: SW Configuration
A5: SW Config. Matrix | B5: SW_Config | C5: 3ECP414080-0001 | D5: _ | F5: 3ECP414196-0001 | G5: _ | H5: FT080031387 | I5: 4.3 | J5: FT080031387 | K5: 4.3 | N5: 3ECP414502-0001 | P5: \
A6: Functional principle diagrams (VISIO)
A7: Drive Control | B7: FPD_Drive Control | C7: 3ECP410467-0001 | D7: B | F7: 3ECP400500-0005 | G7: _ | H7: FA010024090 | I7: 00.2 | J7: FA010024090 | K7: 00.2 | N7: 3ECP413651-0005 | P7: _
A8: Conventional Train Control | B8: FPD_Conventional Train Control | C8: 3ECP410476-0001 | D8: C | F8: 3ECP400500-0014 | G8: A | H8: FA010024089 | I8: 03.2 | J8: FA010024089 | K8: 03.2 | N8: 3ECP413651-0014 | P8: A
A9: Train Protection - ATP | B9: FPD_Train Protection - ATP | C9: 3ECP410482-0001 | D9: C | F9: 3ECP400500-0020 | G9: A | H9: FA010024100 | I9: 03.2 | J9: FA010024100 | K9: 03.2 | N9: 3ECP413651-0020 | P9: D
A10: TCMS Architecture | B10: FPD_TCMS Architecture | C10: \ | D10: \ | F10: \ | G10: \ | H10: FA010024104 | I10: 00.2 | J10: FA010024104 | K10: 00.2 | N10: 3ECP307255-0001 | P10: D
A11: Propulsion and Auxiliary | B11: FPD_Propulsion and Auxiliary | C11: \ | D11: \ | F11: \ | G11: \ | H11: FA010024103 | I11: 01.2 | J11: FA010024103 | K11: 01.2 | N11: \ | P11: \
A12: Line Voltage | B12: FPD_Line Voltage | C12: 3ECP410475-0001 | D12: B | F12: 3ECP400500-0013 | G12: C | H12: FA010024096 | I12: 03.2 | J12: FA010024096 | K12: 03.2 | N12: 3ECP413651-0013 | P12: _
A13: Auxiliary Electrical Supply | B13: FPD_Auxiliary Electrical Supply | C13: 3ECP410465-0001 | D13: B | F13: 3ECP400500-0003 | G13: C | H13: FA010024083 | I13: 01.2 | J13: FA010024083 | K13: 01.2 | N13: 3ECP413651-0003 | P13: A
A14: Battery | B14: FPD_Battery | C14: 3ECP410477-0001 | D14: B | F14: 3ECP400500-0015 | G14: _ | H14: FA010024084 | I14: 01.2 | J14: FA010024084 | K14: 01.2 | N14: 3ECP413651-0015 | P14: _
A15: Air Supply | B15: FPD_Air Supply | C15: 3ECP410463-0001 | D15: B | F15: 3ECP400500-0002 | G15: A | H15: FA010024081 | I15: 01.2 | J15: FA010024081 | K15: 01.2 | N15: 3ECP413651-0002 | P15: A
A16: Brake Control | B16: FPD_Brake Control | C16: 3ECP410480-0001 | D16: C | F16: 3ECP400500-0018 | G16: B | H16: FA010024086 | I16: 02.2 | J16: FA010024086 | K16: 02.2 | N16: 3ECP413651-0018 | P16: A
A17: Bogie | B17: FPD_Bogie | C17: 3ECP410466-0001 | D17: C | F17: 3ECP400500-0004 | G17: B | H17: FA010024085 | I17: 01.2 | J17: FA010024085 | K17: 01.2 | N17: 3ECP413651-0004 | P17: _
A18: Wash Wiper | B18: FPD_Wash Wiper | C18: 3ECP410473-0001 | D18: B | F18: 3ECP400500-0011 | G18: _ | H18: FA010024101 | I18: 00.2 | J18: FA010024101 | K18: 00.2 | N18: 3ECP413651-0011 | P18: _
... A30: Interior Lighting | B30: FPD_Interior Lighting | C30: 3ECP410478-0001 | D30: B | F30: 3ECP400500-0016 | G30: _ | H30: FA010024095 | I30: 01.2 | J30: FA010024095 | K30: 01.2 | N30: 3ECP413651-0016 | P30: A
A31: Functional Requirement Specification (FRS)
A32: Functional Vehicle Requirement Specification | B32: FRS_Vehicle | C32: \ | D32: \ | F32: mancanti | H32: \ | I32: \ | K32: \ | N32: 3ECP413839-0001 | P32: B
A33: Drive Control | B33: FRS_Drive Control | C33: 3EST000225-7909 | D33: A | E33: 3EST000225-7909 | F33: 3EST000225-7909 | G33: A | H33: FA020022675 | I33: 03.2 4.0? | J33: FA020022675 | K33: 03.2 4.0? | N33: 3EST000225-7909 | P33: A
A34: Conventional Train Control | B34: FRS_Conventional Train Control | C34: 3EST000225-7916 | D34: A | E34: 3EST000225-7916 | F34: 3ECP413719-0903 | G34: _ | H34: FA020023107 | I34: 06.3 | J34: FA020023107 | K34: 06.3 | N34: 3ECP413922-0903 | P34: _
A35: Train Protection - ATP | B35: FRS_Train Protection - ATP | C35: EC01P008999B | D35: 04 | E35: 3EST000225-7889 | F35: 3ECP414246-0902 | G35: A | H35: FA020025863 | I35: 01.3 | J35: FA020025863 | K35: 01.3 | N35: 3ECP413922-0902 | P35: D
A36: Diagnostics | B36: FRS_Diagnostics | C36: 3EST000225-7918 | D36: B | E36: 3EST000225-7918 | F36: 3EST000225-7918 | G36: B | H36: FA020023413 | I36: 01.2 | J36: FA020023413 | K36: 01.2 | N36: 3ECP413922-1001 | P36: _
A37: Visualisation - MMI | B37: FRS_Visualisation - MMI | C37: 3EST000225-7919 | D37: B | E37: 3EST000225-7919 | F37: 3EST000225-7919 | G37: B | H37: FA020027681 | I37: 03.2 | J37: FA020027681 | K37: 03.2 | N37: 3ECP413922-1003 | P37: _
A38: TCMS - Operational | B38: FRS_TCMS - Operational | C38: 3EST000225-7917 | D38: B | E38: 3EST000225-7917 | F38: 3EST000225-7917 | G38: B | H38: FA020026278 | I38: 02.2 | J38: FA020026278 | K38: 02.2 | N38: 3ECP413922-0904 | P38: _
A39: Train to Wayside Communication (Teledia) | B39: FRS_Teledia | C39: 3ECP413176-0001 | D39: _ | E39: 3ECP413176-0001 | F39: 3ECP413719-1200 | G39: _ | H39: \ | I39: \ | J39: \ | K39: \ | N39: 3ECP413719-1200 | P39: _
A40: Line Voltage | B40: FRS_Line Voltage | C40: 3EST000225-7907 | D40: C | E40: 3EST000225-7907 | F40: 3ECP413719-0401 | G40: _ | H40: FA020022045 | I40: 06.2 | J40: FA020022045 | K40: 06.2 | N40: 3EGH489028-2358 | P40: B
A41: Aux Electrical Supply | B41: FRS_Aux Electrical Supply | C41: 3EST000225-7914 | D41: B | E41: 3EST000225-7914 | F41: 3EST000225-7914 | G41: B | H41: FA020024537 | I41: 03.2 | J41: FA020024537 | K41: 03.2 | N41: 3EST000225-7914 | P41: B
A42: Battery | B42: FRS_Battery | C42: 3EST000225-7908 | D42: B | E42: 3EST000225-7908 | F42: 3EST000225-7908 | G42: B | H42: FA020024538 | I42: 03.2 | J42: FA020024538 | K42: 03.2 | N42: 3EST000225-7908 | P42: B
A43: Air Supply | B43: FRS_Air Supply | C43: 3EST000225-7915 | D43: D | E43: 3EST000225-7915 | F43: 3ECP413719-0603 | G43: _ | H43: FA020024531 | I43: 01.3 | J43: FA020024531 | K43: 01.3 | N43: 3ECP413719-0603 | P43: _
A44: Brake Control | B44: FRS_Brake Control | C44: 3EST000225-7910 | D44: J | E44: 3EST000225-7910 | F44: 3ECP413719-0502 | G44: A | H44: FA020023100 | I44: 02.3 | J44: FA020023100 | K44: 02.3 | N44: 3ECP413922-0502 | P44: B
... A53: Cab HVAC | B53: FRS_Cab HVAC | C53: EC01P009028B | D53: 00.4 | E53: 3EST000225-7894 | F53: 3EST000225-7894 | G53: A | H53: FA020026562 | I53: 00.2 | J53: FA020026562 | K53: 00.2 | N53: 3EST000225-7894 | P53: A
A54: Saloon HVAC | B54: FRS_Saloon HVAC | C54: EC01P008880B | D54: 00.8 | E54: 3EST000225-7897 | F54: 3EST000225-7897 | G54: A | H54: FA020026563 | I54: 02.2 | J54: FA020026563 | K54: 02.2 | N54: 3EST000225-7897 | O54: EC01P008880B | P54: 00.8
A55: Fire Protection and Extinction | B55: FRS_Fire Protection and Extinction | C55: EC01P008884B | D55: 03 | E55: 3EST000225-7879 | F55: 3EST000225-7879 | G55: A | H55: FA020025419 | I55: 03.2 | J55: FA020025419 | K55: 03.2 | N55: 3ECP413922-0604 | O55: EC01P008884B | P55: 04
A56: Toilet | B56: FRS_Toilet | C56: EC01P008888B | D56: 02 | E56: 3EST000225-7883 | F56: 3ECP413719-0802 | G56: _ | H56: FA020026053 | I56: 01.2 | J56: FA020026053 | K56: 01.2 | N56: 3ECP413719-0802 | P56: _
A57: Catering | B57: FRS_Catering | C57: EC01P008889B | D57: 00 | E57: 3EST000225-7885 | F57: 3EST000225-7885 | G57: A | H57: \ | I57: \ | J57: \ | K57: \ | N57: 3EST000225-7885 | P57: A
A58: PIES | B58: FRS_PIS | C58: EC01P009000B | D58: 02 | E58: 3EST000225-7890 | F58: 3ECP413719-1100 | G58: _ | H58: FA020025354 | I58: 00.3 | J58: FA020025354 | K58: 00.3 | N58: 3ECP413922-1100 | P58: _
A59: PIS 2.0 | B59: FRS_PIS 2.0 | C59: \ | D59: \ | E59: \ | H59: FA020047983 | I59: 00.1 | J59: FA020047983 | K59: 00.1 | N59: \ | P59: \
...

Sheet Funzioni
A1: ID | B1: FUNZIONE | C1: TIPO (TBD) | D1: DOC ID | E1: Info DOC | F1: VZI_IT_Base VZI-50_ IT Flotta base | G1: VZI_IT_New14 | H1: VZI-6_IT_R1 VZI-6_IT Full HRI (New 14) | I1: VZI-4_IT_R1 Full HRI | J1: VZ-FR | K1: VZ-ES | L1: VZ-DAI | M1: Generale
A2: Isolam_FAM_01 | B2: Comando isolamento FAM da banco di manovra | C2: HW | M2: {=COLLE} -> #NAME?
D3: FS_DM1 | E3: Link | F3: {=HYPERLINK(CONCATENATE(Cartelle!$A$9,MID(F$1,1,FIND(CHAR(10),F$1)-1),"/CONFIG/",MID($D3,1,FIND("_",$D3)-1),"/",INDIRECT(CONCATENATE("'Conf Sheet'!",ADDRESS(MATCH($D3, 'Conf Sheet'!$B:$B, 0),MATCH(MID(F$1,1,FIND(CHAR(10),F$1)-1), 'Conf Sheet'!$1:$1, 0)))),".pdf#page=",F4),CONCATENATE("#Sharepoint//",$D3))} -> #Sharepoint//FS_DM1 | H3: {=HYPERLINK(CONCATENATE(Cartelle!$A$9,MID(H$1,1,FIND(CHAR(10),H$1)-1),"/CONFIG/",MID($D3,1,FIND("_",$D3)-1),"/",INDIRECT(CONCATENATE("'Conf Sheet'!",ADDRESS(MATCH($D3, 'Conf Sheet'!$B:$B, 0),MATCH(MID(H$1,1,FIND(CHAR(10),H$1)-1), 'Conf Sheet'!$1:$1, 0)))),".pdf#page=",H4),CONCATENATE("#Sharepoint//",$D3))} -> #Sharepoint//FS_DM1
E4: Rif. Pagina | F4: 243 | H4: 144
E5: Componenti circuito elettrico | F5: GG-A024 = Pulsante parking JE-K0005 = MIO-S-DX4 | H5: GG-A024 = Pulsante parking GC-K025 = Relè abilitazione cabina GC-K018 = Relè temporizz GC-K011 = Relè abilitazione cabina JE-K005 = RIO-LP MASTER
D6: , | E6: Descrizione circuitale | F6: La pressione di GG-A024 chiude 2 contatti interni (1 ordinario, 1 ridondato), collegando 2 linee 110V a 2 ingressi della MIO: BRA_PARK_COM Le 2 linee 110 derivano direttamente dal bus 180, tramite due fusibili rispettivamente JE-F007 e JE-F009. | H6: La pressione di GG-A024 chiude 2 contatti interni (1 ordinario, 1 ridondato), collegando 2 linee 110V a 2 ingressi della RIO: BRA_PARK_COM_N e BRA_PARK_COM_R Le 2 linee 110 derivano direttamente dal bus 180, tramite due fusibili rispettivamente JE-F007 e JE-F009. Un contatto del pulsante inoltre alimenta un circuito che intercetta, sulle casse portanti con disponibilità del freno di parcheggio, il comando di rilascio del TCMS verso le valvole di attuazione del parking brake stesso. Tale circuito viene alimentato tramite i relè di banco GC-K011 e GC-K025 e attuato per mezzo del relè temporizzato GC-K018. Tutta questa catena alimenta un relè GG-K028 presenti sulle casse portanti con disponibilità di freno di parcheggio.
D7: FS_TT2 | E7: Link | F7: {=HYPERLINK(CONCATENATE(Cartelle!$A$9,MID(F$1,1,FIND(CHAR(10),F$1)-1),"/CONFIG/",MID($D7,1,FIND("_",$D7)-1),"/",INDIRECT(CONCATENATE("'Conf Sheet'!",ADDRESS(MATCH($D7, 'Conf Sheet'!$B:$B, 0),MATCH(MID(F$1,1,FIND(CHAR(10),F$1)-1), 'Conf Sheet'!$1:$1, 0)))),".pdf#page=",F8),CONCATENATE("#Sharepoint//",$D7))} -> #Sharepoint//FS_TT2 | H7: {=HYPERLINK(CONCATENATE(Cartelle!$A$9,MID(H$1,1,FIND(CHAR(10),H$1)-1),"/CONFIG/",MID($D7,1,FIND("_",$D7)-1),"/",INDIRECT(CONCATENATE("'Conf Sheet'!",ADDRESS(MATCH($D7, 'Conf Sheet'!$B:$B, 0),MATCH(MID(H$1,1,FIND(CHAR(10),H$1)-1), 'Conf Sheet'!$1:$1, 0)))),".pdf#page=",H8),CONCATENATE("#Sharepoint//",$D7))} -> #Sharepoint//FS_TT2
E8: Rif. Pagina | F8: 171 | H8: 131
E9: Componenti circuito elettrico | F9: EVFS1 = Valvola applicazione parking brake JE-K009 = RIO JE-K010 = RIO GG-K016 = Relè RER | H9: GG-K016 = Relè RER GG-K028 = Relè di taglio per il comando di rilascio del PB dato da TCMS attraverso BRA_EVFS1_COM EVFS1 = Valvola applicazione parking brake JE-K009 = RIO JE-K010 = RIO
E10: Descrizione circuitale | F10: Il segnale di rilascio del praking brake verso la EVFS1 viene fornito dalle RIO BRA-EVFS1_COM. Il comando verso EVFS1 è sezionato solamente da un relè GG-K016 chiamato RER che si abilita con un contatto relativo all'inserzione della chiave di banco | H10: Il comando di GG-K028 è dato dalla catena circuitale introdotta nelle DM che serve a evitare che il TCMS possa comandare impropriamente il circuito di rilascio del freno di stazionamento chiamato anche Parking brake oppure Freno a molla FAM. Il comando verso EVFS1 è sezionato pertanto da un relè GG-K016 chiamato RER che si abilita con un contatto relativo all'inserzione della chiave di banco e dal relè GG-K028 facente capo alla catena introdotta nelle DM rispetto al circuito della flotta base. Lo stato di quest'ultimo relè è diagnosticato tramite 2 ingressi RIO ridondati chiamati BRA_EVFS1-PRO_N e BRA_EVFS1-PRO_R
D11: FRS_Brake Control | E11: Link | F11: {=HYPERLINK(CONCATENATE(Cartelle!$A$9,MID(F$1,1,FIND(CHAR(10),F$1)-1),"/CONFIG/",MID($D11,1,FIND("_",$D11)-1),"/",INDIRECT(CONCATENATE("'Conf Sheet'!",ADDRESS(MATCH($D11, 'Conf Sheet'!$B:$B, 0),MATCH(MID(F$1,1,FIND(CHAR(10),F$1)-1), 'Conf Sheet'!$1:$1, 0)))),".pdf#page=",F12),CONCATENATE("#Sharepoint//",$D11))} -> #Sharepoint//FRS_Brake Control | H11: {=HYPERLINK(CONCATENATE(Cartelle!$A$9,MID(H$1,1,FIND(CHAR(10),H$1)-1),"/CONFIG/",MID($D11,1,FIND("_",$D11)-1),"/",INDIRECT(CONCATENATE("'Conf Sheet'!",ADDRESS(MATCH($D11, 'Conf Sheet'!$B:$B, 0),MATCH(MID(H$1,1,FIND(CHAR(10),H$1)-1), 'Conf Sheet'!$1:$1, 0)))),".pdf#page=",H12),CONCATENATE("#Sharepoint//",$D11))} -> #Sharepoint//FRS_Brake Control
E12: Rif. Pagina | F12: 117 | H12: 154
E13: Info differenze | F13: \ | H13: Aggiunto requisiti .3980 e .TRS.343 per inibire elettricamente il TCMS in caso di comando di sblocco PB non dovuto. Tali requisiti sono stati implementati con il circuito di cui alle descrizioni circuitali di cui sopra, il quale utilizza gli ingressi di comando BRA_PARK_COM di comando e lo stato delle variabili BRA_EVFS1-PRO_N e BRA_EVFS1-PRO_R per verificare che sia stato comandato effettivamente un rilascio da pulsante e da macchinista, e che non sia stato rilasciato esclusivamente dal TCMS
D14: FPD_Brake Control | E14: Link | F14: {=HYPERLINK(CONCATENATE(Cartelle!$A$9,MID(F$1,1,FIND(CHAR(10),F$1)-1),"/CONFIG/",MID($D14,1,FIND("_",$D14)-1),"/",INDIRECT(CONCATENATE("'Conf Sheet'!",ADDRESS(MATCH($D14, 'Conf Sheet'!$B:$B, 0),MATCH(MID(F$1,1,FIND(CHAR(10),F$1)-1), 'Conf Sheet'!$1:$1, 0)))),".pdf#page=",F15),CONCATENATE("#Sharepoint//",$D14))} -> #Sharepoint//FPD_Brake Control | H14: {=HYPERLINK(CONCATENATE(Cartelle!$A$9,MID(H$1,1,FIND(CHAR(10),H$1)-1),"/CONFIG/",MID($D14,1,FIND("_",$D14)-1),"/",INDIRECT(CONCATENATE("'Conf Sheet'!",ADDRESS(MATCH($D14, 'Conf Sheet'!$B:$B, 0),MATCH(MID(H$1,1,FIND(CHAR(10),H$1)-1), 'Conf Sheet'!$1:$1, 0)))),".pdf#page=",H15),CONCATENATE("#Sharepoint//",$D14))} -> #Sharepoint//FPD_Brake Control
E15: Rif. Pagina | F15: 18 | H15: 18
A16: Funz_X_yy | B16: xxxxx | C16: HW + SW
D17: FS_xx | E17: Link | F17: {=HYPERLINK(CONCATENATE(Cartelle!$A$9,MID(F$1,1,FIND(CHAR(10),F$1)-1),"/CONFIG/",MID($D17,1,FIND("_",$D17)-1),"/",INDIRECT(CONCATENATE("'Conf Sheet'!",ADDRESS(MATCH($D17, 'Conf Sheet'!$B:$B, 0),MATCH(MID(F$1,1,FIND(CHAR(10),F$1)-1), 'Conf Sheet'!$1:$1, 0)))),".pdf#page=",F18),CONCATENATE("#Sharepoint//",$D17))} -> #N/A | H17: {=HYPERLINK(CONCATENATE(Cartelle!$A$9,MID(H$1,1,FIND(CHAR(10),H$1)-1),"/CONFIG/",MID($D17,1,FIND("_",$D17)-1),"/",INDIRECT(CONCATENATE("'Conf Sheet'!",ADDRESS(MATCH($D17, 'Conf Sheet'!$B:$B, 0),MATCH(MID(H$1,1,FIND(CHAR(10),H$1)-1), 'Conf Sheet'!$1:$1, 0)))),".pdf#page=",H18),CONCATENATE("#Sharepoint//",$D17))} -> #N/A
E18: Rif. Pagina | F18: 1 | H18: 1
D19: FRS_xx | E19: Link | F19: {=HYPERLINK(CONCATENATE(Cartelle!$A$9,MID(F$1,1,FIND(CHAR(10),F$1)-1),"/CONFIG/",MID($D19,1,FIND("_",$D19)-1),"/",INDIRECT(CONCATENATE("'Conf Sheet'!",ADDRESS(MATCH($D19, 'Conf Sheet'!$B:$B, 0),MATCH(MID(F$1,1,FIND(CHAR(10),F$1)-1), 'Conf Sheet'!$1:$1, 0)))),".pdf#page=",F20),CONCATENATE("#Sharepoint//",$D19))} -> #N/A | H19: {=HYPERLINK(CONCATENATE(Cartelle!$A$9,MID(H$1,1,FIND(CHAR(10),H$1)-1),"/CONFIG/",MID($D19,1,FIND("_",$D19)-1),"/",INDIRECT(CONCATENATE("'Conf Sheet'!",ADDRESS(MATCH($D19, 'Conf Sheet'!$B:$B, 0),MATCH(MID(H$1,1,FIND(CHAR(10),H$1)-1), 'Conf Sheet'!$1:$1, 0)))),".pdf#page=",H20),CONCATENATE("#Sharepoint//",$D19))} -> #N/A
E20: Rif. Pagina | F20: 1 | H20: 1
D21: FPD_xx | E21: Link | F21: {=HYPERLINK(CONCATENATE(Cartelle!$A$9,MID(F$1,1,FIND(CHAR(10),F$1)-1),"/CONFIG/",MID($D21,1,FIND("_",$D21)-1),"/",INDIRECT(CONCATENATE("'Conf Sheet'!",ADDRESS(MATCH($D21, 'Conf Sheet'!$B:$B, 0),MATCH(MID(F$1,1,FIND(CHAR(10),F$1)-1), 'Conf Sheet'!$1:$1, 0)))),".pdf#page=",F22),CONCATENATE("#Sharepoint//",$D21))} -> #N/A | H21: {=HYPERLINK(CONCATENATE(Cartelle!$A$9,MID(H$1,1,FIND(CHAR(10),H$1)-1),"/CONFIG/",MID($D21,1,FIND("_",$D21)-1),"/",INDIRECT(CONCATENATE("'Conf Sheet'!",ADDRESS(MATCH($D21, 'Conf Sheet'!$B:$B, 0),MATCH(MID(H$1,1,FIND(CHAR(10),H$1)-1), 'Conf Sheet'!$1:$1, 0)))),".pdf#page=",H22),CONCATENATE("#Sharepoint//",$D21))} -> #N/A
E22: Rif. Pagina | F22: 1 | H22: 1
D23: RACCOLTA ALTRA DOC ??? | E23: Link

Sheet PBS (TBD)
A1: Impianto | B1: Componente | C1: Oggetto di variante | D1: Hardware | E1: Software | F1: Applicabilità flotte | M1: Manuale | P1: CPR | S1: Raccolta doc | U1: Schema elettrico | W1: Schema Pneumatico
F2: VZI-50_ IT Flotta base | G2: VZI-51-58_IT (New 14) | H2: VZI-6_IT Full HRI (New 14) | I2: VZI-4_IT Full HRI | J2: VZ-FR | K2: VZ-ES | L2: VZ-DAI | M2: File | N2: Pag | O2: Link | P2: File | Q2: Pag | R2: Link | S2: Cartella | T2: Link | U2: Pag | V2: Link | W2: Pag | X2: Link
A3: PANTOGRAFO | F3: X | G3: X | H3: X | I3: X | J3: X | K3: X | L3: X
B4: Pantografo 25 kV | D4: 10574479 | F4: X | G4: X | H4: X | M4: ETR1000V300-MR1-04A-Equip elettrico ed elettropneumatico-06 - TOMO 1.pdf | N4: 161 | O4: =HYPERLINK(CONCATENATE(Cartelle!$A$2,Cartelle!$B$2,Cartelle!$I$2,'PBS (TBD)'!M4,"#page=",'PBS (TBD)'!N4),"#") -> # | P4: ETR1000-CPR_04C_2.05.1002_Pantografo_Mar21.pdf | Q4: 93 | R4: =HYPERLINK(CONCATENATE(Cartelle!$A$2,Cartelle!$C$2,Cartelle!$I$2,'PBS (TBD)'!P4,"#page=",'PBS (TBD)'!Q4),"#") -> #
B5: Pantografo 3 kV | D5: 10542152 | F5: X | G5: X | H5: X | M5: ETR1000V300-MR1-04A-Equip elettrico ed elettropneumatico-06 - TOMO 1.pdf | N5: 180 | O5: =HYPERLINK(CONCATENATE(Cartelle!$A$2,Cartelle!$B$2,Cartelle!$I$2,'PBS (TBD)'!M5,"#page=",'PBS (TBD)'!N5),"#") -> # | P5: ETR1000-CPR_04C_2.05.1002_Pantografo_Mar21.pdf | Q5: 33 | R5: =HYPERLINK(CONCATENATE(Cartelle!$A$2,Cartelle!$C$2,Cartelle!$I$2,'PBS (TBD)'!P5,"#page=",'PBS (TBD)'!Q5),"#") -> #
B6: Pantografo 1,5 kV | J6: X
B7: PPU | C7: Isol_ADD | D7: 0102895 | F7: X
B8: PPU | D8: 232C10395F | G8: X | H8: X | S8: 232C10395F | T8: =HYPERLINK(CONCATENATE(Cartelle!$A$2,Cartelle!$D$2,'PBS (TBD)'!S8),"#") -> #
B9: PPU | D9: 232C10353E | J9: X
A10: TCMS | F10: X | G10: X | H10: X | I10: X | J10: X | K10: X | L10: X
B11: CCU-O Dual MVB (DCY1110B) | D11: 3EST000225-5707 | E11: CCS xxx | F11: X | G11: X | M11: ETR1000V300-MR1-05A-Logica di comando-03.pdf | N11: 113 | O11: =HYPERLINK(CONCATENATE(Cartelle!$A$2,Cartelle!$B$2,Cartelle!$I$2,'PBS (TBD)'!M11,"#page=",'PBS (TBD)'!N11),"#") -> # | P11: ETR1000-CPR_05_2.05.1004_Logica di comando_Aprile2021.pdf | Q11: 48 | R11: =HYPERLINK(CONCATENATE(Cartelle!$A$2,Cartelle!$C$2,Cartelle!$I$2,'PBS (TBD)'!P11,"#page=",'PBS (TBD)'!Q11),"#") -> #
B12: CCU-C 2ETH (DCY1550A) | D12: 3EST000225-5711 | E12: CCS xxx | F12: X | G12: X | M12: ETR1000V300-MR1-05A-Logica di comando-03.pdf | N12: 121 | O12: =HYPERLINK(CONCATENATE(Cartelle!$A$2,Cartelle!$B$2,Cartelle!$I$2,'PBS (TBD)'!M12,"#page=",'PBS (TBD)'!N12),"#") -> # | P12: ETR1000-CPR_05_2.05.1004_Logica di comando_Aprile2021.pdf | Q12: 52 | R12: =HYPERLINK(CONCATENATE(Cartelle!$A$2,Cartelle!$C$2,Cartelle!$I$2,'PBS (TBD)'!P12,"#page=",'PBS (TBD)'!Q12),"#") -> #
B13: CCU-S (DCY 1660A) | D13: 3EST000221-6430 | E13: CCS xxx | F13: X | G13: X | M13: ETR1000V300-MR1-05A-Logica di comando-03.pdf | N13: 124 | O13: =HYPERLINK(CONCATENATE(Cartelle!$A$2,Cartelle!$B$2,Cartelle!$I$2,'PBS (TBD)'!M13,"#page=",'PBS (TBD)'!N13),"#") -> # | P13: ETR1000-CPR_05_2.05.1004_Logica di comando_Aprile2021.pdf | Q13: 44 | R13: =HYPERLINK(CONCATENATE(Cartelle!$A$2,Cartelle!$C$2,Cartelle!$I$2,'PBS (TBD)'!P13,"#page=",'PBS (TBD)'!Q13),"#") -> #
B14: MIO-DXH4-S (DCS 2222B) | D14: 3EST000228-0629 | F14: X | M14: ETR1000V300-MR1-05A-Logica di comando-03.pdf | N14: 175 | O14: =HYPERLINK(CONCATENATE(Cartelle!$A$2,Cartelle!$B$2,Cartelle!$I$2,'PBS (TBD)'!M14,"#page=",'PBS (TBD)'!N14),"#") -> # | P14: ETR1000-CPR_05_2.05.1004_Logica di comando_Aprile2021.pdf | Q14: 70 | R14: =HYPERLINK(CONCATENATE(Cartelle!$A$2,Cartelle!$C$2,Cartelle!$I$2,'PBS (TBD)'!P14,"#page=",'PBS (TBD)'!Q14),"#") -> #
B15: MIO-S (DCS 2222C) | D15: 3EST000230-5830 | G15: X | P15: ETR1000-CPR_05_2.05.1004_Logica di comando_Aprile2021.pdf | Q15: 28 | R15: =HYPERLINK(CONCATENATE(Cartelle!$A$2,Cartelle!$C$2,Cartelle!$I$2,'PBS (TBD)'!P15,"#page=",'PBS (TBD)'!Q15),"#") -> #
B16: MIO-S-AI1+DXH3 (DCS 7222B) | D16: 3EST000228-3395 | F16: X | M16: ETR1000V300-MR1-05A-Logica di comando-03.pdf | N16: 175 | O16: =HYPERLINK(CONCATENATE(Cartelle!$A$2,Cartelle!$B$2,Cartelle!$I$2,'PBS (TBD)'!M16,"#page=",'PBS (TBD)'!N16),"#") -> # | P16: ETR1000-CPR_05_2.05.1004_Logica di comando_Aprile2021.pdf | Q16: 74 | R16: =HYPERLINK(CONCATENATE(Cartelle!$A$2,Cartelle!$C$2,Cartelle!$I$2,'PBS (TBD)'!P16,"#page=",'PBS (TBD)'!Q16),"#") -> #
B17: MIO-S (DCS 7222B) | D17: 3EST000230-5833 | G17: X | P17: ETR1000-CPR_05_2.05.1004_Logica di comando_Aprile2021.pdf | Q17: 84 | R17: =HYPERLINK(CONCATENATE(Cartelle!$A$2,Cartelle!$C$2,Cartelle!$I$2,'PBS (TBD)'!P17,"#page=",'PBS (TBD)'!Q17),"#") -> #
B18: MIO-S-AI1+DXH2 (DCS 7220B) | D18: 3EST000228-3394 | F18: X | G18: X | M18: ETR1000V300-MR1-05A-Logica di comando-03.pdf | N18: 175 | O18: =HYPERLINK(CONCATENATE(Cartelle!$A$2,Cartelle!$B$2,Cartelle!$I$2,'PBS (TBD)'!M18,"#page=",'PBS (TBD)'!N18),"#") -> # | P18: ETR1000-CPR_05_2.05.1004_Logica di comando_Aprile2021.pdf | Q18: 76 | R18: =HYPERLINK(CONCATENATE(Cartelle!$A$2,Cartelle!$C$2,Cartelle!$I$2,'PBS (TBD)'!P18,"#page=",'PBS (TBD)'!Q18),"#") -> #
B19: MIO-DXH4 (DCX 2222A) | D19: 3EST000209-5696 | F19: X | G19: ? | M19: ETR1000V300-MR1-05A-Logica di comando-03.pdf | N19: 150 | O19: =HYPERLINK(CONCATENATE(Cartelle!$A$2,Cartelle!$B$2,Cartelle!$I$2,'PBS (TBD)'!M19,"#page=",'PBS (TBD)'!N19),"#") -> # | P19: ETR1000-CPR_05_2.05.1004_Logica di comando_Aprile2021.pdf | Q19: 62 | R19: =HYPERLINK(CONCATENATE(Cartelle!$A$2,Cartelle!$C$2,Cartelle!$I$2,'PBS (TBD)'!P19,"#page=",'PBS (TBD)'!Q19),"#") -> #
B20: MIO-DX1H (DCX 2000A) | D20: 3EST000209-5690 | F20: X | G20: ? | M20: ETR1000V300-MR1-05A-Logica di comando-03.pdf | N20: 151 | O20: =HYPERLINK(CONCATENATE(Cartelle!$A$2,Cartelle!$B$2,Cartelle!$I$2,'PBS (TBD)'!M20,"#page=",'PBS (TBD)'!N20),"#") -> # | P20: ETR1000-CPR_05_2.05.1004_Logica di comando_Aprile2021.pdf | Q20: 82 | R20: =HYPERLINK(CONCATENATE(Cartelle!$A$2,Cartelle!$C$2,Cartelle!$I$2,'PBS (TBD)'!P20,"#page=",'PBS (TBD)'!Q20),"#") -> #
B21: MIO-DX3H (DCX 2220A) | D21: 3EST000209-5694 | F21: X | G21: ? | M21: ETR1000V300-MR1-05A-Logica di comando-03.pdf | N21: 151 | O21: =HYPERLINK(CONCATENATE(Cartelle!$A$2,Cartelle!$B$2,Cartelle!$I$2,'PBS (TBD)'!M21,"#page=",'PBS (TBD)'!N21),"#") -> # | P21: ETR1000-CPR_05_2.05.1004_Logica di comando_Aprile2021.pdf | Q21: 66 | R21: =HYPERLINK(CONCATENATE(Cartelle!$A$2,Cartelle!$C$2,Cartelle!$I$2,'PBS (TBD)'!P21,"#page=",'PBS (TBD)'!Q21),"#") -> #
B22: MCG (DCZ 2424B) | D22: 3EST000225-7169 | F22: X | M22: ETR1000V300-MR1-05A-Logica di comando-03.pdf | N22: 152 | O22: =HYPERLINK(CONCATENATE(Cartelle!$A$2,Cartelle!$B$2,Cartelle!$I$2,'PBS (TBD)'!M22,"#page=",'PBS (TBD)'!N22),"#") -> # | P22: ETR1000-CPR_05_2.05.1004_Logica di comando_Aprile2021.pdf | Q22: 84 | R22: =HYPERLINK(CONCATENATE(Cartelle!$A$2,Cartelle!$C$2,Cartelle!$I$2,'PBS (TBD)'!P22,"#page=",'PBS (TBD)'!Q22),"#") -> #
B23: MCG | D23: 3EST000234-1560 | G23: X | P23: ETR1000-CPR_05_2.05.1004_Logica di comando_Aprile2021.pdf | Q23: 32 | R23: =HYPERLINK(CONCATENATE(Cartelle!$A$2,Cartelle!$C$2,Cartelle!$I$2,'PBS (TBD)'!P23,"#page=",'PBS (TBD)'!Q23),"#") -> #
B24: MCG Antenna WLAN/GSM GPS | D24: 3EST000212-2155 | F24: X | M24: ETR1000V300-MR1-05A-Logica di comando-03.pdf | N24: 163 | O24: =HYPERLINK(CONCATENATE(Cartelle!$A$2,Cartelle!$B$2,Cartelle!$I$2,'PBS (TBD)'!M24,"#page=",'PBS (TBD)'!N24),"#") -> # | P24: ETR1000-CPR_05_2.05.1004_Logica di comando_Aprile2021.pdf | Q24: 32 | R24: =HYPERLINK(CONCATENATE(Cartelle!$A$2,Cartelle!$C$2,Cartelle!$I$2,'PBS (TBD)'!P24,"#page=",'PBS (TBD)'!Q24),"#") -> #
B25: MCG Antenna WLAN/GSM GPS | D25: 3EH-232550R0005 | G25: X | P25: ETR1000-CPR_05_2.05.1004_Logica di comando_Aprile2021.pdf | Q25: 32 | R25: =HYPERLINK(CONCATENATE(Cartelle!$A$2,Cartelle!$C$2,Cartelle!$I$2,'PBS (TBD)'!P25,"#page=",'PBS (TBD)'!Q25),"#") -> #
B26: MOBAD DCA 0030A | D26: 3EST 92-492 | F26: X | G26: X | M26: ETR1000V300-MR1-05A-Logica di comando-03.pdf | N26: 169 | O26: =HYPERLINK(CONCATENATE(Cartelle!$A$2,Cartelle!$B$2,Cartelle!$I$2,'PBS (TBD)'!M26,"#page=",'PBS (TBD)'!N26),"#") -> # | P26: ETR1000-CPR_05_2.05.1004_Logica di comando_Aprile2021.pdf | Q26: 56 | R26: =HYPERLINK(CONCATENATE(Cartelle!$A$2,Cartelle!$C$2,Cartelle!$I$2,'PBS (TBD)'!P26,"#page=",'PBS (TBD)'!Q26),"#") -> #
B27: TCN GW-S DCY 1703A | D27: EST000221-6460 | F27: X | G27: X | M27: ETR1000V300-MR1-05B-02- Logica di comando - Nodo TCN.pdf | N27: 113 | O27: =HYPERLINK(CONCATENATE(Cartelle!$A$2,Cartelle!$B$2,Cartelle!$I$2,'PBS (TBD)'!M27,"#page=",'PBS (TBD)'!N27),"#") -> # | P27: ETR1000-CPR_05_2.05.1004_Logica di comando_Aprile2021.pdf | Q27: 58 | R27: =HYPERLINK(CONCATENATE(Cartelle!$A$2,Cartelle!$C$2,Cartelle!$I$2,'PBS (TBD)'!P27,"#page=",'PBS (TBD)'!Q27),"#") -> #
B28: IP Train Switch | D28: 3EST000212-3000 | F28: X | M28: ETR1000V300-MR1-05A-Logica di comando-03.pdf | N28: 128 | O28: =HYPERLINK(CONCATENATE(Cartelle!$A$2,Cartelle!$B$2,Cartelle!$I$2,'PBS (TBD)'!M28,"#page=",'PBS (TBD)'!N28),"#") -> # | P28: ETR1000-CPR_05_2.05.1004_Logica di comando_Aprile2021.pdf | Q28: 28 | R28: =HYPERLINK(CONCATENATE(Cartelle!$A$2,Cartelle!$C$2,Cartelle!$I$2,'PBS (TBD)'!P28,"#page=",'PBS (TBD)'!Q28),"#") -> #
B29: IP Train Switch | D29: 3EST000236-6769 | G29: X | P29: ETR1000-CPR_05_2.05.1004_Logica di comando_Aprile2021.pdf | Q29: 28 | R29: =HYPERLINK(CONCATENATE(Cartelle!$A$2,Cartelle!$C$2,Cartelle!$I$2,'PBS (TBD)'!P29,"#page=",'PBS (TBD)'!Q29),"#") -> #
B30: IP Train Repeater | D30: 3EST000212-3010 | F30: X | M30: ETR1000V300-MR1-05A-Logica di comando-03.pdf | N30: 132 | O30: =HYPERLINK(CONCATENATE(Cartelle!$A$2,Cartelle!$B$2,Cartelle!$I$2,'PBS (TBD)'!M30,"#page=",'PBS (TBD)'!N30),"#") -> # | P30: ETR1000-CPR_05_2.05.1004_Logica di comando_Aprile2021.pdf | Q30: 32 | R30: =HYPERLINK(CONCATENATE(Cartelle!$A$2,Cartelle!$C$2,Cartelle!$I$2,'PBS (TBD)'!P30,"#page=",'PBS (TBD)'!Q30),"#") -> #
B31: IP Train Repeater | D31: 3EST000236-6770 | G31: X | P31: ETR1000-CPR_05_2.05.1004_Logica di comando_Aprile2021.pdf | Q31: 32 | R31: =HYPERLINK(CONCATENATE(Cartelle!$A$2,Cartelle!$C$2,Cartelle!$I$2,'PBS (TBD)'!P31,"#page=",'PBS (TBD)'!Q31),"#") -> #
B32: IP Ring Switch | D32: 3EST000225-7297 | F32: X | M32: ETR1000V300-MR1-05A-Logica di comando-03.pdf | N32: 136 | O32: =HYPERLINK(CONCATENATE(Cartelle!$A$2,Cartelle!$B$2,Cartelle!$I$2,'PBS (TBD)'!M32,"#page=",'PBS (TBD)'!N32),"#") -> # | P32: ETR1000-CPR_05_2.05.1004_Logica di comando_Aprile2021.pdf | Q32: 28 | R32: =HYPERLINK(CONCATENATE(Cartelle!$A$2,Cartelle!$C$2,Cartelle!$I$2,'PBS (TBD)'!P32,"#page=",'PBS (TBD)'!Q32),"#") -> #
B33: IP Ring Switch | D33: 3EST000235-7837 | G33: X | P33: ETR1000-CPR_05_2.05.1004_Logica di comando_Aprile2021.pdf | Q33: 28 | R33: =HYPERLINK(CONCATENATE(Cartelle!$A$2,Cartelle!$C$2,Cartelle!$I$2,'PBS (TBD)'!P33,"#page=",'PBS (TBD)'!Q33),"#") -> #
B34: BUS Coupler BCT 12KF04 | D34: EGM032400R0001 | F34: X | G34: X | M34: ETR1000V300-MR1-05A-Logica di comando-03.pdf | N34: 137 | O34: =HYPERLINK(CONCATENATE(Cartelle!$A$2,Cartelle!$B$2,Cartelle!$I$2,'PBS (TBD)'!M34,"#page=",'PBS (TBD)'!N34),"#") -> # | P34: ETR1000-CPR_05_2.05.1004_Logica di comando_Aprile2021.pdf | Q34: 30 | R34: =HYPERLINK(CONCATENATE(Cartelle!$A$2,Cartelle!$C$2,Cartelle!$I$2,'PBS (TBD)'!P34,"#page=",'PBS (TBD)'!Q34),"#") -> #
B35: Plug di configurazione ECP-USB | D35: 3EST000212-3038 | F35: X | M35: ETR1000V300-MR1-05A-Logica di comando-03.pdf | N35: 168 | O35: =HYPERLINK(CONCATENATE(Cartelle!$A$2,Cartelle!$B$2,Cartelle!$I$2,'PBS (TBD)'!M35,"#page=",'PBS (TBD)'!N35),"#") -> # | P35: ETR1000-CPR_05_2.05.1004_Logica di comando_Aprile2021.pdf | Q35: 32 | R35: =HYPERLINK(CONCATENATE(Cartelle!$A$2,Cartelle!$C$2,Cartelle!$I$2,'PBS (TBD)'!P35,"#page=",'PBS (TBD)'!Q35),"#") -> #
B36: Plug di configurazione ECP-USB | D36: 3EST000235-5100 | G36: X | P36: ETR1000-CPR_05_2.05.1004_Logica di comando_Aprile2021.pdf | Q36: 32 | R36: =HYPERLINK(CONCATENATE(Cartelle!$A$2,Cartelle!$C$2,Cartelle!$I$2,'PBS (TBD)'!P36,"#page=",'PBS (TBD)'!Q36),"#") -> #
B37: IDU | D37: 3EST000223-8802 | F37: X | G37: X | P37: ETR1000-CPR_05_2.05.1004_Logica di comando_Aprile2021.pdf | Q37: 32 | R37: =HYPERLINK(CONCATENATE(Cartelle!$A$2,Cartelle!$C$2,Cartelle!$I$2,'PBS (TBD)'!P37,"#page=",'PBS (TBD)'!Q37),"#") -> #
B38: xxx
B39: CENTRALINA CCU | C39: ID_Pippo | D39: XXX | E39: YYY | F39: X
B40: CENTRALINA XXX | D40: XXX | E40: ZZZ | G40: X
...

Sheet Cartelle
A1: Radice | B1: MR | C1: CPR | D1: Componenti | E1: Doc modifica | F1: Specifiche | G1: Funzionali | I1: NOME FILE | J1: VZI-51-58 / IT (New 14) | K1: VZI-6 / IT Full HRI (New 14) | L1: VZI-4 / IT Full HRI | M1: VZ-FR | N1: VZ-ES | O1: VZ-DAI
A2: https://gruppofsitaliane.sharepoint.com/:f:/r/sites/IngegneriaETReMezziLeggeri-Trenitalia/Shared%20Documents/Prova%20Doc%20ETR1000/ | B2: MR/ | C2: CPR/ | D2: COMP/ | E2: MOD/ | F2: SPEC/ | G2: FUNZ/ | H2: CONFIG/ | I2: VZI-IT_FB/ | K2: VZI-IT_R1/
A5: dimensione massima COLLEG.IPERTESTUALE() = 255 caratteri
A8: Radice | B8: VZI_IT_Base | C8: VZI_IT_R1
A9: https://gruppofsitaliane.sharepoint.com/:f:/r/sites/IngegneriaETReMezziLeggeri-Trenitalia/Shared%20Documents/Prova%20Doc%20ETR1000/PROVA_CONFIG/ | I9: CONFIG | J9: =HYPERLINK(CONCATENATE($A9,$I9),"solo pdf") -> solo pdf
A11: =LEN(A9) -> 144 | B11: =LEN(B8) -> 11 | C11: =LEN(C8) -> 9 | I11: =LEN(I9) -> 6 | J11: =A11+B11+I11 -> 161
A19: https://gruppofsitaliane.sharepoint.com/:f:/r/sites/IngegneriaETReMezziLeggeri-Trenitalia/Shared%20Documents/ETR700/
A21: aaa.pdf | B21: 30 | I21: =HYPERLINK(CONCATENATE($A$19,$A21),"solo pdf") -> solo pdf | J21: =HYPERLINK(CONCATENATE($A$19,$A21,"#page=",$B21),"pdf+page") -> pdf+page
A22: bbb.pdf | B22: 91 | I22: =HYPERLINK(CONCATENATE($A$19,$A22),"solo pdf") -> solo pdf | J22: =HYPERLINK(CONCATENATE($A$19,$A22,"#page=",$B22),"pdf+page") -> pdf+page
A24: https://gruppofsitaliane.sharepoint.com/:f:/r/sites/IngegneriaETReMezziLeggeri-Trenitalia/Prova Doc ETR1000/GENERALE/

Sheet MR-CPR
A1: TRENO | B1: TIPO | C1: VOLUME SUBVOLUME | D1: DESCRIZIONE | E1: COD | F1: VZI-50_IT + VZI-51/58_IT | H1: NOTE | I1: VZI-6_IT + VZI-4_IT | J1: VZI-4_IT Full HRI | K1: NOTE | L1: VZ-FR | M1: VZ-ES | N1: VZ-DAI
F2: REV | G2: DATA | I2: REV | J2: DATA
A3: ETR1000V300 | B3: PBC | C3: 01A | D3: Descrizione generale e funzionamento | E3: =CONCATENATE(B3,"-",C3) -> PBC-01A | F3: 12 | G3: giu-21 | I3: 06
A4: ETR1000V300 | B4: PBC | C4: 01B | D4: Norme d’Uso ed Interventi di Emergenza | E4: =CONCATENATE(B4,"-",C4) -> PBC-01B | F4: 12 | G4: mag-21 | I4: 09
A5: ETR1000V300 | B5: PBS | C5: 01A | D5: Manuale per il Personale di Bordo addetto alla Scorta | E5: =CONCATENATE(B5,"-",C5) -> PBS-01A | F5: 03 | G5: feb-21 | I5: 03
A6: ETR1000V300 | B6: MRx | C6: 20A | D6: SOTTOSISTEMA DI BORDO ERTMSSCMT Piattaforma ELO MANUALE GENERICO USO E MANUTENZIONE | E6: =CONCATENATE(B6,"-",C6) -> MRx-20A | F6: 0 | G6: 44866
A7: ETR1000V300 | B7: MR1 | C7: 01A | D7: Cassa | E7: =CONCATENATE(B7,"-",C7) -> MR1-01A | F7: 03 | G7: giu-20 | I7: 05
A8: ETR1000V300 | B8: MR1 | C8: 02A | D8: Carrello | E8: =CONCATENATE(B8,"-",C8) -> MR1-02A | F8: 11 | G8: set-21 | I8: 08
A9: ETR1000V300 | B9: MR1 | C9: 03A | D9: Impianto pneumatico e freno | E9: =CONCATENATE(B9,"-",C9) -> MR1-03A | F9: 08 | G9: mag-21 | I9: 04
A10: ETR1000V300 | B10: MR1 | C10: 04A | D10: Equipaggiamento elettrico ed elettropneumatico | E10: =CONCATENATE(B10,"-",C10) -> MR1-04A | F10: 0 | G10: lug-21 | I10: 05
A11: ETR1000V300 | B11: MR1 | C11: 05A | D11: Logica di comando | E11: =CONCATENATE(B11,"-",C11) -> MR1-05A | F11: 03 | G11: gen-21 | I11: 03
A12: ETR1000V300 | B12: MR1 | C12: 05B | D12: Logica di comando - Nodo TCN | E12: =CONCATENATE(B12,"-",C12) -> MR1-05B | F12: 02 | G12: giu-17 | I12: 04
A13: ETR1000V300 | B13: MR1 | C13: 06A | D13: Azionamento di trazione | E13: =CONCATENATE(B13,"-",C13) -> MR1-06A | F13: 03 | G13: giu-17 | I13: 04
A14: ETR1000V300 | B14: MR1 | C14: 07A | D14: Motore di trazione | E14: =CONCATENATE(B14,"-",C14) -> MR1-07A | F14: 05 | G14: lug-20 | I14: 04
A15: ETR1000V300 | B15: MR1 | C15: 08A | D15: Passaggi esterni | E15: =CONCATENATE(B15,"-",C15) -> MR1-08A | F15: 03 | G15: giu-20 | I15: 04
A16: ETR1000V300 | B16: MR1 | C16: 08B | D16: Sotto Sistema di Bordo ERTMS BL3 CON SCMT INTEGRATO | E16: B60A.0100914.G00.00IT | F16: 0 | G16: 44986
A17: ETR1000V300 | B17: MR1 | C17: 09A | D17: Sottosistema di climatizzazione | E17: =CONCATENATE(B17,"-",C17) -> MR1-09A | F17: 03 | G17: giu-20 | I17: 04
A18: ETR1000V300 | B18: MR1 | C18: 10A | D18: Sottosistema di comunicazione | E18: =CONCATENATE(B18,"-",C18) -> MR1-10A | F18: 04 | G18: mag-22 | I18: 03
A19: ETR1000V300 | B19: MR1 | C19: 11A | D19: Convertitore servizi ausiliari e caricabatterie | E19: =CONCATENATE(B19,"-",C19) -> MR1-11A | F19: 01 | G19: giu-17 | I19: 03
A20: ETR1000V300 | B20: MR1 | C20: 13A | D20: Sottosistema diagnostica di bordo | E20: =CONCATENATE(B20,"-",C20) -> MR1-13A | F20: 02 | G20: giu-17 | I20: 03
A21: ETR1000V300 | B21: MR1 | C21: 14A | D21: Allestimenti interni | E21: =CONCATENATE(B21,"-",C21) -> MR1-14A | F21: 04 | G21: mag-22
A22: ETR1000V300 | B22: MR1 | C22: 14B | D22: Allestimenti interni - Arredi comparto e cabina di guida | E22: =CONCATENATE(B22,"-",C22) -> MR1-14B | F22: \ | G22: \ | I22: 03
A23: ETR1000V300 | B23: MR1 | C23: 15A | D23: Servizi Generali di Bordo - Toilette | E23: =CONCATENATE(B23,"-",C23) -> MR1-15A | F23: 04 | G23: mag-22 | I23: 03
A24: ETR1000V300 | B24: MR1 | C24: 15B | D24: Servizi Generali di Bordo - Bar Bistrot | E24: =CONCATENATE(B24,"-",C24) -> MR1-15B | F24: \ | G24: \ | I24: 03
A25: ETR1000V300 | B25: MR1 | C25: 18A | D25: Telecomunicazioni TT | E25: =CONCATENATE(B25,"-",C25) -> MR1-18A | F25: 02 | G25: gen-18 | I25: 03
A26: ETR1000V300 | B26: MR1 | C26: 20A | D26: Sottosistema di bordo ETCS generale | E26: =CONCATENATE(B26,"-",C26) -> MR1-20A | F26: 03 | G26: giu-20 | I26: 05
A27: ETR1000V300 | B27: MR1 | C27: 20B | D27: Sottosistema di bordo ETCS specifico del treno | E27: =CONCATENATE(B27,"-",C27) -> MR1-20B | F27: 01 | G27: lug-17 | I27: 02
A28: ETR1000V300 | B28: MR1 | C28: 31A | D28: Sistema informativo di condotta Generale (DIS) | E28: =CONCATENATE(B28,"-",C28) -> MR1-31A | F28: 02 | G28: gen-18 | I28: 04
A29: ETR1000V300 | B29: MR1 | C29: 16A | D29: Emergenza e recupero | E29: =CONCATENATE(B29,"-",C29) -> MR1-16A | F29: 07 | G29: feb-21
A30: ETR1000V300 | B30: MR2 | C30: 01A | D30: Cassa | E30: =CONCATENATE(B30,"-",C30) -> MR2-01A | F30: 04 | G30: feb-21
A31: ETR1000V300 | B31: MR2 | C31: 02A | D31: Carrello | E31: =CONCATENATE(B31,"-",C31) -> MR2-02A | F31: 10 | G31: set-21
A32: ETR1000V300 | B32: MR2 | C32: 03A | D32: Impianto pneumatico e freno | E32: =CONCATENATE(B32,"-",C32) -> MR2-03A | F32: 04 | G32: mag-21
A33: ETR1000V300 | B33: MR2 | C33: 04A | D33: Equipaggiamento elettrico ed elettropneumatico | E33: =CONCATENATE(B33,"-",C33) -> MR2-04A | F33: 06 | G33: lug-21
A34: ETR1000V300 | B34: MR2 | C34: 05A | D34: Logica di comando | E34: =CONCATENATE(B34,"-",C34) -> MR2-05A | F34: 02 | G34: giu-17
A35: ETR1000V300 | B35: MR2 | C35: 05B | D35: Logica di comando - Nodo TCN | E35: =CONCATENATE(B35,"-",C35) -> MR2-05B | F35: 02 | G35: giu-17
A36: ETR1000V300 | B36: MR2 | C36: 06A | D36: Azionamento di trazione | E36: =CONCATENATE(B36,"-",C36) -> MR2-06A | F36: 03 | G36: mag-18
A37: ETR1000V300 | B37: MR2 | C37: 07A | D37: Motore di trazione | E37: =CONCATENATE(B37,"-",C37) -> MR2-07A | F37: 02 | G37: nov-18
A38: ETR1000V300 | B38: MR2 | C38: 08A | D38: Passaggi esterni | E38: =CONCATENATE(B38,"-",C38) -> MR2-08A | F38: 03 | G38: giu-20
A39: ETR1000V300 | B39: MR2 | C39: 09A | D39: Sottosistema di climatizzazione | E39: =CONCATENATE(B39,"-",C39) -> MR2-09A | F39: 03 | G39: giu-20
A40: ETR1000V300 | B40: MR2 | C40: 11A | D40: Convertitore servizi ausiliari e caricabatterie | E40: =CONCATENATE(B40,"-",C40) -> MR2-11A | F40: 01 | G40: giu-17
...

Sheet Struttura
C1: IT 50 treni (flotta base) | G1: IT 8 treni (51-58) | K1: IT 6+30 treni (101-136) | O1: I-FR 9 treni | S1: DAI 9 treni | W1: ES 20 treni
A2: Sottosistema | C2: P/N | D2: Id | E2: P/N | F2: Descrizione | G2: P/N | H2: Id | I2: P/N | J2: Descrizione | K2: P/N | L2: Id | M2: P/N | N2: Descrizione | O2: P/N | P2: Id | Q2: P/N | R2: Descrizione | S2: P/N | T2: Id | U2: P/N | V2: Descrizione | W2: P/N | X2: Id | Y2: P/N | Z2: Descrizione
A3: Carrelli | B3: Motori | C3: 100360301 100360302 100360303 100360304 | D3: Sala Montata | E3: 100360402 100360403 | F3: Sensoristica ERTMS-SCMT carrelli DM Sala senza boccole: 100360064 | G3: 100360301 100360302 100360303 100360304 | H3: Sala Montata | I3: 100360402 100360403 | J3: Sensoristica ERTMS-SCMT carrelli DM Sala senza boccole: 100360064 | K3: 100360301 100360302 100360303 100360304 (EN45545) | L3: Sala Montata | M3: 100360402 100360403 | N3: Sensoristica ERTMS-SCMT carrelli DM | O3: 100329688 100329689 100360303 100360304 | P3: Sala Montata | R3: Sensoristica ERTMS-SCMT, Memor brush, ETCS antenna su carrelli ant. DM1/8 Sensori Wiegand su post. DM1/8 Sensori Wiegand su ant. TT2/7 Sala senza boccole: 100360064 | T3: Sala Montata | V3: tbd sensori boccola DM | W3: DM: 100437987 100470644 | X3: Sala Montata | Z3: Sensoristica ETCS-ASFA-LZB carrelli DM
D4: Riduttore | E4: 13900244911 | H4: Riduttore | I4: 13900244911 | L4: Riduttore | M4: 13900244911 | P4: Riduttore | Q4: 13900244911 | T4: Riduttore | U4: 13900244911 | X4: Riduttore
D5: Motore | E5: 3EST000224-9555 | H5: Motore | I5: 3EST000224-9555 | L5: Motore | M5: 3EST000224-9555 | P5: Motore | Q5: 3EST000224-9555 | T5: Motore | U5: 3EST000224-9555 | X5: Motore
D6: Cil.Freno | E6: FT0011601-100 FT0011602-100 FT0011602-101 | H6: Cil.Freno | I6: FT0011601-100 FT0011602-100 FT0011602-101 | L6: Cil.Freno | M6: FT0011601-100 FT0011602-100 FT0011602-101 | P6: Cil.Freno | Q6: FT0011601-100 FT0011602-100 FT0011602-101 | T6: Cil.Freno | U6: FT0011601-100 FT0011602-100 FT0011602-101 | X6: Cil.Freno | Y6: FT0011601-100 FT0011602-100 FT0011602-101
D7: Als | E7: 6398B000-01 | H7: Als | I7: 6398B000-01 | L7: Als | M7: 6398B000-01 | P7: Als | Q7: 6398B000-01 | T7: Als | U7: 6398B000-01 | X7: Als
D8: BMS | F8: Ephimess fase 2 | H8: BMS | J8: Ephimess fase 2 | L8: BMS | P8: BMS | T8: BMS | X8: BMS
B9: Portanti | C9: 100360311 100360312 100360313 | D9: Sala | E9: 100360411 100360412 | G9: 100360311 100360312 100360313 | H9: Sala | I9: 100360411 100360412 | K9: 100360311 100360312 100360313 (EN45545) | L9: Sala | M9: 100360411 100360412 | O9: 100360311 100329690 100360313 | P9: Sala | Q9: 100360411 100360412 | T9: Sala | X9: Sala
D10: Freno | H10: Freno | L10: Freno | P10: Freno | T10: Freno | X10: Freno
D11: Als | H11: Als | L11: Als | P11: Als | T11: Als | X11: Als
D12: BMS | H12: BMS | L12: BMS | P12: BMS | T12: BMS | X12: BMS
A13: Pantografi | B13: 3 kV | C13: 100170460 | D13: Struttura | E13: 10573076 | G13: 10949272 | H13: Struttura | I13: 10573076 | K13: 10949272 | L13: Struttura | M13: 10573076 | O13: 100170460 | P13: Struttura | Q13: 10573076 | T13: Struttura | X13: Struttura
D14: Archetto | E14: 10561136 | H14: Archetto | I14: 10561136 | L14: Archetto | M14: 10561136 | P14: Archetto | Q14: 10561136 | T14: Archetto | X14: Archetto | Z14: Archetto 1.950 mm
D15: Strisciante | E15: SK1451 | H15: Strisciante | I15: SK1451 | L15: Strisciante | M15: SK1451 | P15: Strisciante | Q15: SK1451 | T15: Strisciante | X15: Strisciante
D16: PPU | E16: 102895 | H16: PPU | I16: 232C10395F | J16: Con isolamento ADD | L16: PPU | M16: 231C100036B | N16: Con isolamento ADD | P16: PPU | Q16: 232C10353E | R16: PPU DC Modificata per agg.panto 1.5 | T16: PCU | X16: PPU | Z16: Con isolamento ADD
B17: 25 kV | C17: 100170464 | D17: Struttura | E17: 10573076 | G17: 10949356 | H17: Struttura | I17: 10573076 | K17: 10949356 | L17: Struttura | M17: 10573076 | O17: 100170464 | P17: Struttura | Q17: 10573076 | T17: Struttura | X17: Struttura
D18: Archetto | E18: 10572700 | H18: Archetto | I18: 10572700 | L18: Archetto | M18: 10572700 | P18: Archetto | Q18: 10572700 | R18: Vedi strisciante | T18: Archetto | X18: Archetto
D19: Strisciante | E19: SK1630 | H19: Strisciante | I19: SK1630 | L19: Strisciante | M19: SK1630 | P19: Strisciante | Q19: SK 2381 | R19: Conforme a norma FR SAM E903 | T19: Strisciante | U19: SK1630 | X19: Strisciante | Y19: SK1630
D20: PPU | E20: 102895 | H20: PPU | I20: 232C10395F | J20: Con isolamento ADD | L20: PPU | M20: 231C100036B | N20: Con isolamento ADD | P20: PPU | Q20: 102895 | T20: PPU | X20: PPU | Z20: Con isolamento ADD
B21: 1,5 kV | C21: n/a | D21: Struttura | G21: n/a | H21: Struttura | K21: n/a | L21: Struttura | O21: 10851208 | P21: Struttura | Q21: 10573076 | T21: Struttura | X21: Struttura
D22: Archetto | H22: Archetto | L22: Archetto | P22: Archetto | Q22: 10882275 | R22: Larghezza 1.950 mm | T22: Archetto | X22: Archetto
D23: Strisciante | H23: Strisciante | L23: Strisciante | P23: Strisciante | Q23: SK 2348 | T23: Strisciante | X23: Strisciante
D24: PCU | H24: PCU | L24: PCU | P24: PPU | Q24: 232C10353E | R24: PPU Modificata per agg.panto 1.5 | T24: PCU | X24: PCU
B25: 15 kV | C25: n/a | D25: Struttura | G25: n/a | H25: Struttura | K25: n/a | L25: Struttura | P25: Struttura | T25: Struttura | X25: Struttura
D26: Archetto | H26: Archetto | L26: Archetto | P26: Archetto | T26: Archetto | X26: Archetto
D27: Strisciante | H27: Strisciante | L27: Strisciante | P27: Strisciante | T27: Strisciante | X27: Strisciante
D28: PCU | H28: PCU | L28: PCU | P28: PPU | T28: PCU | X28: PCU
A29: TCMS Hardware | B29: LV | D29: CCU-O | E29: 3EST000225-5707 | H29: CCU-O | I29: 3EST000225-5707 | L29: CCU-O | M29: Nuova architettura Full Ethernet | P29: CCU-O | Q29: 3EST000225-5707 | T29: CCU-O | U29: 3EST000225-5707 | X29: CCU-O | Y29: 3EST000236-6235 | Z29: Higher performances and longer spare parts support
D30: CCU-S | E30: 3EST000221-6430 | H30: CCU-S | I30: 3EST000221-6430 | L30: CCU-S | P30: CCU-S | Q30: 3EST000221-6430 | T30: CCU-S | U30: 3EST000221-6430 | X30: CCU-S | Y30: 3EST000232-1990
D31: MIO-S | E31: 3EST000228-0629 3EST000228-3395 3EST000228-3394 | H31: MIO-S | I31: 3EST000230-5830 3EST000230-5833 3EST000228-3394 | J31: Sell no more supported for new projects due to internal component out of production (legacy only) | L31: MIO-S | P31: MIO-S | Q31: 3EST000228-0629 3EST000228-3395 3EST000228-3394 | T31: MIO-S | U31: 3EST000228-0629 3EST000228-3395 3EST000228-3394 | X31: MIO-S | Y31: 3EST000230-5830 3EST000230-5833 3EST000228-3394 | Z31: Sell no more supported for new projects due to internal component out of production (legacy only)
B32: Teledia | D32: MCG | E32: 3EST000225-7169 | H32: MCG | I32: 3EST000234-1560 | J32: additional LTE connection | L32: MCG | P32: MCG | Q32: 3EST000225-7169 | T32: MCG | U32: 3EST000225-7169 | X32: MCG | Y32: 3EST000234-1560 | Z32: additional LTE connection
B33: Monitor | D33: IDU | E33: 3EST000223-8802 | H33: IDU | I33: 3EST000223-8802 | L33: IDU/TOD | P33: IDU | Q33: 3EST000223-8802 | T33: IDU | U33: 3EST000223-8802 | X33: IDU | Y33: 3EST000223-8802
B34: Bus | D34: T Repeater | E34: 3EST000212-3010 | H34: T Repeater | I34: 3EST000236-6770 | J34: Sell no more supported for new projects due to internal component out of production (legacy only) | L34: T Repeater | P34: T Repeater | Q34: 3EST000212-3010 | T34: T Repeater | U34: 3EST000212-3010 | X34: T Repeater | Y34: 3EST000236-6770 | Z34: Sell no more supported for new projects due to internal component out of production (legacy only)
D35: T Switch | E35: 3EST000212-3000 | H35: T Switch | I35: 3EST000236-6769 | L35: T Switch | P35: T Switch | Q35: 3EST000212-3000 | T35: T Switch | U35: 3EST000212-3000 | X35: T Switch | Y35: 3EST000236-6769
D36: R Switch | E36: 3EST000225-7297 | H36: R Switch | I36: 3EST000234-7837 | L36: R Switch | P36: R Switch | Q36: 3EST000225-7297 | T36: R Switch | U36: 3EST000225-7297 | X36: R Switch | Y36: 3EST000234-7837
A37: Energy Meter | B37: Tipo | C37: n/a | G37: n/a | K37: EMS Microelettrica integrato con TCMS | O37: EMS Microelettrica non integrato con TCMS | S37: EMS Alstom integrato con TCMS | W37: EMS Alstom integrato con TCMS
A38: Freno | B38: Centraline | D38: BCU | E38: FT0024971-100 (DM) FT0028492-100 (TT) | H38: BCU | I38: FT0024971-100 (DM) FT0028492-100 (TT) | L38: BCU | P38: BCU | Q38: FT0024971-100 (DM) FT0028492-100 (TT) | T38: BCU | U38: FT0024971-100 (DM) FT0028492-100 (TT) | X38: BCU
D39: WSP | E39: FT0024963-100 (DM) FT0024967-100 (TT) | H39: WSP | I39: FT0024963-100 (DM) FT0024967-100 (TT) | L39: WSP | P39: WSP | Q39: FT0024963-100 (DM) FT0024967-100 (TT) | T39: WSP | U39: FT0024963-100 (DM) FT0024967-100 (TT) | X39: WSP
B40: Pneumatica | D40: Distributore | E40: SW4 COD. 726 43V S1 10 | H40: Distributore | I40: SW4 COD. 726 43V S1 10 | L40: Distributore | P40: Distributore | Q40: SW4 COD. 726 43V S1 10 | T40: Distributore | U40: SW4 COD. 726 43V S1 10 | X40: Distributore
...

Sheet Modifiche progettuali
C2: VZI-50 | D2: VZI-51-58 | E2: VZI-6 | F2: VZI-4 | G2: VZ-FR | H2: VZ-ES | I2: VZ-DAI
B3: IPA (Indicazione Porte Aperte) | D3: SI | E3: SI | F3: SI | H3: SI | I3: SI
B4: BY-PASS ALLARME APPLICAZIONE PARKING BRAKE IN MOVIMENTO | D4: SI | E4: SI | F4: SI | H4: SI | I4: SI
B5: RIDONDANZA LOOP DNRA-BMS | D5: SI | E5: SI | F5: SI | H5: SI | I5: SI
B6: INTERRUTTORI 220V SPOSTATI INTERNO CASSA | D6: SI | E6: SI | F6: SI | H6: SI | I6: SI
B7: COMPRESSORE ARIA (?)
B8: BY-PASS ADD PER MARCIA SOCCORSO | D8: SI | E8: SI | F8: SI | H8: SI | I8: SI
B9: ARREDI TOILET BAR BISTROT
B10: COMANDO DISACCOPPIAMENTO AUTOMATICO TESTE ELETTRICHE | D10: SI | E10: SI | F10: SI | H10: SI | I10: SI
B11: PANTOGRAFI
B12: PIANO DI MANUTENZIONE
B13: BL SSB
B14: BL DIS
B15: ETCS HD (HW)
B16: ANTINCENDIO
B17: LAYOUT INTERNO
