Workbook

Sheet Issue
A1: Rev | B1: Data | C1: Descrizione
A2: 1.0 | B2: 46190 | C2: Presentazione bozza

Sheet ToDo
A1: Data | B1: Chi | C1: Priorità | D1: Descrizione | E1: Note
A2: 46190 | B2: Federico | C2: Alta | D2: protezione azionamenti | E2: da ricercare all'interno dei documenti, una volta collezionati tutti i doc disponibili sulla trazione
A3: 46190 | B3: Federico | C3: Alta | D3: ricerca doc propulsion | E3: in corso sui vari SGF
A4: 46190 | B4: Maurizio | C4: Alta | D4: legare manuali e CPR a documenti CONF | E4: eseguito manualmente, TBD legame automatico (vedi pt sotto)
A5: 46190 | B5: Federico | C5: Alta | D5: provare integrazione copilot | E5: Eseguita prova su FRS_Line_Voltage con compilazione automatica colonna B di Funzioni. Riutilizzabile per prossime FUNC ID
A6: 46189 | B6: Maurizio | C6: Bassa | D6: Definire struttura codice FUNC ID | E6: Valutare se necessario
A7: 46189 | B7: Maurizio | C7: Media | D7: Diagnostica: - Reperire documentazione diagnostica EVENTI + AWO per flotta - Definire modalità archiviazione file diagnostici per flotta e referenziazione in FUNZIONI | E7: Alcuni doc già recuperati, da definire criterio di archiviazione
A8: 46189 | B8: Maurizio | C8: Bassa | D8: Rivedere/Completare PBS | E8: TBD
A9: 46189 | B9: Maurizio | C9: Bassa | D9: Legare FUNZIONI a PBS ??? | E9: TBD
A10: 46189 | B10: Maurizio | C10: Bassa | D10: Pensare a come gestire in Funzioni, l'aggiornamento dei documenti richiamati. ES aggiungere campo data??? | E10: TBD
A11: 46196 | B11: Maurizio | C11: Alta | D11: Valutare se inserire colonna File Type in Conf Sheet per poter referenziare anche documenti diversi da pdf (es. file excel degli annex ICD) In tal caso modificare la costruzione del link in Funzioni | E11: la diversa tipologia di doc a disposizione potrebbe generare problemi nel referenziare i doc tramite link. Agganciare i link ad una colonna che indica il tipo di documento bypassa il problema del formato
A12: 46196 | B12: Maurizio | C12: Alta | D12: Inserire in Funzioni una colonna Doc Type che specifica la tipologia di documenti da linkare (es. CONFIG, MR_CPR, GENERAL, DIAGNOSTIC…) al quale è associato il foglio excel per la ricerca del documento (automatica nella formula del link) e la cartella di archiviazione per la costruzione del link (automatica) | E12: Dato che la costruzione del file DB e delle cartelle su Sharepoint (criterio di archiviazione) può essere ancora modificabile sulla base della tipologia di documenti che sarà necessario tracciare/archiviare, potrebbe essere utili introdurre un Doc Type che venga utilizzato sia per tracciare i doc su un foglio del DB dedicato sia per creare dinamicamente il link su cartelle ad oggi ancora "flessibili"
A13: 46197 | B13: Federico | C13: Media | D13: Pensare a come esportare il file in formato di HTML per poter essere navigabile via broswer | E13: Potrebbe essere utile in caso sia necessario reperire informazioni quando siamo a bordo treno anche da Telefono

Sheet Cartelle
A1: DESCRIZIONE | B1: NOME | C1: Livello | D1: INDIRIZZO | E1: LINK
A2: Root Sharepoint | B2: Sharepoint | C2: 0 | D2: https://gruppofsitaliane.sharepoint.com/:f:/r/sites/IngegneriaETReMezziLeggeri-Trenitalia/ | E2: =HYPERLINK(D2,"🔗") -> 🔗
A3: Cartella Documenti Ingegneria | B3: Shared%20Documents/ | C3: 1 | D3: =CONCATENATE($D$2,B3) -> https://gruppofsitaliane.sharepoint.com/:f:/r/sites/IngegneriaETReMezziLeggeri-Trenitalia/Shared%20Documents/ | E3: =HYPERLINK(D3,"🔗") -> 🔗
A4: Cartella Archiviazione doc ETR1000 | B4: DB_ETR1000/ | C4: 2 | D4: =CONCATENATE($D$3,B4) -> https://gruppofsitaliane.sharepoint.com/:f:/r/sites/IngegneriaETReMezziLeggeri-Trenitalia/Shared%20Documents/DB_ETR1000/ | E4: =HYPERLINK(D4,"🔗") -> 🔗
A5: Documenti di configurazione | B5: DOC_FLOTTE/ | C5: 3 | D5: =CONCATENATE($D$4,B5) -> https://gruppofsitaliane.sharepoint.com/:f:/r/sites/IngegneriaETReMezziLeggeri-Trenitalia/Shared%20Documents/DB_ETR1000/DOC_FLOTTE/ | E5: =HYPERLINK(D5,"🔗") -> 🔗
A6: Raccolta documentazione Funzioni | B6: DOC_FUNC/ | C6: 3 | D6: =CONCATENATE($D$4,B6) -> https://gruppofsitaliane.sharepoint.com/:f:/r/sites/IngegneriaETReMezziLeggeri-Trenitalia/Shared%20Documents/DB_ETR1000/DOC_FUNC/ | E6: =HYPERLINK(D6,"🔗") -> 🔗
A7: Raccolta file diagnostica | B7: DIAGNOSTICA/ | C7: 3 | D7: =CONCATENATE($D$4,B7) -> https://gruppofsitaliane.sharepoint.com/:f:/r/sites/IngegneriaETReMezziLeggeri-Trenitalia/Shared%20Documents/DB_ETR1000/DIAGNOSTICA/ | E7: =HYPERLINK(D7,"🔗") -> 🔗

Sheet Flotte
A1: Nome flotta | B1: ID flotta | C1: ID flotta "nativa" | D1: Ultima BL rilasciata | E1: Conf Sheet aggiornata a BL | F1: TOT Treni | G1: NUMERI TRENO
A2: VZI-50_IT Flotta base | B2: VZI_Base | C2: VZI_Base | D2: 6.3 ? | E2: 6.0 27/09/24 | F2: =COUNTIF(G2:BW2,"<>") -> 44 | G2: 1 | H2: 2 | I2: 3 | J2: 4 | K2: 5 | L2: 6 | M2: 7 | N2: 8 | O2: 9 | P2: 10 | Q2: 11 | R2: 12 | S2: 13 | T2: 14 | V2: 16 | W2: 17 | X2: 18 | Y2: 19 | AA2: 21 | AB2: 22 | AD2: 24 | AF2: 26 | AG2: 27 | AI2: 29 | AJ2: 30 | AL2: 32 | AM2: 33 | AN2: 34 | AP2: 36 | AQ2: 37 | AR2: 38 | AS2: 39 | AT2: 40 | AU2: 41 | AV2: 42 | AW2: 43 | AY2: 45 | AZ2: 46 | BB2: 48 | BE2: 46 | BF2: 47 | BG2: 48 | BH2: 49 | BI2: 50
A3: VZI-51-58_IT (New 14) | B3: VZI_New14 | C3: VZI_Base | D3: 4.3_14 17/12/2025 | E3: 4.2_14 30/01/2025 | F3: =COUNTIF(G3:BW3,"<>") -> 8 | BJ3: 51 | BK3: 52 | BL3: 53 | BM3: 54 | BN3: 55 | BO3: 56 | BP3: 57 | BQ3: 58
A4: VZ_IF Francia | B4: VZ_IF | C4: VZI_Base | D4: 4.3_IF 04/04/2025 | E4: 4.0_F 10/04/2024 | F4: =COUNTIF(G4:BW4,"<>") -> 8 | U4: 15 | AC4: 23 | AE4: 25 | AH4: 28 | AK4: 31 | BA4: 47 | BC4: 49 | BD4: 50
A5: VZ_ES Spagna | B5: VZ_ES | C5: VZI_New14 | D5: 2.8 16/04/2025 | E5: 2.4 09/03/2023 | F5: =COUNTIF(G5:BW5,"<>") -> 20 | G5: 1 | H5: 2 | I5: 3 | J5: 4 | K5: 5 | L5: 6 | M5: 7 | N5: 8 | O5: 9 | P5: 10 | Q5: 11 | R5: 12 | S5: 13 | T5: 14 | U5: 15 | V5: 16 | W5: 17 | X5: 18 | Y5: 19 | Z5: 20
A6: VZI-6_IT Full HRI (New 14) | B6: VZI-6_R1 | C6: VZI-6_R1 | D6: 5.0 15/04/2026 | E6: 4.0 ? xx/07/2025 | F6: =COUNTIF(G6:BW6,"<>") -> 6 | G6: 101 | H6: 102 | I6: 103 | J6: 104 | K6: 105 | L6: 106
A7: VZI-4_IT Full HRI | B7: VZI-4_R1 | C7: VZI-6_R1 | D7: 1.0 15/04/2026 | E7: ? | F7: =COUNTIF(G7:BW7,"<>") -> 40 | M7: 107 | N7: 108 | O7: 109 | P7: 110 | Q7: 111 | R7: 112 | S7: 113 | T7: 114 | U7: 115 | V7: 116 | W7: 117 | X7: 118 | Y7: 119 | Z7: 120 | AA7: 121 | AB7: 122 | AC7: 123 | AD7: 124 | AE7: 125 | AF7: 126 | AG7: 127 | AH7: 128 | AI7: 129 | AJ7: 130 | AK7: 131 | AL7: 132 | AM7: 133 | AN7: 134 | AO7: 135 | AP7: 136 | AQ7: 137 | AR7: 138 | AS7: 139 | AT7: 140 | AU7: 141 | AV7: 142 | AW7: 143 | AX7: 144 | AY7: 145 | AZ7: 146
A8: VZ_ES Spagna Full HRI | B8: VZ_ESxx | C8: VZI-6_R1 | F8: =COUNTIF(G8:BW8,"<>") -> 3 | AA8: 21 | AB8: 22 | AC8: 23
A9: VZ_DAI | B9: VZ_DAI | C9: VZI-6_R1 | F9: =COUNTIF(G9:BW9,"<>") -> 3 | Z9: 20 | AO9: 35 | AX9: 44

Sheet CONFIG
A1: Doc Description | B1: Doc ID | C1: VZI_Base | F1: VZI_New14 | I1: VZ_FR | L1: VZ_ES | O1: VZI-6_R1 | Q1: VZI-4_R1 | S1: VZ_DAI | U1: VZ_Esxx
C2: Doc BD130033980 - BL 6.0 | F2: BD140036813 - BL 4.2 | I2: 3ECP414415-0001 - BL 4.0 | L2: VZ-ES Spagna BL 2.4 | O2: VZI-6_IT [R1] BL 4.0 | Q2: VZI-4_IT [R1] BL 1.0 | S2: VZ-DAI BL xxx | U2: VZ_ES Full HRI BL xxx
C3: File/Codice | D3: Rev | E3: Codice Config | F3: File/Codice | G3: Rev | H3: Codice Config | I3: File/Codice | J3: Rev | K3: Codice Config | L3: File/Codice | M3: Rev | N3: Codice Config | O3: Codice | P3: Rev | Q3: Codice | R3: Rev | S3: Codice | T3: Rev | U3: Codice | V3: Rev
A4: SW Configuration
A5: SW Config. Matrix | B5: SW_Config | C5: BD130033981 | D5: _ | F5: 3ECP414196-0001 | G5: _ | I5: 3ECP414332-0001 | J5: _ | L5: 3ECP414502-0001 | M5: \ | O5: FT080031387 | P5: 4.3 | Q5: FT080031387 | R5: 4.3
A6: Functional principle diagrams (VISIO)
A7: Drive Control | B7: FPD_Drive Control | C7: 3ECP410467-0001 | D7: B | F7: 3ECP400500-0005 | G7: _ | I7: 3ECP410467-0001 | J7: B | L7: 3ECP413651-0005 | M7: _ | O7: FA010024090 | P7: 00.2 | Q7: FA010024090 | R7: 00.2
A8: Conventional Train Control | B8: FPD_Conventional Train Control | C8: 3ECP410476-0001 | D8: C | F8: 3ECP400500-0014 | G8: A | I8: 3ECP307072-0001 | J8: C | L8: 3ECP413651-0014 | M8: A | O8: FA010024089 | P8: 03.2 | Q8: FA010024089 | R8: 03.2
A9: Train Protection - ATP | B9: FPD_Train Protection - ATP | C9: 3ECP410482-0001 | D9: C | F9: 3ECP400500-0020 | G9: A | I9: 3ECP410482-0001 | J9: C | L9: 3ECP413651-0020 | M9: D | O9: FA010024100 | P9: 03.2 | Q9: FA010024100 | R9: 03.2
A10: TCMS Architecture | B10: FPD_TCMS Architecture | C10: \ | D10: \ | F10: \ | G10: \ | I10: 3ECP307076-0001 | J10: _ | L10: 3ECP307255-0001 | M10: D | O10: FA010024104 | P10: 00.2 | Q10: FA010024104 | R10: 00.2
A11: Propulsion and Auxiliary | B11: FPD_Propulsion and Auxiliary | C11: \ | D11: \ | F11: \ | G11: \ | L11: \ | M11: \ | O11: FA010024103 | P11: 01.2 | Q11: FA010024103 | R11: 01.2
A12: Line Voltage | B12: FPD_Line Voltage | C12: 3ECP410475-0001 | D12: B | F12: 3ECP400500-0013 | G12: C | I12: 3ECP307079-0001 | J12: A | L12: 3ECP413651-0013 | M12: _ | O12: FA010024096 | P12: 03.2 | Q12: FA010024096 | R12: 03.2
A13: Auxiliary Electrical Supply | B13: FPD_Auxiliary Electrical Supply | C13: 3ECP410465-0001 | D13: B | F13: 3ECP400500-0003 | G13: C | I13: 3ECP410465-0001 | J13: B | L13: 3ECP413651-0003 | M13: A | O13: FA010024083 | P13: 01.2 | Q13: FA010024083 | R13: 01.2
A14: Battery | B14: FPD_Battery | C14: 3ECP410477-0001 | D14: B | F14: 3ECP400500-0015 | G14: _ | I14: 3ECP410477-0001 | J14: B | L14: 3ECP413651-0015 | M14: _ | O14: FA010024084 | P14: 01.2 | Q14: FA010024084 | R14: 01.2
A15: Air Supply | B15: FPD_Air Supply | C15: 3ECP410463-0001 | D15: B | F15: 3ECP400500-0002 | G15: A | I15: 3ECP410463-0001 | J15: B | L15: 3ECP413651-0002 | M15: A | O15: FA010024081 | P15: 01.2 | Q15: FA010024081 | R15: 01.2
A16: Brake Control | B16: FPD_Brake Control | C16: 3ECP410480-0001 | D16: C | F16: 3ECP400500-0018 | G16: B | I16: 3ECP307074-0001 | J16: E | L16: 3ECP413651-0018 | M16: A | O16: FA010024086 | P16: 02.2 | Q16: FA010024086 | R16: 02.2
A17: Bogie | B17: FPD_Bogie | C17: 3ECP410466-0001 | D17: D | F17: 3ECP400500-0004 | G17: B | I17: 3ECP307081-0001 | J17: B | L17: 3ECP413651-0004 | M17: _ | O17: FA010024085 | P17: 01.2 | Q17: FA010024085 | R17: 01.2
A18: Wash Wiper | B18: FPD_Wash Wiper | C18: 3ECP410473-0001 | D18: B | F18: 3ECP400500-0011 | G18: _ | I18: 3ECP307082-0001 | J18: _ | L18: 3ECP413651-0011 | M18: _ | O18: FA010024101 | P18: 00.2 | Q18: FA010024101 | R18: 00.2
A19: Windscreen heater | B19: FPD_Windscreen heater | C19: 3ECP410474-0001 | D19: B | F19: 3ECP400500-0012 | G19: _ | I19: 3ECP410474-0001 | J19: B | L19: 3ECP413651-0012 | M19: _ | O19: FA010024102 | P19: 00.2 | Q19: FA010024102 | R19: 00.2
A20: Automatic Coupler | B20: FPD_Automatic Coupler | C20: 3ECP410481-0001 | D20: C | F20: 3ECP400500-0019 | G20: A | I20: 3ECP307077-0001 | J20: B | L20: 3ECP413651-0019 | M20: A | O20: FA010024082 | P20: 02.2 | Q20: FA010024082 | R20: 02.2
A21: Horn | B21: FPD_Horn | C21: 3ECP410468-0001 | D21: B | F21: 3ECP400500-0006 | G21: _ | I21: 3ECP410468-0001 | J21: B | L21: 3ECP413651-0006 | M21: _ | O21: FA010024094 | P21: 00.2 | Q21: FA010024094 | R21: 00.2
A22: Exterior and Interior Doors | B22: FPD_Exterior and Interior Doors | C22: 3ECP410462-0001 | D22: C | F22: 3ECP400500-0001 | G22: A | I22: 3ECP307073-0001 | J22: D | L22: 3ECP413651-0001 | M22: A | O22: FA010024091 | P22: 02.2 | Q22: FA010024091 | R22: 02.2
A23: Cab HVAC | B23: FPD_Cab HVAC | C23: 3ECP410470-0001 | D23: B | F23: 3ECP400500-0008 | G23: A | I23: 3ECP307084-0001 | J23: _ | L23: 3ECP413651-0008 | M23: A | O23: FA010024087 | P23: 00.2 | Q23: FA010024087 | R23: 00.2
... A30: Interior Lighting | B30: FPD_Interior Lighting | C30: 3ECP410478-0001 | D30: B | F30: 3ECP400500-0016 | G30: _ | I30: 3ECP410478-0001 | J30: B | L30: 3ECP413651-0016 | M30: A | O30: FA010024095 | P30: 01.2 | Q30: FA010024095 | R30: 01.2
A31: Train Control Design System | B31: FPD_Train Control | C31: \ | D31: \ | I31: 3ECP307076-0001 | J31: A | K31: manca
A32: Schematic diagram for French ATP MU | B32: FPD_ATP-MU | I32: 90000056.D04 | J32: 5.0 | K32: manca
A33: Functional Requirement Specification (FRS)
A34: Functional Vehicle Requirement Specification | B34: FRS_Vehicle | C34: 3EST000224-9984 | D34: C | E34: 3EST000224-9984 | L34: 3ECP413839-0001 | M34: B | N34: 3ECP413839-0001 | O34: \ | P34: \ | R34: \
A35: Drive Control | B35: FRS_Drive Control | C35: 3EST000225-7909 | D35: A | E35: 3EST000225-7909 | F35: 3EST000225-7909 | G35: A | I35: 3ECP413571-0501 | J35: _ | L35: 3EST000225-7909 | M35: A | N35: 3EST000225-7909 | O35: FA020022675 | P35: 03.2 4.0? | Q35: FA020022675 | R35: 03.2 4.0?
A36: Conventional Train Control | B36: FRS_Conventional Train Control | C36: 3EST000225-7916 | D36: A | E36: 3EST000225-7916 | F36: 3ECP413719-0903 | G36: _ | H36: manca | I36: FA02P021958B | J36: 2.0 | K36: 3ECP413719-0903 | L36: 3ECP413922-0903 | M36: _ | N36: 3ECP413922-0903 | O36: FA020023107 | P36: 06.3 | Q36: FA020023107 | R36: 06.3
A37: Train Protection - ATP | B37: FRS_Train Protection - ATP | C37: FA020013231 | D37: 01 | E37: 3EST000225-7889 EC01P008999B | F37: FA020013231 | G37: 01 | H37: 3ECP414246-0902 | I37: FA020013231 | J37: 01 | K37: 3EST000225-7889 EC01P008999B | L37: FA020007630 | M37: 04 | N37: 3ECP413922-0902 | O37: FA020025863 | P37: 01.3 | Q37: FA020025863 | R37: 01.3
A38: Diagnostics | B38: FRS_Diagnostics | C38: 3EST000225-7918 | D38: B | E38: 3EST000225-7918 | F38: 3EST000225-7918 | G38: B | H38: 3EST000225-7918 | I38: 3EST000225-7918 | J38: B | K38: 3EST000225-7918 | L38: 3ECP413922-1001 | M38: _ | N38: 3ECP413922-1001 | O38: FA020023413 | P38: 01.2 | Q38: FA020023413 | R38: 01.2
A39: Visualisation - MMI | B39: FRS_Visualisation - MMI | C39: 3EST000225-7919 | D39: B | E39: 3EST000225-7919 | F39: 3EST000225-7919 | G39: B | H39: 3EST000225-7919 | I39: 3EST000225-7919 | J39: B | K39: 3EST000225-7919 | L39: 3ECP413922-1003 | M39: _ | N39: 3ECP413922-1003 | O39: FA020027681 | P39: 03.2 | Q39: FA020027681 | R39: 03.2
A40: TCMS - Operational | B40: FRS_TCMS - Operational | C40: 3EST000225-7917 | D40: B | E40: 3EST000225-7917 | F40: 3EST000225-7917 | G40: B | H40: 3EST000225-7917 | I40: 3EST000225-7917 | J40: B | K40: 3EST000225-7917 | L40: 3ECP413922-0904 | M40: _ | N40: 3ECP413922-0904 | O40: FA020026278 | P40: 02.2 | Q40: FA020026278 | R40: 02.2
A41: Train to Wayside Communication (Teledia) | B41: FRS_Teledia | C41: 3ECP413176-0001 | D41: _ | E41: 3ECP413176-0001 | F41: 3ECP413719-1200 | G41: _ | H41: 3ECP413719-1200 | I41: 3ECP413176-0001 | J41: _ | K41: 3ECP413176-0001 | L41: 3ECP413719-1200 | M41: _ | N41: 3ECP413719-1200 | O41: \ | P41: \ | Q41: \ | R41: \
A42: Line Voltage | B42: FRS_Line Voltage | C42: 3EST000225-7907 | D42: C | E42: 3EST000225-7907 | F42: 3ECP413719-0401 | G42: _ | H42: manca | I42: 3ECP413571-0401 | J42: A | L42: 3EGH489028-2358 | M42: B | N42: 3EGH489028-2358 | O42: FA020022045 | P42: 06.2 | Q42: FA020022045 | R42: 06.2
A43: Aux Electrical Supply | B43: FRS_Aux Electrical Supply | C43: 3EST000225-7914 | D43: B | E43: 3EST000225-7914 | F43: 3EST000225-7914 | G43: B | H43: 3EST000225-7914 | I43: 3ECP413571-0601 | J43: _ | L43: 3EST000225-7914 | M43: B | N43: 3EST000225-7914 | O43: FA020024537 | P43: 03.2 | Q43: FA020024537 | R43: 03.2
A44: Battery | B44: FRS_Battery | C44: 3EST000225-7908 | D44: B | E44: 3EST000225-7908 | F44: 3EST000225-7908 | G44: B | H44: 3EST000225-7908 | I44: 3EST000225-7908 | J44: B | K44: 3EST000225-7908 | L44: 3EST000225-7908 | M44: B | N44: 3EST000225-7908 | O44: FA020024538 | P44: 03.2 | Q44: FA020024538 | R44: 03.2
A45: Air Supply | B45: FRS_Air Supply | C45: 3EST000225-7915 | D45: D | E45: 3EST000225-7915 | F45: 3ECP413719-0603 | G45: _ | H45: 3ECP413719-0603 | I45: 3EST000225-7915 | J45: D | K45: 3EST000225-7915 | L45: 3ECP413719-0603 | M45: _ | N45: 3ECP413719-0603 | O45: FA020024531 | P45: 01.3 | Q45: FA020024531 | R45: 01.3
A46: Brake Control | B46: FRS_Brake Control | C46: 3EST000225-7910 | D46: L | E46: 3EST000225-7910 | F46: 3ECP413719-0502 | G46: A | H46: manca | I46: 3ECP413571-0502 | J46: C | L46: 3ECP413922-0502 | M46: A | N46: 3ECP413922-0502 | O46: FA020023100 | P46: 02.3 | Q46: FA020023100 | R46: 02.3
...

Sheet GENERAL
A1: Doc Description | B1: Doc ID | C1: File type | D1: VZI_Base | F1: VZI_New14 | H1: VZ_FR | J1: VZ_ES | L1: VZI-6_R1 | N1: VZI-4_R1 | P1: VZ_DAI | R1: VZ_Esxx
D2: File/Codice | E2: Rev | F2: File/Codice | G2: Rev | H2: File/Codice | I2: Rev | J2: File/Codice | K2: Rev | L2: Codice | M2: Rev | N2: Codice | O2: Rev | P2: Codice | Q2: Rev | R2: Codice | S2: Rev
A3: Energy
A4: EMS Schemi Visio | B4: FPD_EMS | C4: pdf | H4: FA010031914 | I4: 00.1
A5: EMS Func Req | B5: FRS_EMS | C5: pdf | H5: EC010029076 | I5: 00.1 | L5: EC010019484 | M5: 01
A6: Functional Doc & Specification
A7: Architettura di Controllo Treno ed Interfacce di Comando | B7: DF_TCMS | C7: pdf | D7: 3ECP410429-0001 | E7: L | F7: 3ECP413973-0001 | G7: A
A8: Brake System | B8: DF_Brake | C8: pdf | D8: 3EGH489013-3044 | E8: F
A9: Air Supply | B9: DF_Air Supply | C9: pdf | D9: 3EGH489013-4928 | E9: A
A10: High Voltage System | B10: DF_High Voltage | C10: pdf | D10: 3EST000225-0599 | E10: B
A11: Sistema di controllo propulsione | B11: ST_Propulsion | C11: pdf | D11: 3ECP507757-0001 | E11: _
A12: ETR1000 HW Functionality Overview | B12: HWFO_ETR1000 | C12: pdf | D12: 3EST000225-6040 | E12: J
A13: Descrizione SW Alta Tensione | B13: SDS_High Voltage | C13: pdf | D13: 3EST000225-5113 | E13: C
A14: Descrizione SW Propulsione | B14: SDS_Propulsion | C14: pdf | D14: 3EST000225-5115 | E14: C
A15: Descrizione SW DCU/L | B15: SDS_DCU/L | C15: pdf | D15: 3EST000225-5117 | E15: B
A16: Descrizione SW DCU/C | B16: SDS_DCU/C | C16: pdf | D16: 3EST000225-5120 | E16: C
A17: Descrizione SW LIM | B17: SDS_LIM | C17: pdf | D17: 3EST000225-5132 | E17: _
A18: Descrizione SW ACM | B18: SDS_ACM | C18: pdf | D18: 3EST000225-5119 | E18: E
A19: Descrizione SW PCU | B19: SDS_PCU | C19: pdf | D19: 3EST000225-5111 | E19: C
A20: Descrizione SW DCU/M | B20: SDS_DCU/M | C20: pdf | D20: 3EST000225-5118 | E20: G
A25: Product Description
A26: Converter unit TC1120 | B26: PDES_Converter | C26: pdf | D26: 3EST000228-5653 | E26: B
A27: Auxiliary converter module, CM-C S 15/10 WA V02 | B27: PDES_Auxiliary module | C27: pdf | D27: 3EST000226-1993 | E27: A
A28: Chopper converter module, CM-C L 30/07 WC V01 | B28: PDES_Chopper module | C28: pdf | D28: 3EST000226-1995 | E28: B
A29: Line converter module, CM-C M 15/15 WL V06 | B29: PDES_Line Module | C29: pdf | D29: 3EST000226-1994 | E29: B
A30: Motor converter module, CM-C S 15/10 WM V02 | B30: PDES_Motor Module | C30: pdf | D30: 3EST000226-1992 | E30: B
A31: Converter interface | B31: ICD_Converter | C31: pdf | D31: 3EST000225-0120 | E31: D
A32: TCMS Tech Description | B32: PDES_TCMS | C32: pdf | D32: 3EST000225-4855 | E32: E
A33: Brake Tech Description | B33: PDES_Brake | C33: pdf | D33: FTIT10002-I01TDE | E33: F00
A36: Requirements Document
A37: Propulsion and Auxiliary Supply | B37: SS_Propulsion and Auxiliary | C37: pdf | D37: 3EST000225-1983 | E37: A
A38: Brake SW Req | B38: SRS_Brake | C38: pdf | D38: 3EST000227-7526 | E38: M
A39: Propulsion and Auxiliary Supply | B39: TRD_Propulsion and Auxiliary | C39: pdf | D39: 3EGH489007-6600 | E39: H
A40: Pantograph | B40: TRD_Pantograph | C40: pdf | D40: 3EGH489007-6593 | E40: G
A41: Line Circuit Breaker with Earthing Switch | B41: TRD_LCB | C41: pdf | D41: 3EKD000000-0417 | E41: C
A42: Roof Line Disconnector | B42: TRD_Roof Line Disconnector | C42: pdf | D42: 3EKD000000-0419 | E42: B
A43: Surge Arrester | B43: TRD_Surge Arrester | C43: pdf | D43: 3EKD000000-0416
A44: DC System Disconnector | B44: TRD_DC System Disconnector | C44: pdf | D44: 3EKD000000-0427 | E44: E
A45: DC System Isolation Switch | B45: TRD_DC System Isolation Switch | C45: pdf | D45: 3EKD000000-0428 | E45: B
A46: AC Charging resistor | B46: TRD_AC Charging resistor | C46: pdf | D46: 3EKD000000-0460 | E46: A
...

Sheet MAN_CPR
A1: TRENO | B1: TIPO | C1: VOLUME SUBVOLUME _TOMO | D1: DESCRIZIONE | E1: DOC ID | F1: VZI_Base | I1: VZI_New14 | L1: VZ_FR | O1: VZ-ES | R1: VZI-6_R1 | U1: VZI-4_R1
F2: REF | G2: REV | H2: DATA | I2: REF | J2: REV | K2: DATA | L2: REF | M2: REV | N2: DATA | O2: REF | P2: REV | Q2: DATA | R2: REV | U2: REV
A3: ETR1000V300 | B3: PBC | C3: 01A | D3: Descrizione generale e funzionamento | E3: =CONCATENATE(B3,"-",C3) -> PBC-01A | F3: =CONCATENATE("ETR1000V300-",$E3) -> ETR1000V300-PBC-01A | G3: 14 | H3: 46113 | I3: =CONCATENATE("ETR1000V300-",$E3) -> ETR1000V300-PBC-01A | J3: 14 | K3: 46113 | R3: 06 | U3: 06
A4: ETR1000V300 | B4: PBC | C4: 01B | D4: Norme d’Uso ed Interventi di Emergenza | E4: =CONCATENATE(B4,"-",C4) -> PBC-01B | F4: =CONCATENATE("ETR1000V300-",$E4) -> ETR1000V300-PBC-01B | G4: 14 | H4: 45748 | I4: =CONCATENATE("ETR1000V300-",$E4) -> ETR1000V300-PBC-01B | J4: 14 | K4: 45748 | L4: TBD | M4: TBD | N4: TBD | O4: TBD | P4: TBD | Q4: TBD | R4: 09 | U4: 09
A5: ETR1000V300 | B5: PBS | C5: 01A | D5: Manuale per il Personale di Bordo addetto alla Scorta | E5: =CONCATENATE(B5,"-",C5) -> PBS-01A | F5: =CONCATENATE("ETR1000V300-",$E5) -> ETR1000V300-PBS-01A | G5: 04 | H5: 45748 | I5: =CONCATENATE("ETR1000V300-",$E5) -> ETR1000V300-PBS-01A | J5: 04 | K5: 45748 | L5: esiste collana completa Giugno 2022 in | R5: 03 | U5: 03
A6: ETR1000V300 | B6: MR1 | C6: 01A | D6: Cassa | E6: =CONCATENATE(B6,"-",C6) -> MR1-01A | F6: =CONCATENATE("ETR1000V300-",$E6) -> ETR1000V300-MR1-01A | G6: 08 | H6: 46113 | I6: =CONCATENATE("ETR1000V300-",$E6) -> ETR1000V300-MR1-01A | J6: 08 | K6: 46113 | L6: SGF Base/ Documentazione Tecnica | R6: 05 | U6: 05
A7: ETR1000V300 | B7: MR1 | C7: 02A | D7: Carrello | E7: =CONCATENATE(B7,"-",C7) -> MR1-02A | F7: =CONCATENATE("ETR1000V300-",$E7) -> ETR1000V300-MR1-02A | G7: 14 | H7: 46113 | I7: =CONCATENATE("ETR1000V300-",$E7) -> ETR1000V300-MR1-02A | J7: 14 | K7: 46113 | L7: / ETR1000 I-F | R7: 08 | U7: 08
A8: ETR1000V300 | B8: MR1 | C8: 03A | D8: Impianto pneumatico e freno | E8: =CONCATENATE(B8,"-",C8) -> MR1-03A | F8: =CONCATENATE("ETR1000V300-",$E8) -> ETR1000V300-MR1-03A | G8: 09 | H8: 46113 | I8: =CONCATENATE("ETR1000V300-",$E8) -> ETR1000V300-MR1-03A | J8: 09 | K8: 46113 | L8: / Manualistica Corridoio I/F | R8: 04 | U8: 04
A9: ETR1000V300 | B9: MR1 | C9: 04A | D9: Equipaggiamento elettrico ed elettropneumatico | E9: =CONCATENATE(B9,"-",C9) -> MR1-04A | F9: =CONCATENATE("ETR1000V300-",$E9) -> ETR1000V300-MR1-04A | G9: 10 | H9: 46113 | I9: =CONCATENATE("ETR1000V300-",$E9) -> ETR1000V300-MR1-04A | J9: 10 | K9: 46113 | R9: 05 | U9: 05
A10: ETR1000V300 | B10: MR1 | C10: 05A | D10: Logica di comando | E10: =CONCATENATE(B10,"-",C10) -> MR1-05A | F10: =CONCATENATE("ETR1000V300-",$E10) -> ETR1000V300-MR1-05A | G10: 04 | H10: 46113 | I10: =CONCATENATE("ETR1000V300-",$E10) -> ETR1000V300-MR1-05A | J10: 04 | K10: 46113 | R10: 03 | U10: 03
A11: ETR1000V300 | B11: MR1 | C11: 05B | D11: Logica di comando - Nodo TCN | E11: =CONCATENATE(B11,"-",C11) -> MR1-05B | F11: =CONCATENATE("ETR1000V300-",$E11) -> ETR1000V300-MR1-05B | G11: 02 | H11: giu-17 | I11: =CONCATENATE("ETR1000V300-",$E11) -> ETR1000V300-MR1-05B | J11: 02 | K11: giu-17 | R11: 04 | U11: 04
A12: ETR1000V300 | B12: MR1 | C12: 06A | D12: Azionamento di trazione | E12: =CONCATENATE(B12,"-",C12) -> MR1-06A | F12: =CONCATENATE("ETR1000V300-",$E12) -> ETR1000V300-MR1-06A | G12: 05 | H12: 46113 | I12: =CONCATENATE("ETR1000V300-",$E12) -> ETR1000V300-MR1-06A | J12: 05 | K12: 46113 | R12: 04 | U12: 04
A13: ETR1000V300 | B13: MR1 | C13: 07A | D13: Motore di trazione | E13: =CONCATENATE(B13,"-",C13) -> MR1-07A | F13: =CONCATENATE("ETR1000V300-",$E13) -> ETR1000V300-MR1-07A | G13: 07 | H13: 46113 | I13: =CONCATENATE("ETR1000V300-",$E13) -> ETR1000V300-MR1-07A | J13: 07 | K13: 46113 | R13: 04 | U13: 04
A14: ETR1000V300 | B14: MR1 | C14: 08A | D14: Passaggi esterni | E14: =CONCATENATE(B14,"-",C14) -> MR1-08A | F14: =CONCATENATE("ETR1000V300-",$E14) -> ETR1000V300-MR1-08A | G14: 05 | H14: 46113 | I14: =CONCATENATE("ETR1000V300-",$E14) -> ETR1000V300-MR1-08A | J14: 05 | K14: 46113 | R14: 04 | U14: 04
A15: ETR1000V300 | B15: MR1 | C15: 09A | D15: Sottosistema di climatizzazione | E15: =CONCATENATE(B15,"-",C15) -> MR1-09A | F15: =CONCATENATE("ETR1000V300-",$E15) -> ETR1000V300-MR1-09A | G15: 05 | H15: 46113 | I15: =CONCATENATE("ETR1000V300-",$E15) -> ETR1000V300-MR1-09A | J15: 05 | K15: 46113 | R15: 04 | U15: 04
A16: ETR1000V300 | B16: MR1 | C16: 10A | D16: Sottosistema di comunicazione | E16: =CONCATENATE(B16,"-",C16) -> MR1-10A | F16: =CONCATENATE("ETR1000V300-",$E16) -> ETR1000V300-MR1-10A | G16: 05 | H16: 46113 | I16: =CONCATENATE("ETR1000V300-",$E16) -> ETR1000V300-MR1-10A | J16: 05 | K16: 46113 | R16: 03 | U16: 03
A17: ETR1000V300 | B17: MR1 | C17: 11A | D17: Convertitore servizi ausiliari e caricabatterie | E17: =CONCATENATE(B17,"-",C17) -> MR1-11A | F17: =CONCATENATE("ETR1000V300-",$E17) -> ETR1000V300-MR1-11A | G17: 03 | H17: 46113 | I17: =CONCATENATE("ETR1000V300-",$E17) -> ETR1000V300-MR1-11A | J17: 03 | K17: 46113 | R17: 03 | U17: 03
A18: ETR1000V300 | B18: MR1 | C18: 13A | D18: Sottosistema diagnostica di bordo | E18: =CONCATENATE(B18,"-",C18) -> MR1-13A | F18: =CONCATENATE("ETR1000V300-",$E18) -> ETR1000V300-MR1-13A | G18: 03 | H18: 46113 | I18: =CONCATENATE("ETR1000V300-",$E18) -> ETR1000V300-MR1-13A | J18: 03 | K18: 46113 | R18: 03 | U18: 03
A19: ETR1000V300 | B19: MR1 | C19: 14A | D19: Allestimenti interni | E19: =CONCATENATE(B19,"-",C19) -> MR1-14A | F19: =CONCATENATE("ETR1000V300-",$E19) -> ETR1000V300-MR1-14A | G19: 06 | H19: 46113 | I19: =CONCATENATE("ETR1000V300-",$E19) -> ETR1000V300-MR1-14A | J19: 06 | K19: 46113
A20: ETR1000V300 | B20: MR1 | C20: 14B | D20: Allestimenti interni - Arredi comparto e cabina di guida | E20: =CONCATENATE(B20,"-",C20) -> MR1-14B | F20: =CONCATENATE("ETR1000V300-",$E20) -> ETR1000V300-MR1-14B | G20: \ | H20: \ | I20: =CONCATENATE("ETR1000V300-",$E20) -> ETR1000V300-MR1-14B | J20: \ | K20: \ | R20: 03 | U20: 03
A21: ETR1000V300 | B21: MR1 | C21: 15A | D21: Servizi Generali di Bordo - Toilette | E21: =CONCATENATE(B21,"-",C21) -> MR1-15A | F21: =CONCATENATE("ETR1000V300-",$E21) -> ETR1000V300-MR1-15A | G21: 06 | H21: 46113 | I21: =CONCATENATE("ETR1000V300-",$E21) -> ETR1000V300-MR1-15A | J21: 06 | K21: 46113 | R21: 03 | U21: 03
A22: ETR1000V300 | B22: MR1 | C22: 15B | D22: Servizi Generali di Bordo - Bar Bistrot | E22: =CONCATENATE(B22,"-",C22) -> MR1-15B | F22: =CONCATENATE("ETR1000V300-",$E22) -> ETR1000V300-MR1-15B | G22: \ | H22: \ | I22: =CONCATENATE("ETR1000V300-",$E22) -> ETR1000V300-MR1-15B | J22: \ | K22: \ | R22: 03 | U22: 03
A23: ETR1000V300 | B23: MR1 | C23: 16A | D23: Emergenza e recupero | E23: =CONCATENATE(B23,"-",C23) -> MR1-16A | F23: =CONCATENATE("ETR1000V300-",$E23) -> ETR1000V300-MR1-16A | G23: 07 | H23: 44228 | I23: =CONCATENATE("ETR1000V300-",$E23) -> ETR1000V300-MR1-16A | J23: 07 | K23: 44228 | R23: 03 | U23: 03
A24: ETR1000V300 | B24: MR1 | C24: 18A | D24: Telecomunicazioni TT | E24: =CONCATENATE(B24,"-",C24) -> MR1-18A | F24: =CONCATENATE("ETR1000V300-",$E24) -> ETR1000V300-MR1-18A | G24: 05 | H24: 46113 | I24: =CONCATENATE("ETR1000V300-",$E24) -> ETR1000V300-MR1-18A | J24: 05 | K24: 46113 | R24: 03 | U24: 03
A25: ETR1000V300 | B25: MR1 | C25: 20A | D25: Sottosistema di bordo generale | E25: =CONCATENATE(B25,"-",C25) -> MR1-20A | F25: =CONCATENATE("ETR1000V300-",$E25) -> ETR1000V300-MR1-20A | G25: 03 | H25: giu-20 | I25: =CONCATENATE("ETR1000V300-",$E25) -> ETR1000V300-MR1-20A | J25: 03 | K25: giu-20 | R25: 05 | U25: 05
A26: ETR1000V300 | B26: MR1 | C26: 20B | D26: Sottosistema di bordo ETCS specifico del treno | E26: =CONCATENATE(B26,"-",C26) -> MR1-20B | F26: =CONCATENATE("ETR1000V300-",$E26) -> ETR1000V300-MR1-20B | G26: 01 | H26: lug-17 | I26: =CONCATENATE("ETR1000V300-",$E26) -> ETR1000V300-MR1-20B | J26: 01 | K26: lug-17 | R26: 02 | U26: 02
A27: ETR1000V300 | B27: MR1 | C27: 20A_ALA | D27: SSB ERTMS/SCMT (ALA) - MANUALE GENERICO USO E MANUTENZIONE (B60A.000012.640.06I) | E27: =CONCATENATE(B27,"-",C27) -> MR1-20A_ALA | F27: =CONCATENATE("ETR1000V300-",$E27) -> ETR1000V300-MR1-20A_ALA | G27: 08 | H27: 43966 | I27: \ | J27: \ | K27: \
A28: ETR1000V300 | B28: MR1 | C28: 20A_ELO | D28: SSB ERTMS/SCMT (ELO) - MANUALE GENERICO USO E MANUTENZIONE (B60X.0100506.G00.00IT rev.02.00) | E28: =CONCATENATE(B28,"-",C28) -> MR1-20A_ELO | F28: =CONCATENATE("ETR1000V300-",$E28) -> ETR1000V300-MR1-20A_ELO | G28: 05 | H28: 46113 | I28: =CONCATENATE("ETR1000V300-",$E28) -> ETR1000V300-MR1-20A_ELO | J28: 05 | K28: 46113
A29: ETR1000V300 | B29: MR1 | C29: 20B_ELO | D29: Sotto Sistema di Bordo ERTMS BL3 CON SCMT INTEGRATO (B60A.0100914.G00.00IT) | E29: =CONCATENATE(B29,"-",C29) -> MR1-20B_ELO | F29: =CONCATENATE("ETR1000V300-",$E29) -> ETR1000V300-MR1-20B_ELO | G29: 02 | H29: 45717 | I29: =CONCATENATE("ETR1000V300-",$E29) -> ETR1000V300-MR1-20B_ELO | J29: 02 | K29: 45717
A30: ETR1000V300 | B30: MR1 | C30: 31A_JRU | D30: PGDJ DIS-JRU FTP - PRODOTTO GENERICO DIS-JRU (FT11P035105GE03B) | E30: =CONCATENATE(B30,"-",C30) -> MR1-31A_JRU | F30: =CONCATENATE("ETR1000V300-",$E30) -> ETR1000V300-MR1-31A_JRU | G30: \ | H30: 44256 | I30: =CONCATENATE("ETR1000V300-",$E30) -> ETR1000V300-MR1-31A_JRU | J30: \ | K30: 44256
A31: ETR1000V300 | B31: MR1 | C31: 31A | D31: Sistema informativo di condotta Generale (DIS) | E31: =CONCATENATE(B31,"-",C31) -> MR1-31A | F31: =CONCATENATE("ETR1000V300-",$E31) -> ETR1000V300-MR1-31A | G31: 02 | H31: gen-18 | I31: =CONCATENATE("ETR1000V300-",$E31) -> ETR1000V300-MR1-31A | J31: 02 | K31: gen-18 | R31: 04 | U31: 04
A32: ETR1000V300 | B32: MR2 | C32: 01A | D32: Cassa | E32: =CONCATENATE(B32,"-",C32) -> MR2-01A | F32: =CONCATENATE("ETR1000V300-",$E32) -> ETR1000V300-MR2-01A | G32: 07 | H32: 46113 | I32: =CONCATENATE("ETR1000V300-",$E32) -> ETR1000V300-MR2-01A | J32: 07 | K32: 46113
A33: ETR1000V300 | B33: MR2 | C33: 02A | D33: Carrello | E33: =CONCATENATE(B33,"-",C33) -> MR2-02A | F33: =CONCATENATE("ETR1000V300-",$E33) -> ETR1000V300-MR2-02A | G33: 13 | H33: 46113 | I33: =CONCATENATE("ETR1000V300-",$E33) -> ETR1000V300-MR2-02A | J33: 13 | K33: 46113
A34: ETR1000V300 | B34: MR2 | C34: 03A | D34: Impianto pneumatico e freno | E34: =CONCATENATE(B34,"-",C34) -> MR2-03A | F34: =CONCATENATE("ETR1000V300-",$E34) -> ETR1000V300-MR2-03A | G34: 06 | H34: 46113 | I34: =CONCATENATE("ETR1000V300-",$E34) -> ETR1000V300-MR2-03A | J34: 06 | K34: 46113
A35: ETR1000V300 | B35: MR2 | C35: 04A | D35: Equipaggiamento elettrico ed elettropneumatico | E35: =CONCATENATE(B35,"-",C35) -> MR2-04A | F35: =CONCATENATE("ETR1000V300-",$E35) -> ETR1000V300-MR2-04A | G35: 10 | H35: 46113 | I35: =CONCATENATE("ETR1000V300-",$E35) -> ETR1000V300-MR2-04A | J35: 10 | K35: 46113
A36: ETR1000V300 | B36: MR2 | C36: 05A | D36: Logica di comando | E36: =CONCATENATE(B36,"-",C36) -> MR2-05A | F36: =CONCATENATE("ETR1000V300-",$E36) -> ETR1000V300-MR2-05A | G36: 03 | H36: 46113 | I36: =CONCATENATE("ETR1000V300-",$E36) -> ETR1000V300-MR2-05A | J36: 03 | K36: 46113
A37: ETR1000V300 | B37: MR2 | C37: 05B | D37: Logica di comando - Nodo TCN | E37: =CONCATENATE(B37,"-",C37) -> MR2-05B | F37: =CONCATENATE("ETR1000V300-",$E37) -> ETR1000V300-MR2-05B | G37: 02 | H37: giu-17 | I37: =CONCATENATE("ETR1000V300-",$E37) -> ETR1000V300-MR2-05B | J37: 02 | K37: giu-17
A38: ETR1000V300 | B38: MR2 | C38: 06A | D38: Azionamento di trazione | E38: =CONCATENATE(B38,"-",C38) -> MR2-06A | F38: =CONCATENATE("ETR1000V300-",$E38) -> ETR1000V300-MR2-06A | G38: 04 | H38: 46113 | I38: =CONCATENATE("ETR1000V300-",$E38) -> ETR1000V300-MR2-06A | J38: 04 | K38: 46113
A39: ETR1000V300 | B39: MR2 | C39: 07A | D39: Motore di trazione | E39: =CONCATENATE(B39,"-",C39) -> MR2-07A | F39: =CONCATENATE("ETR1000V300-",$E39) -> ETR1000V300-MR2-07A | G39: 05 | H39: 46113 | I39: =CONCATENATE("ETR1000V300-",$E39) -> ETR1000V300-MR2-07A | J39: 05 | K39: 46113
A40: ETR1000V300 | B40: MR2 | C40: 08A | D40: Passaggi esterni | E40: =CONCATENATE(B40,"-",C40) -> MR2-08A | F40: =CONCATENATE("ETR1000V300-",$E40) -> ETR1000V300-MR2-08A | G40: 04 | H40: 46113 | I40: =CONCATENATE("ETR1000V300-",$E40) -> ETR1000V300-MR2-08A | J40: 04 | K40: 46113
...

Sheet DIAGNOSTIC
A1: Doc Description | B1: Doc ID | C1: File type | D1: VZI_Base | F1: VZI_New14 | H1: VZ_FR | J1: VZ_ES | L1: VZI-6_R1 | N1: VZI-4_R1 | P1: VZ_DAI | R1: VZ_Esxx
D2: File/Codice | E2: Rev | F2: File/Codice | G2: Rev | H2: File/Codice | I2: Rev | J2: File/Codice | K2: Rev | L2: Codice | M2: Rev | N2: Codice | O2: Rev | P2: Codice | Q2: Rev | R2: Codice | S2: Rev
A3: Telediagnostica
A4: Progetto concettuale | B4: PRG_Teledia | C4: pdf | D4: 3ECP409852-0001 | E4: \
A5: Sviluppo regole (Algoritmi Diagnostici) | B5: AD_Flotte | C5: xlsm | D5: Sviluppo_Regole_TI_rev1.1 | E5: \ | F5: SVILUPPO REGOLE_ 14_FR_SP_Rev_0.1 | G5: \ | H5: SVILUPPO REGOLE_ 14_FR_SP_Rev_0.1 | I5: \ | J5: SVILUPPO REGOLE_ 14_FR_SP_Rev_0.1 | K5: \
A6: Event Report | B6: Event_Report | C6: xlsx | D6: EventReport_VZI_3.9.0.3 | E6: \ | F6: EventReport_VZI14_BL3_5.1.0.3 2 | G6: \ | H6: EventReport VZIF 11.4.0 | I6: \ | J6: EventReport_VZS 21.2.0.3
A7: Progetto concettuale | B7: PRG_Teledia | C7: pdf | D7: 3ECP409852-0001 | E7: \
A8: Diagnostic Event List | B8: Event_VZI-6 | C8: xlsx | L8: FP010036055 | M8: 3.32
A9: Teledia Signal List | B9: Signal_VZI-6 | C9: xlsx | L9: FP020046917 | M9: 3.32
A10: PropulsionDiagnosticDataset | B10: Dataset_Propulsion | C10: xlsx | L10: PropulsionDiagnosticDataset | M10: 00.12
A11: EMS ICD diagnostic event | B11: Event_EMS | C11: xlsx | H11: EC130034365 | I11: 00

Sheet Funzioni
A1: FUNC ID | B1: DESCRIZIONE FUNZIONE | C1: DOC Type | D1: DOC ID | E1: Info DOC | F1: VZI_Base | G1: VZI_New14 | H1: VZ_FR | I1: VZ_ES | J1: VZI-6_R1 | K1: VZI-4_R1 | L1: VZ_DAI
A2: Park_Brake_01 | B2: Comando applicazione/rilascio FAM da banco di manovra | C2: HW | D2: =IF($A2="","",HYPERLINK(CONCATENATE(Cartelle!$D$6,$A2),CONCATENATE("#Sharepoint//",$A2))) -> #Sharepoint//Park_Brake_01
D3: FS_DM1 | E3: Link | F3: {=HYPERLINK(CONCATENATE(Cartelle!$D$5,F$1,"/CONFIG/",MID($D3,1,FIND("_",$D3)-1),"/",INDIRECT(CONCATENATE("'CONFIG'!",ADDRESS(MATCH($D3, CONFIG!$B:$B, 0),MATCH(F$1, CONFIG!$1:$1, 0)))),".pdf#page=",F4),CONCATENATE("#Sharepoint//",$D3))} -> #Sharepoint//FS_DM1 | J3: {=HYPERLINK(CONCATENATE(Cartelle!$D$5,J$1,"/CONFIG/",MID($D3,1,FIND("_",$D3)-1),"/",INDIRECT(CONCATENATE("'CONFIG'!",ADDRESS(MATCH($D3, CONFIG!$B:$B, 0),MATCH(J$1, CONFIG!$1:$1, 0)))),".pdf#page=",J4),CONCATENATE("#Sharepoint//",$D3))} -> #Sharepoint//FS_DM1
E4: Rif. Pagina | F4: 276 | G4: 243 | J4: 144
E5: Componenti circuito elettrico | F5: GG-A024 = Pulsante parking JE-K0005 = MIO-S-DX4 | J5: GG-A024 = Pulsante parking GC-K025 = Relè abilitazione cabina GC-K018 = Relè temporizz GC-K011 = Relè abilitazione cabina JE-K005 = RIO-LP MASTER
E6: Descrizione circuitale | F6: La pressione di GG-A024 chiude 2 contatti interni (1 ordinario, 1 ridondato), collegando 2 linee 110V a 2 ingressi della MIO: BRA_PARK_COM Le 2 linee 110 derivano direttamente dal bus 180, tramite due fusibili rispettivamente JE-F007 e JE-F009. | J6: La pressione di GG-A024 chiude 2 contatti interni (1 ordinario, 1 ridondato), collegando 2 linee 110V a 2 ingressi della RIO: BRA_PARK_COM_N e BRA_PARK_COM_R Le 2 linee 110 derivano direttamente dal bus 180, tramite due fusibili rispettivamente JE-F007 e JE-F009. Un contatto del pulsante inoltre alimenta un circuito che intercetta, sulle casse portanti con disponibilità del freno di parcheggio, il comando di rilascio del TCMS verso le valvole di attuazione del parking brake stesso. Tale circuito viene alimentato tramite i relè di banco GC-K011 e GC-K025 e attuato per mezzo del relè temporizzato GC-K018. Tutta questa catena alimenta un relè GG-K028 presenti sulle casse portanti con disponibilità di freno di parcheggio.
D7: FS_TT2 | E7: Link | F7: {=HYPERLINK(CONCATENATE(Cartelle!$D$5,F$1,"/CONFIG/",MID($D7,1,FIND("_",$D7)-1),"/",INDIRECT(CONCATENATE("'CONFIG'!",ADDRESS(MATCH($D7, CONFIG!$B:$B, 0),MATCH(F$1, CONFIG!$1:$1, 0)))),".pdf#page=",F8),CONCATENATE("#Sharepoint//",$D7))} -> #Sharepoint//FS_TT2 | J7: {=HYPERLINK(CONCATENATE(Cartelle!$D$5,J$1,"/CONFIG/",MID($D7,1,FIND("_",$D7)-1),"/",INDIRECT(CONCATENATE("'CONFIG'!",ADDRESS(MATCH($D7, CONFIG!$B:$B, 0),MATCH(J$1, CONFIG!$1:$1, 0)))),".pdf#page=",J8),CONCATENATE("#Sharepoint//",$D7))} -> #Sharepoint//FS_TT2
E8: Rif. Pagina | F8: 171 | J8: 131
E9: Componenti circuito elettrico | F9: EVFS1 = Valvola applicazione parking brake JE-K009 = RIO JE-K010 = RIO GG-K016 = Relè RER | J9: GG-K016 = Relè RER GG-K028 = Relè di taglio per il comando di rilascio del PB dato da TCMS attraverso BRA_EVFS1_COM EVFS1 = Valvola applicazione parking brake JE-K009 = RIO JE-K010 = RIO
E10: Descrizione circuitale | F10: Il segnale di rilascio del praking brake verso la EVFS1 viene fornito dalle RIO BRA-EVFS1_COM. Il comando verso EVFS1 è sezionato solamente da un relè GG-K016 chiamato RER che si abilita con un contatto relativo all'inserzione della chiave di banco | J10: Il comando di GG-K028 è dato dalla catena circuitale introdotta nelle DM che serve a evitare che il TCMS possa comandare impropriamente il circuito di rilascio del freno di stazionamento chiamato anche Parking brake oppure Freno a molla FAM. Il comando verso EVFS1 è sezionato pertanto da un relè GG-K016 chiamato RER che si abilita con un contatto relativo all'inserzione della chiave di banco e dal relè GG-K028 facente capo alla catena introdotta nelle DM rispetto al circuito della flotta base. Lo stato di quest'ultimo relè è diagnosticato tramite 2 ingressi RIO ridondati chiamati BRA_EVFS1-PRO_N e BRA_EVFS1-PRO_R
D11: FRS_Brake Control | E11: Link | F11: {=HYPERLINK(CONCATENATE(Cartelle!$D$5,F$1,"/CONFIG/",MID($D11,1,FIND("_",$D11)-1),"/",INDIRECT(CONCATENATE("'CONFIG'!",ADDRESS(MATCH($D11, CONFIG!$B:$B, 0),MATCH(F$1, CONFIG!$1:$1, 0)))),".pdf#page=",F12),CONCATENATE("#Sharepoint//",$D11))} -> #Sharepoint//FRS_Brake Control | J11: {=HYPERLINK(CONCATENATE(Cartelle!$D$5,J$1,"/CONFIG/",MID($D11,1,FIND("_",$D11)-1),"/",INDIRECT(CONCATENATE("'CONFIG'!",ADDRESS(MATCH($D11, CONFIG!$B:$B, 0),MATCH(J$1, CONFIG!$1:$1, 0)))),".pdf#page=",J12),CONCATENATE("#Sharepoint//",$D11))} -> #Sharepoint//FRS_Brake Control
E12: Rif. Pagina | F12: 117 | J12: 154
E13: Requisiti specifici | F13: \ | J13: Rispetto a FRS VZI_Base, aggiunto requisiti .3980 e .TRS.343 per inibire elettricamente il TCMS in caso di comando di sblocco PB non dovuto. Tali requisiti sono stati implementati con il circuito di cui alle descrizioni circuitali di cui sopra, il quale utilizza gli ingressi di comando BRA_PARK_COM di comando e lo stato delle variabili BRA_EVFS1-PRO_N e BRA_EVFS1-PRO_R per verificare che sia stato comandato effettivamente un rilascio da pulsante e da macchinista, e che non sia stato rilasciato esclusivamente dal TCMS
D14: FPD_Brake Control | E14: Link | F14: {=HYPERLINK(CONCATENATE(Cartelle!$D$5,F$1,"/CONFIG/",MID($D14,1,FIND("_",$D14)-1),"/",INDIRECT(CONCATENATE("'CONFIG'!",ADDRESS(MATCH($D14, CONFIG!$B:$B, 0),MATCH(F$1, CONFIG!$1:$1, 0)))),".pdf#page=",F15),CONCATENATE("#Sharepoint//",$D14))} -> #Sharepoint//FPD_Brake Control | J14: {=HYPERLINK(CONCATENATE(Cartelle!$D$5,J$1,"/CONFIG/",MID($D14,1,FIND("_",$D14)-1),"/",INDIRECT(CONCATENATE("'CONFIG'!",ADDRESS(MATCH($D14, CONFIG!$B:$B, 0),MATCH(J$1, CONFIG!$1:$1, 0)))),".pdf#page=",J15),CONCATENATE("#Sharepoint//",$D14))} -> #Sharepoint//FPD_Brake Control
E15: Rif. Pagina | F15: 18 | J15: 18
A16: Hot_Axle_Box_01 | B16: Funzione di monitoraggio Hot Axle Box Detection (HABD) | C16: HW + SW | D16: =IF($A16="","",HYPERLINK(CONCATENATE(Cartelle!$D$6,$A16),CONCATENATE("#Sharepoint//",$A16))) -> #Sharepoint//Hot_Axle_Box_01
D17: FS_DM1 | E17: Link | F17: {=HYPERLINK(CONCATENATE(Cartelle!$D$5,F$1,"/CONFIG/",MID($D17,1,FIND("_",$D17)-1),"/",INDIRECT(CONCATENATE("'CONFIG'!",ADDRESS(MATCH($D17, CONFIG!$B:$B, 0),MATCH(F$1, CONFIG!$1:$1, 0)))),".pdf#page=",F18),CONCATENATE("#Sharepoint//",$D17))} -> #Sharepoint//FS_DM1 | J17: {=HYPERLINK(CONCATENATE(Cartelle!$D$5,J$1,"/CONFIG/",MID($D17,1,FIND("_",$D17)-1),"/",INDIRECT(CONCATENATE("'CONFIG'!",ADDRESS(MATCH($D17, CONFIG!$B:$B, 0),MATCH(J$1, CONFIG!$1:$1, 0)))),".pdf#page=",J18),CONCATENATE("#Sharepoint//",$D17))} -> #Sharepoint//FS_DM1
E18: Rif. Pagina | F18: 388 | J18: 264
E19: Componenti circuito elettrico | F19: GC-Q024 = Relè abilitazione cabina LCA GC-Q026 = Relè abilitazione cabina LCA SB-K018 = Relè accoppiamento JB-K003 = Relè apertura Loop HABD JB-K004 = Relè apertura Loop HABD GG-K016 = Relè apertura Loop DNRA GG-K017 = Relè apertura Loop DNRA GC-A018 H2B = spia Locked Axle | J19: JB-K003 = Relè apertura Loop HABD JB-K004 = Relè apertura Loop HABD JE-K009 = RIO OTC_FUSE_LOOP JE-K010 = RIO OTC_FUSE LOOP GC-A018 H2B = spia HABD Alarm
E20: Descrizione circuitale | F20: L'informazione di apertura loop HBDA è data dai termofusibili, essa comanda la disalimetazione dei relè JB-K003 e JB-K004, questi tramite i contatti AI-B1 passano l'informazione al TCMS, OTC_FUSE_LOOP. L'accensione della spia HABD-DNRA deriva daii contatti C1-D1 e C3-D3 di JB-K003 e JB-K004, i quali comandano il loop DNRA stesso. L'informazione di apertura è propagata dai contatti di JB-K003 e JB-K004 verso i relè GG-K016 e GG-K017 i quali comandano l'accensione della spia GC-A018. Il filo treno-loop DNRA viene alimentato alla tensione di batteria nella cabina non abilitata attraverso l’interruttore magnetotermico di protezione GG-F004 e i contatti del relè di accoppiamento Rcm SB-K018 e di abilitazione cabina LCA. GC-Q024 e Q026 | J20: L'informazione di apertura loop HABDA è data dai termofusibili, essa comanda la disalimetazione dei relè JB-K003 e JB-K004, questi tramite i contatti A1 - B1 passano l'informazione al TCMS tramite i DI RIO JE-K009 e JE-K010, OTC_FUSE_LOOP. Il TCMS a seguito comanda l'accensione della spia GC-A18 relativa al solo allarme HABD, tramite le uscite JE-K005 e JE-K006, OTC_HABD_ALARM
D21: FRS_Bogies | E21: Link | F21: {=HYPERLINK(CONCATENATE(Cartelle!$D$5,F$1,"/CONFIG/",MID($D21,1,FIND("_",$D21)-1),"/",INDIRECT(CONCATENATE("'CONFIG'!",ADDRESS(MATCH($D21, CONFIG!$B:$B, 0),MATCH(F$1, CONFIG!$1:$1, 0)))),".pdf#page=",F22),CONCATENATE("#Sharepoint//",$D21))} -> #Sharepoint//FRS_Bogies | G21: {=HYPERLINK(CONCATENATE(Cartelle!$D$5,G$1,"/CONFIG/",MID($D21,1,FIND("_",$D21)-1),"/",INDIRECT(CONCATENATE("'CONFIG'!",ADDRESS(MATCH($D21, CONFIG!$B:$B, 0),MATCH(G$1, CONFIG!$1:$1, 0)))),".pdf#page=",G22),CONCATENATE("#Sharepoint//",$D21))} -> #Sharepoint//FRS_Bogies | J21: {=HYPERLINK(CONCATENATE(Cartelle!$D$5,J$1,"/CONFIG/",MID($D21,1,FIND("_",$D21)-1),"/",INDIRECT(CONCATENATE("'CONFIG'!",ADDRESS(MATCH($D21, CONFIG!$B:$B, 0),MATCH(J$1, CONFIG!$1:$1, 0)))),".pdf#page=",J22),CONCATENATE("#Sharepoint//",$D21))} -> #Sharepoint//FRS_Bogies
E22: Rif. Pagina | F22: 14 | G22: 12 | J22: 1
E23: Requisiti specifici | F23: Europe.CONCEPT.392: in caso di bypass DNRA, limite velocità a 200 km/h Europe.CONCEPT.355: evento di warning se Temp gearbox >= 145 °C | G23: Europe.CONCEPT.392: in caso di bypass DNRA, limite velocità inibito se attivo stato "DNRA - BMS Local Monitoring" Europe.CONCEPT.355: evento di warning se Temp gearbox >= 135 °C Europe.CONCEPT.377: generazione evento di warning o allarme in base a gradiente temperatura Europe.CONCEPT.380: mantenimento in memoria degli allarmi generati dalle letture PT100 Europe.CONCEPT.381: introduzione dell'evento di reset allarme tramite softkey Europe.CONCEPT.378: in caso di allarme temp riduttore, il TCMS applica un blocco alla trazione se la di vel è > 80 km/h, che si ripristina quando la vel scende < 80 km/h con manipolatore T/F in coasting Europe.CONCEPT.383: il limite di vel si disattiva quando il PDC resetta l'allarme di temp, anche se la condizione di allarme è ancora presente Europe.CONCEPT.384: la limitazione di vel si riattiva in caso l'allarme, precedentemente resettato, si ripresenti | J23: TBD
D24: FPD_xx | E24: Link | F24: {=HYPERLINK(CONCATENATE(Cartelle!$D$5,F$1,"/CONFIG/",MID($D24,1,FIND("_",$D24)-1),"/",INDIRECT(CONCATENATE("'CONFIG'!",ADDRESS(MATCH($D24, CONFIG!$B:$B, 0),MATCH(F$1, CONFIG!$1:$1, 0)))),".pdf#page=",F25),CONCATENATE("#Sharepoint//",$D24))} -> #N/A | J24: {=HYPERLINK(CONCATENATE(Cartelle!$D$5,J$1,"/CONFIG/",MID($D24,1,FIND("_",$D24)-1),"/",INDIRECT(CONCATENATE("'CONFIG'!",ADDRESS(MATCH($D24, CONFIG!$B:$B, 0),MATCH(J$1, CONFIG!$1:$1, 0)))),".pdf#page=",J25),CONCATENATE("#Sharepoint//",$D24))} -> #N/A
E25: Rif. Pagina | F25: 1 | J25: 1
A26: Func_XXX | B26: xxxxx | C26: HW + SW | D26: \
C27: CONFIG | D27: FS_xx | E27: Link | F27: {=HYPERLINK(CONCATENATE(Cartelle!$D$5,F$1,"/CONFIG/",MID($D27,1,FIND("_",$D27)-1),"/",INDIRECT(CONCATENATE("'CONFIG'!",ADDRESS(MATCH($D27, CONFIG!$B:$B, 0),MATCH(F$1, CONFIG!$1:$1, 0)))),".pdf#page=",F28),CONCATENATE("#Sharepoint//",$D27))} -> #N/A | J27: {=HYPERLINK(CONCATENATE(Cartelle!$D$5,J$1,"/CONFIG/",MID($D27,1,FIND("_",$D27)-1),"/",INDIRECT(CONCATENATE("'CONFIG'!",ADDRESS(MATCH($D27, CONFIG!$B:$B, 0),MATCH(J$1, CONFIG!$1:$1, 0)))),".pdf#page=",J28),CONCATENATE("#Sharepoint//",$D27))} -> #N/A
C28: CONFIG | E28: Rif. Pagina | F28: 1 | J28: 1
C29: CONFIG | D29: FRS_xx | E29: Link | F29: {=HYPERLINK(CONCATENATE(Cartelle!$D$5,F$1,"/CONFIG/",MID($D29,1,FIND("_",$D29)-1),"/",INDIRECT(CONCATENATE("'CONFIG'!",ADDRESS(MATCH($D29, CONFIG!$B:$B, 0),MATCH(F$1, CONFIG!$1:$1, 0)))),".pdf#page=",F30),CONCATENATE("#Sharepoint//",$D29))} -> #N/A | J29: {=HYPERLINK(CONCATENATE(Cartelle!$D$5,J$1,"/CONFIG/",MID($D29,1,FIND("_",$D29)-1),"/",INDIRECT(CONCATENATE("'CONFIG'!",ADDRESS(MATCH($D29, CONFIG!$B:$B, 0),MATCH(J$1, CONFIG!$1:$1, 0)))),".pdf#page=",J30),CONCATENATE("#Sharepoint//",$D29))} -> #N/A
C30: CONFIG | E30: Rif. Pagina | F30: 1 | J30: 1
C31: CONFIG | D31: FPD_xx | E31: Link | F31: {=HYPERLINK(CONCATENATE(Cartelle!$D$5,F$1,"/CONFIG/",MID($D31,1,FIND("_",$D31)-1),"/",INDIRECT(CONCATENATE("'CONFIG'!",ADDRESS(MATCH($D31, CONFIG!$B:$B, 0),MATCH(F$1, CONFIG!$1:$1, 0)))),".pdf#page=",F32),CONCATENATE("#Sharepoint//",$D31))} -> #N/A | J31: {=HYPERLINK(CONCATENATE(Cartelle!$D$5,J$1,"/CONFIG/",MID($D31,1,FIND("_",$D31)-1),"/",INDIRECT(CONCATENATE("'CONFIG'!",ADDRESS(MATCH($D31, CONFIG!$B:$B, 0),MATCH(J$1, CONFIG!$1:$1, 0)))),".pdf#page=",J32),CONCATENATE("#Sharepoint//",$D31))} -> #N/A
E32: Rif. Pagina | F32: 1 | J32: 1
B33: (TBD) Destinazione cartella link sulla base del DOC Type | C33: MR_CPR | D33: PBC-01A | E33: Link | F33: {=HYPERLINK(CONCATENATE(Cartelle!$D$5,F$1,"/MAN_CPR/","/",INDIRECT(CONCATENATE("'MAN_CPR'!",ADDRESS(MATCH($D33, MAN_CPR!$E:$E, 0),MATCH(F$1, MAN_CPR!$1:$1, 0)))),".pdf#page=",F34),CONCATENATE("#Sharepoint//",$D33))} -> #Sharepoint//PBC-01A | G33: {=HYPERLINK(CONCATENATE(Cartelle!$D$5,INDEX(MAN_CPR!$1:$1, 1, MATCH(INDIRECT(CONCATENATE("'MAN_CPR'!",ADDRESS(MATCH($D33, MAN_CPR!$E:$E, 0),MATCH(G$1, MAN_CPR!$1:$1, 0)))),INDIRECT(CONCATENATE("'MAN_CPR'!",MATCH($D33, MAN_CPR!$E:$E, 0),":",MATCH($D33, MAN_CPR!$E:$E, 0))),0)),"/MAN_CPR/","/",INDIRECT(CONCATENATE("'MAN_CPR'!",ADDRESS(MATCH($D33, MAN_CPR!$E:$E, 0),MATCH(G$1, MAN_CPR!$1:$1, 0)))),".pdf#page=",G34),CONCATENATE("#Sharepoint//",$D33))} -> #Sharepoint//PBC-01A
E34: Rif. Pagina | F34: 1 | G34: 1
E35: Descrizione
C36: GENERAL | D36: AD_Regole | E36: TBD
E37: Lista Eventi
E38: Lista AWO
A39: LV_Country_code_selection | B39: Selezione su IDU del paese corrente, per informare la PCU sui pantografi selezionabili | D39: \
D40: FRS_Line Voltage | E40: Link | F40: {=HYPERLINK(CONCATENATE(Cartelle!$D$5,F$1,"/CONFIG/",MID($D40,1,FIND("_",$D40)-1),"/",INDIRECT(CONCATENATE("'CONFIG'!",ADDRESS(MATCH($D40, CONFIG!$B:$B, 0),MATCH(F$1, CONFIG!$1:$1, 0)))),".pdf#page=",F41),CONCATENATE("#Sharepoint//",$D40))} -> #Sharepoint//FRS_Line Voltage | H40: {=HYPERLINK(CONCATENATE(Cartelle!$D$5,INDEX(CONFIG!$1:$1, 1, MATCH(INDIRECT(CONCATENATE("'CONFIG'!",ADDRESS(MATCH($D40, CONFIG!$B:$B, 0),MATCH(H$1, CONFIG!$1:$1, 0)))),INDIRECT(CONCATENATE("'CONFIG'!",MATCH($D40, CONFIG!$B:$B, 0),":",MATCH($D40, CONFIG!$B:$B, 0))),0)),"/CONFIG/",MID($D40,1,FIND("_",$D40)-1),"/",INDIRECT(CONCATENATE("'CONFIG'!",ADDRESS(MATCH($D40, CONFIG!$B:$B, 0),MATCH(H$1, CONFIG!$1:$1, 0)))),".pdf#page=",H41),CONCATENATE("#Sharepoint//",$D40))} -> #Sharepoint//FRS_Line Voltage | I40: {=HYPERLINK(CONCATENATE(Cartelle!$D$5,INDEX(CONFIG!$1:$1, 1, MATCH(INDIRECT(CONCATENATE("'CONFIG'!",ADDRESS(MATCH($D40, CONFIG!$B:$B, 0),MATCH(I$1, CONFIG!$1:$1, 0)))),INDIRECT(CONCATENATE("'CONFIG'!",MATCH($D40, CONFIG!$B:$B, 0),":",MATCH($D40, CONFIG!$B:$B, 0))),0)),"/CONFIG/",MID($D40,1,FIND("_",$D40)-1),"/",INDIRECT(CONCATENATE("'CONFIG'!",ADDRESS(MATCH($D40, CONFIG!$B:$B, 0),MATCH(I$1, CONFIG!$1:$1, 0)))),".pdf#page=",I41),CONCATENATE("#Sharepoint//",$D40))} -> #Sharepoint//FRS_Line Voltage | J40: {=HYPERLINK(CONCATENATE(Cartelle!$D$5,J$1,"/CONFIG/",MID($D40,1,FIND("_",$D40)-1),"/",INDIRECT(CONCATENATE("'CONFIG'!",ADDRESS(MATCH($D40, CONFIG!$B:$B, 0),MATCH(J$1, CONFIG!$1:$1, 0)))),".pdf#page=",J41),CONCATENATE("#Sharepoint//",$D40))} -> #Sharepoint//FRS_Line Voltage
...

Sheet PBS (TBD)
A1: Impianto | B1: Gruppo/Componente | C1: P/N | D1: Applicabilità flotte | K1: Manuale | N1: CPR | Q1: Raccolta doc | S1: Schema elettrico | U1: Schema Pneumatico
D2: VZI_Base | E2: VZI_New14 | F2: VZ_FR | G2: VZ_ES | H2: VZI-6_R1 | I2: VZI-4_R1 | J2: VZ_DAI | K2: File | L2: Pag | M2: Link | N2: File | O2: Pag | P2: Link | Q2: Cartella | R2: Link | S2: Pag | T2: Link | U2: Pag | V2: Link
A3: PANTOGRAFO | D3: . | E3: . | F3: . | G3: . | H3: . | I3: . | J3: .
B4: CAPTAZIONE | D4: .. | E4: .. | F4: .. | G4: .. | H4: .. | I4: .. | J4: ..
B5: Pantografo 25 kV | C5: 10574479 | D5: T4-T5 | E5: T4-T5 | F5: X | H5: T4-T5 | K5: ETR1000V300-MR1-04A-Equip elettrico ed elettropneumatico-06 - TOMO 1.pdf | L5: 161 | M5: =HYPERLINK(CONCATENATE(Cartelle!$A$2,Cartelle!$D$2,Cartelle!#REF!,'PBS (TBD)'!K5,"#page=",'PBS (TBD)'!L5),"#") -> #REF! | N5: ETR1000-CPR_04C_2.05.1002_Pantografo_Mar21.pdf | O5: 93 | P5: =HYPERLINK(CONCATENATE(Cartelle!$A$2,Cartelle!#REF!,Cartelle!#REF!,'PBS (TBD)'!N5,"#page=",'PBS (TBD)'!O5),"#") -> #REF!
B6: Pantografo 3 kV | C6: 10542152 | D6: TT2-TT7 | E6: TT2-TT7 | F6: X | H6: TT2-TT7 | K6: ETR1000V300-MR1-04A-Equip elettrico ed elettropneumatico-06 - TOMO 1.pdf | L6: 180 | M6: =HYPERLINK(CONCATENATE(Cartelle!$A$2,Cartelle!$D$2,Cartelle!#REF!,'PBS (TBD)'!K6,"#page=",'PBS (TBD)'!L6),"#") -> #REF! | N6: ETR1000-CPR_04C_2.05.1002_Pantografo_Mar21.pdf | O6: 33 | P6: =HYPERLINK(CONCATENATE(Cartelle!$A$2,Cartelle!#REF!,Cartelle!#REF!,'PBS (TBD)'!N6,"#page=",'PBS (TBD)'!O6),"#") -> #REF!
B7: Pantografo 1,5 kV
B8: CONTROLLO | D8: .. | E8: .. | F8: .. | G8: .. | H8: .. | I8: .. | J8: ..
B9: PPU | C9: 0102895 | D9: TT2-T4-T5-TT7
B10: PPU | C10: 232C10395F | E10: TT2-T4-T5-TT7 | Q10: 232C10395F | R10: =HYPERLINK(CONCATENATE(Cartelle!$A$2,Cartelle!#REF!,'PBS (TBD)'!Q10),"#") -> #REF!
B11: PPU | C11: 231C100036B | H11: TT2-T4-T5-TT7
A12: TCMS | D12: . | E12: . | F12: . | G12: . | H12: . | I12: . | J12: .
B13: CONTROLLO | D13: .. | E13: .. | F13: .. | G13: .. | H13: .. | I13: .. | J13: ..
B14: CCU-O Dual MVB (DCY1110B) | C14: 3EST000225-5707 | D14: DM1-DM8 | E14: DM1-DM8 | K14: ETR1000V300-MR1-05A-Logica di comando-03.pdf | L14: 113 | M14: =HYPERLINK(CONCATENATE(Cartelle!$A$2,Cartelle!$D$2,Cartelle!#REF!,'PBS (TBD)'!K14,"#page=",'PBS (TBD)'!L14),"#") -> #REF! | N14: ETR1000-CPR_05_2.05.1004_Logica di comando_Aprile2021.pdf | O14: 48 | P14: =HYPERLINK(CONCATENATE(Cartelle!$A$2,Cartelle!#REF!,Cartelle!#REF!,'PBS (TBD)'!N14,"#page=",'PBS (TBD)'!O14),"#") -> #REF!
B15: CCU-C 2ETH (DCY1550A) | C15: 3EST000225-5711 | D15: DM1-M3-DM8 | E15: DM1-M3-DM8 | K15: ETR1000V300-MR1-05A-Logica di comando-03.pdf | L15: 121 | M15: =HYPERLINK(CONCATENATE(Cartelle!$A$2,Cartelle!$D$2,Cartelle!#REF!,'PBS (TBD)'!K15,"#page=",'PBS (TBD)'!L15),"#") -> #REF! | N15: ETR1000-CPR_05_2.05.1004_Logica di comando_Aprile2021.pdf | O15: 52 | P15: =HYPERLINK(CONCATENATE(Cartelle!$A$2,Cartelle!#REF!,Cartelle!#REF!,'PBS (TBD)'!N15,"#page=",'PBS (TBD)'!O15),"#") -> #REF!
B16: CCU-S (DCY 1660A) | C16: 3EST000221-6430 | D16: DM1-DM8 | E16: DM1-DM8 | K16: ETR1000V300-MR1-05A-Logica di comando-03.pdf | L16: 124 | M16: =HYPERLINK(CONCATENATE(Cartelle!$A$2,Cartelle!$D$2,Cartelle!#REF!,'PBS (TBD)'!K16,"#page=",'PBS (TBD)'!L16),"#") -> #REF! | N16: ETR1000-CPR_05_2.05.1004_Logica di comando_Aprile2021.pdf | O16: 44 | P16: =HYPERLINK(CONCATENATE(Cartelle!$A$2,Cartelle!#REF!,Cartelle!#REF!,'PBS (TBD)'!N16,"#page=",'PBS (TBD)'!O16),"#") -> #REF!
B17: MIO-DXH4-S (DCS 2222B) | C17: 3EST000228-0629 | D17: DM1-DM8 | K17: ETR1000V300-MR1-05A-Logica di comando-03.pdf | L17: 175 | M17: =HYPERLINK(CONCATENATE(Cartelle!$A$2,Cartelle!$D$2,Cartelle!#REF!,'PBS (TBD)'!K17,"#page=",'PBS (TBD)'!L17),"#") -> #REF! | N17: ETR1000-CPR_05_2.05.1004_Logica di comando_Aprile2021.pdf | O17: 70 | P17: =HYPERLINK(CONCATENATE(Cartelle!$A$2,Cartelle!#REF!,Cartelle!#REF!,'PBS (TBD)'!N17,"#page=",'PBS (TBD)'!O17),"#") -> #REF!
B18: MIO-S (DCS 2222C) | C18: 3EST000230-5830 | E18: DM1-DM8 | N18: ETR1000-CPR_05_2.05.1004_Logica di comando_Aprile2021.pdf | O18: 28 | P18: =HYPERLINK(CONCATENATE(Cartelle!$A$2,Cartelle!#REF!,Cartelle!#REF!,'PBS (TBD)'!N18,"#page=",'PBS (TBD)'!O18),"#") -> #REF!
B19: MIO-S-AI1+DXH3 (DCS 7222B) | C19: 3EST000228-3395 | D19: DM1-DM8 | K19: ETR1000V300-MR1-05A-Logica di comando-03.pdf | L19: 175 | M19: =HYPERLINK(CONCATENATE(Cartelle!$A$2,Cartelle!$D$2,Cartelle!#REF!,'PBS (TBD)'!K19,"#page=",'PBS (TBD)'!L19),"#") -> #REF! | N19: ETR1000-CPR_05_2.05.1004_Logica di comando_Aprile2021.pdf | O19: 74 | P19: =HYPERLINK(CONCATENATE(Cartelle!$A$2,Cartelle!#REF!,Cartelle!#REF!,'PBS (TBD)'!N19,"#page=",'PBS (TBD)'!O19),"#") -> #REF!
B20: MIO-S (DCS 7222B) | C20: 3EST000230-5833 | E20: DM1-DM8 | N20: ETR1000-CPR_05_2.05.1004_Logica di comando_Aprile2021.pdf | O20: 84 | P20: =HYPERLINK(CONCATENATE(Cartelle!$A$2,Cartelle!#REF!,Cartelle!#REF!,'PBS (TBD)'!N20,"#page=",'PBS (TBD)'!O20),"#") -> #REF!
B21: MIO-S-AI1+DXH2 (DCS 7220B) | C21: 3EST000228-3394 | D21: Tutte | E21: Tutte | K21: ETR1000V300-MR1-05A-Logica di comando-03.pdf | L21: 175 | M21: =HYPERLINK(CONCATENATE(Cartelle!$A$2,Cartelle!$D$2,Cartelle!#REF!,'PBS (TBD)'!K21,"#page=",'PBS (TBD)'!L21),"#") -> #REF! | N21: ETR1000-CPR_05_2.05.1004_Logica di comando_Aprile2021.pdf | O21: 76 | P21: =HYPERLINK(CONCATENATE(Cartelle!$A$2,Cartelle!#REF!,Cartelle!#REF!,'PBS (TBD)'!N21,"#page=",'PBS (TBD)'!O21),"#") -> #REF!
B22: MIO-DXH4 (DCX 2222A) | C22: 3EST000209-5696 | D22: Tutte | E22: Tutte | K22: ETR1000V300-MR1-05A-Logica di comando-03.pdf | L22: 150 | M22: =HYPERLINK(CONCATENATE(Cartelle!$A$2,Cartelle!$D$2,Cartelle!#REF!,'PBS (TBD)'!K22,"#page=",'PBS (TBD)'!L22),"#") -> #REF! | N22: ETR1000-CPR_05_2.05.1004_Logica di comando_Aprile2021.pdf | O22: 62 | P22: =HYPERLINK(CONCATENATE(Cartelle!$A$2,Cartelle!#REF!,Cartelle!#REF!,'PBS (TBD)'!N22,"#page=",'PBS (TBD)'!O22),"#") -> #REF!
B23: MIO-DX1H (DCX 2000A) | C23: 3EST000209-5690 | D23: M3 | E23: M3 | K23: ETR1000V300-MR1-05A-Logica di comando-03.pdf | L23: 151 | M23: =HYPERLINK(CONCATENATE(Cartelle!$A$2,Cartelle!$D$2,Cartelle!#REF!,'PBS (TBD)'!K23,"#page=",'PBS (TBD)'!L23),"#") -> #REF! | N23: ETR1000-CPR_05_2.05.1004_Logica di comando_Aprile2021.pdf | O23: 82 | P23: =HYPERLINK(CONCATENATE(Cartelle!$A$2,Cartelle!#REF!,Cartelle!#REF!,'PBS (TBD)'!N23,"#page=",'PBS (TBD)'!O23),"#") -> #REF!
B24: MIO-DX3H (DCX 2220A) | C24: 3EST000209-5694 | D24: Tutte | E24: Tutte | K24: ETR1000V300-MR1-05A-Logica di comando-03.pdf | L24: 151 | M24: =HYPERLINK(CONCATENATE(Cartelle!$A$2,Cartelle!$D$2,Cartelle!#REF!,'PBS (TBD)'!K24,"#page=",'PBS (TBD)'!L24),"#") -> #REF! | N24: ETR1000-CPR_05_2.05.1004_Logica di comando_Aprile2021.pdf | O24: 66 | P24: =HYPERLINK(CONCATENATE(Cartelle!$A$2,Cartelle!#REF!,Cartelle!#REF!,'PBS (TBD)'!N24,"#page=",'PBS (TBD)'!O24),"#") -> #REF!
B25: CDU-H03 | C25: HW01107958-00 | H25: DM1-DM8 | I25: DM1-DM8 | K25: ETR1000-V300ZEFIRO-R1_MR1-05A_R03.pdf | L25: 94 | M25: =HYPERLINK(CONCATENATE(Cartelle!$A$2,Cartelle!$D$2,Cartelle!#REF!,'PBS (TBD)'!K25,"#page=",'PBS (TBD)'!L25),"#") -> #REF!
B26: DU-H03 | C26: HW02298449-00 | H26: DM1-DM8 | I26: DM1-DM8
B27: DU-H04 (OBS) | C27: HW02298458-00 | H27: M3 | I27: M3
B28: DU-H05 (PIS-ALG) | C28: HW02298473-00 | H28: M3 | I28: M3
B29: RIO-LP (CUSFE684-H05) | C29: HW01107911-00 | H29: DM1-DM8 | I29: DM1-DM8
B30: RIO-C5/C6 (CUSFE684-H06) | C30: HW01107914-00 | H30: DM1-DM8 | I30: DM1-DM8
B31: RIO-EB-01 (CUSFE684-H01) | C31: HW01107901-00 | H31: DM1-DM8 | I31: DM1-DM8 | N31: ETR1000-V300ZEFIRO-R1_CPR-05A_2.05.1408_R02.pdf | O31: 40 | P31: =HYPERLINK(CONCATENATE(Cartelle!$A$2,Cartelle!#REF!,Cartelle!#REF!,'PBS (TBD)'!N31,"#page=",'PBS (TBD)'!O31),"#") -> #REF!
B32: RIO-EB-02 (CUSFE684-H02) | C32: HW01107904-00 | H32: TT2-TT7 | I32: TT2-TT7
B33: RIO-EB-03 (CUSFE684-H03) | C33: HW01107905-00 | H33: M3-M6 | I33: M3-M6
B34: RIO-EB-04 (CUSFE684-H04) | C34: HW01107908-00 | H34: T4-T5 | I34: T4-T5
B35: RIO-C2-01 (CURSE32-H01) | C35: HW01107953-00 | H35: DM1-TT2-M3-M6-TT7-DM8 | I35: DM1-TT2-M3-M6-TT7-DM8
B36: RIO-C2-02 (CURSE32-H02) | C36: HW01107954-00 | H36: T4-T5 | I36: T4-T5
B37: DIAGNOSTICA | D37: .. | E37: .. | F37: .. | G37: .. | H37: .. | I37: .. | J37: ..
B38: MCG (DCZ 2424B) | C38: 3EST000225-7169 | D38: X | K38: ETR1000V300-MR1-05A-Logica di comando-03.pdf | L38: 152 | M38: =HYPERLINK(CONCATENATE(Cartelle!$A$2,Cartelle!$D$2,Cartelle!#REF!,'PBS (TBD)'!K38,"#page=",'PBS (TBD)'!L38),"#") -> #REF! | N38: ETR1000-CPR_05_2.05.1004_Logica di comando_Aprile2021.pdf | O38: 84 | P38: =HYPERLINK(CONCATENATE(Cartelle!$A$2,Cartelle!#REF!,Cartelle!#REF!,'PBS (TBD)'!N38,"#page=",'PBS (TBD)'!O38),"#") -> #REF!
B39: MCG | C39: 3EST000234-1560 | E39: X | N39: ETR1000-CPR_05_2.05.1004_Logica di comando_Aprile2021.pdf | O39: 32 | P39: =HYPERLINK(CONCATENATE(Cartelle!$A$2,Cartelle!#REF!,Cartelle!#REF!,'PBS (TBD)'!N39,"#page=",'PBS (TBD)'!O39),"#") -> #REF!
B40: IDU | C40: 3EST000223-8802 | D40: DM1-M3-DM8 | E40: DM1-M3-DM8 | N40: ETR1000-CPR_05_2.05.1004_Logica di comando_Aprile2021.pdf | O40: 32 | P40: =HYPERLINK(CONCATENATE(Cartelle!$A$2,Cartelle!#REF!,Cartelle!#REF!,'PBS (TBD)'!N40,"#page=",'PBS (TBD)'!O40),"#") -> #REF!
...

Sheet Struttura
C1: IT 50 treni (flotta base) | G1: IT 8 treni (51-58) | K1: IT 6+30 treni (101-136) | O1: I-FR 9 treni | S1: DAI 9 treni | W1: ES 20 treni
A2: Sottosistema | C2: P/N | D2: Id | E2: P/N | F2: Descrizione | G2: P/N | H2: Id | I2: P/N | J2: Descrizione | K2: P/N | L2: Id | M2: P/N | N2: Descrizione | O2: P/N | P2: Id | Q2: P/N | R2: Descrizione | S2: P/N | T2: Id | U2: P/N | V2: Descrizione | W2: P/N | X2: Id | Y2: P/N | Z2: Descrizione
A3: Carrelli | B3: Motori | C3: 100360301 100360302 100360303 100360304 | D3: Sala Montata | E3: 100360402 100360403 | F3: Sensoristica ERTMS-SCMT carrelli DM Sala senza boccole: 100360064 | G3: 100360301 100360302 100360303 100360304 | H3: Sala Montata | I3: 100360402 100360403 | J3: Sensoristica ERTMS-SCMT carrelli DM Sala senza boccole: 100360064 | K3: 100360301 100360302 100360303 100360304 (EN45545) | L3: Sala Montata | M3: 100360402 100360403 | N3: Sensoristica ERTMS-SCMT carrelli DM | O3: 100329688 100329689 100360303 100360304 | P3: Sala Montata | R3: Sensoristica ERTMS-SCMT, Memor brush, ETCS antenna su carrelli ant. DM1/8 Sensori Wiegand su post. DM1/8 Sensori Wiegand su ant. TT2/7 Sala senza boccole: 100360064 | T3: Sala Montata | V3: tbd sensori boccola DM | W3: DM: 100437987 100470644 | X3: Sala Montata | Z3: Sensoristica ETCS-ASFA-LZB carrelli DM
D4: Riduttore | E4: 13900244911 | H4: Riduttore | I4: 13900244911 | L4: Riduttore | M4: 13900244911 | P4: Riduttore | Q4: 13900244911 | T4: Riduttore | U4: 13900244911 | X4: Riduttore
D5: Motore | E5: 3EST000224-9555 | H5: Motore | I5: 3EST000224-9555 | L5: Motore | M5: 3EST000224-9555 | P5: Motore | Q5: 3EST000224-9555 | T5: Motore | U5: 3EST000224-9555 | X5: Motore
