Workbook

Sheet Issue
A1: Rev | B1: Data | C1: Descrizione
A2: 1.0 | B2: 46190 | C2: Presentazione bozza

Sheet ToDo
A1: Data | B1: Chi | C1: Priorità | D1: Descrizione | E1: Note
A2: 46190 | B2: Federico | C2: Alta | D2: protezione azionamenti | E2: da ricercare all'interno dei documenti, una volta collezionati tutti i doc disponibili sulla trazione
A3: 46190 | B3: Federico | C3: Alta | D3: ricerca doc propulsion | E3: in corso sui vari SGF
A4: 46190 | B4: Maurizio | C4: Alta | D4: legare manuali e CPR a documenti CONF | E4: eseguito manualmente, TBD legame automatico (vedi pt sotto)
A5: 46190 | B5: Federico | C5: Alta | D5: provare integrazione copilot | E5: Eseguita prova su FRS_Line_Voltage con compilazione automatica colonna B di Funzioni. Riutilizzabile per prossime FUNC ID
A6: 46189 | B6: Maurizio | C6: Bassa | D6: Definire struttura codice FUNC ID | E6: Valutare se necessario
A7: 46189 | B7: Maurizio | C7: Media | D7: Diagnostica: - Reperire documentazione diagnostica EVENTI + AWO per flotta - Definire modalità archiviazione file diagnostici per flotta e referenziazione in FUNZIONI | E7: Alcuni doc già recuperati, da definire criterio di archiviazione
A8: 46189 | B8: Maurizio | C8: Bassa | D8: Rivedere/Completare PBS | E8: TBD
A9: 46189 | B9: Maurizio | C9: Bassa | D9: Legare FUNZIONI a PBS ??? | E9: TBD
A10: 46189 | B10: Maurizio | C10: Bassa | D10: Pensare a come gestire in Funzioni, l'aggiornamento dei documenti richiamati. ES aggiungere campo data??? | E10: TBD
A11: 46196 | B11: Maurizio | C11: Alta | D11: Valutare se inserire colonna File Type in Conf Sheet per poter referenziare anche documenti diversi da pdf (es. file excel degli annex ICD) In tal caso modificare la costruzione del link in Funzioni | E11: la diversa tipologia di doc a disposizione potrebbe generare problemi nel referenziare i doc tramite link. Agganciare i link ad una colonna che indica il tipo di documento bypassa il problema del formato
A12: 46196 | B12: Maurizio | C12: Alta | D12: Inserire in Funzioni una colonna Doc Type che specifica la tipologia di documenti da linkare (es. CONFIG, MR_CPR, GENERAL, DIAGNOSTIC…) al quale è associato il foglio excel per la ricerca del documento (automatica nella formula del link) e la cartella di archiviazione per la costruzione del link (automatica) | E12: Dato che la costruzione del file DB e delle cartelle su Sharepoint (criterio di archiviazione) può essere ancora modificabile sulla base della tipologia di documenti che sarà necessario tracciare/archiviare, potrebbe essere utili introdurre un Doc Type che venga utilizzato sia per tracciare i doc su un foglio del DB dedicato sia per creare dinamicamente il link su cartelle ad oggi ancora "flessibili"
A13: 46197 | B13: Federico | C13: Media | D13: Pensare a come esportare il file in formato di HTML per poter essere navigabile via broswer | E13: Potrebbe essere utile in caso sia necessario reperire informazioni quando siamo a bordo treno anche da Telefono

Sheet Cartelle
A1: DESCRIZIONE | B1: NOME | C1: Livello | D1: INDIRIZZO | E1: LINK
A2: Root Sharepoint | B2: Sharepoint | C2: 0 | D2: https://gruppofsitaliane.sharepoint.com/:f:/r/sites/IngegneriaETReMezziLeggeri-Trenitalia/ | E2: =HYPERLINK(D2,"🔗") -> 🔗
A3: Cartella Documenti Ingegneria | B3: Shared%20Documents/ | C3: 1 | D3: =CONCATENATE($D$2,B3) -> https://gruppofsitaliane.sharepoint.com/:f:/r/sites/IngegneriaETReMezziLeggeri-Trenitalia/Shared%20Documents/ | E3: =HYPERLINK(D3,"🔗") -> 🔗
A4: Cartella Archiviazione doc ETR1000 | B4: DB_ETR1000/ | C4: 2 | D4: =CONCATENATE($D$3,B4) -> https://gruppofsitaliane.sharepoint.com/:f:/r/sites/IngegneriaETReMezziLeggeri-Trenitalia/Shared%20Documents/DB_ETR1000/ | E4: =HYPERLINK(D4,"🔗") -> 🔗
A5: Documenti di configurazione | B5: DOC_FLOTTE/ | C5: 3 | D5: =CONCATENATE($D$4,B5) -> https://gruppofsitaliane.sharepoint.com/:f:/r/sites/IngegneriaETReMezziLeggeri-Trenitalia/Shared%20Documents/DB_ETR1000/DOC_FLOTTE/ | E5: =HYPERLINK(D5,"🔗") -> 🔗
A6: Raccolta documentazione Funzioni | B6: DOC_FUNC/ | C6: 3 | D6: =CONCATENATE($D$4,B6) -> https://gruppofsitaliane.sharepoint.com/:f:/r/sites/IngegneriaETReMezziLeggeri-Trenitalia/Shared%20Documents/DB_ETR1000/DOC_FUNC/ | E6: =HYPERLINK(D6,"🔗") -> 🔗
A10: VINCOLI
A11: Id Flotta | B11: Riga 1
A12: DOC ID | B12: Colonna B
A13: DOC EXT | B13: Colonna C

Sheet Flotte
A1: Nome flotta | B1: ID flotta | C1: ID flotta "nativa" | D1: Ultima BL rilasciata | E1: Conf Sheet aggiornata a BL | F1: TOT Treni | G1: NUMERI TRENO
A2: VZI-50_IT Flotta base | B2: VZI_Base | C2: VZI_Base | D2: 6.3 ? | E2: 6.0 27/09/24 | F2: =COUNTIF(G2:BW2,"<>") -> 44 | G2: 1 | H2: 2 | I2: 3 | J2: 4 | K2: 5 | L2: 6 | M2: 7 | N2: 8 | O2: 9 | P2: 10 | Q2: 11 | R2: 12 | S2: 13 | T2: 14 | V2: 16 | W2: 17 | X2: 18 | Y2: 19 | AA2: 21 | AB2: 22 | AD2: 24 | AF2: 26 | AG2: 27 | AI2: 29 | AJ2: 30 | AL2: 32 | AM2: 33 | AN2: 34 | AP2: 36 | AQ2: 37 | AR2: 38 | AS2: 39 | AT2: 40 | AU2: 41 | AV2: 42 | AW2: 43 | AY2: 45 | AZ2: 46 | BB2: 48 | BE2: 46 | BF2: 47 | BG2: 48 | BH2: 49 | BI2: 50
A3: VZI-51-58_IT (New 14) | B3: VZI_New14 | C3: VZI_Base | D3: 4.3_14 17/12/2025 | E3: 4.2_14 30/01/2025 | F3: =COUNTIF(G3:BW3,"<>") -> 8 | BJ3: 51 | BK3: 52 | BL3: 53 | BM3: 54 | BN3: 55 | BO3: 56 | BP3: 57 | BQ3: 58
A4: VZ_IF Francia | B4: VZ_IF | C4: VZI_Base | D4: 4.3_IF 04/04/2025 | E4: 4.0_F 10/04/2024 | F4: =COUNTIF(G4:BW4,"<>") -> 8 | U4: 15 | AC4: 23 | AE4: 25 | AH4: 28 | AK4: 31 | BA4: 47 | BC4: 49 | BD4: 50
A5: VZ_ES Spagna | B5: VZ_ES | C5: VZI_New14 | D5: 2.8 16/04/2025 | E5: 2.4 09/03/2023 | F5: =COUNTIF(G5:BW5,"<>") -> 20 | G5: 1 | H5: 2 | I5: 3 | J5: 4 | K5: 5 | L5: 6 | M5: 7 | N5: 8 | O5: 9 | P5: 10 | Q5: 11 | R5: 12 | S5: 13 | T5: 14 | U5: 15 | V5: 16 | W5: 17 | X5: 18 | Y5: 19 | Z5: 20
A6: VZI-6_IT Full HRI (New 14) | B6: VZI-6_R1 | C6: VZI-6_R1 | D6: 5.0 15/04/2026 | E6: 4.0 ? xx/07/2025 | F6: =COUNTIF(G6:BW6,"<>") -> 6 | G6: 101 | H6: 102 | I6: 103 | J6: 104 | K6: 105 | L6: 106
A7: VZI-4_IT Full HRI | B7: VZI-4_R1 | C7: VZI-6_R1 | D7: 1.0 15/04/2026 | E7: ? | F7: =COUNTIF(G7:BW7,"<>") -> 40 | M7: 107 | N7: 108 | O7: 109 | P7: 110 | Q7: 111 | R7: 112 | S7: 113 | T7: 114 | U7: 115 | V7: 116 | W7: 117 | X7: 118 | Y7: 119 | Z7: 120 | AA7: 121 | AB7: 122 | AC7: 123 | AD7: 124 | AE7: 125 | AF7: 126 | AG7: 127 | AH7: 128 | AI7: 129 | AJ7: 130 | AK7: 131 | AL7: 132 | AM7: 133 | AN7: 134 | AO7: 135 | AP7: 136 | AQ7: 137 | AR7: 138 | AS7: 139 | AT7: 140 | AU7: 141 | AV7: 142 | AW7: 143 | AX7: 144 | AY7: 145 | AZ7: 146
A8: VZ_ES Spagna Full HRI | B8: VZ_ESxx | C8: VZI-6_R1 | F8: =COUNTIF(G8:BW8,"<>") -> 3 | AA8: 21 | AB8: 22 | AC8: 23
A9: VZ_DAI | B9: VZ_DAI | C9: VZI-6_R1 | F9: =COUNTIF(G9:BW9,"<>") -> 3 | Z9: 20 | AO9: 35 | AX9: 44

Sheet CONFIG
A1: DOC DESCRIPTION | B1: DOC ID | C1: DOC EXT | D1: VZI_Base | G1: VZI_New14 | J1: VZ_FR | M1: VZ_ES | P1: VZI-6_R1 | R1: VZI-4_R1 | T1: VZ_DAI | V1: VZ_Esxx
D2: Doc BD130033980 - BL 6.0 | G2: BD140036813 - BL 4.2 | J2: 3ECP414415-0001 - BL 4.0 | M2: VZ-ES Spagna BL 2.4 | P2: VZI-6_IT [R1] BL 4.0 | R2: VZI-4_IT [R1] BL 1.0 | T2: VZ-DAI BL xxx | V2: VZ_ES Full HRI BL xxx
D3: File/Codice | E3: Rev | F3: Codice Config | G3: File/Codice | H3: Rev | I3: Codice Config | J3: File/Codice | K3: Rev | L3: Codice Config | M3: File/Codice | N3: Rev | O3: Codice Config | P3: Codice | Q3: Rev | R3: Codice | S3: Rev | T3: Codice | U3: Rev | V3: Codice | W3: Rev
A4: SW Configuration
A5: SW Config. Matrix | B5: SW_Config | C5: pdf | D5: BD130033981 | E5: _ | G5: 3ECP414196-0001 | H5: _ | J5: 3ECP414332-0001 | K5: _ | M5: 3ECP414502-0001 | N5: \ | P5: FT080031387 | Q5: 4.3 | R5: FT080031387 | S5: 4.3
A6: Functional principle diagrams (VISIO)
A7: Drive Control | B7: FPD_Drive Control | C7: pdf | D7: 3ECP410467-0001 | E7: B | G7: 3ECP400500-0005 | H7: _ | J7: 3ECP410467-0001 | K7: B | M7: 3ECP413651-0005 | N7: _ | P7: FA010024090 | Q7: 00.2 | R7: FA010024090 | S7: 00.2
A8: Conventional Train Control | B8: FPD_Conventional Train Control | C8: pdf | D8: 3ECP410476-0001 | E8: C | G8: 3ECP400500-0014 | H8: A | J8: 3ECP307072-0001 | K8: C | M8: 3ECP413651-0014 | N8: A | P8: FA010024089 | Q8: 03.2 | R8: FA010024089 | S8: 03.2
A9: Train Protection - ATP | B9: FPD_Train Protection - ATP | C9: pdf | D9: 3ECP410482-0001 | E9: C | G9: 3ECP400500-0020 | H9: A | J9: 3ECP410482-0001 | K9: C | M9: 3ECP413651-0020 | N9: D | P9: FA010024100 | Q9: 03.2 | R9: FA010024100 | S9: 03.2
A10: TCMS Architecture | B10: FPD_TCMS Architecture | C10: pdf | D10: \ | E10: \ | G10: \ | H10: \ | J10: 3ECP307076-0001 | K10: _ | M10: 3ECP307255-0001 | N10: D | P10: FA010024104 | Q10: 00.2 | R10: FA010024104 | S10: 00.2
A11: Propulsion and Auxiliary | B11: FPD_Propulsion and Auxiliary | C11: pdf | D11: \ | E11: \ | G11: \ | H11: \ | M11: \ | N11: \ | P11: FA010024103 | Q11: 01.2 | R11: FA010024103 | S11: 01.2
A12: Line Voltage | B12: FPD_Line Voltage | C12: pdf | D12: 3ECP410475-0001 | E12: B | G12: 3ECP400500-0013 | H12: C | J12: 3ECP307079-0001 | K12: A | M12: 3ECP413651-0013 | N12: _ | P12: FA010024096 | Q12: 03.2 | R12: FA010024096 | S12: 03.2
A13: Auxiliary Electrical Supply | B13: FPD_Auxiliary Electrical Supply | C13: pdf | D13: 3ECP410465-0001 | E13: B | G13: 3ECP400500-0003 | H13: C | J13: 3ECP410465-0001 | K13: B | M13: 3ECP413651-0003 | N13: A | P13: FA010024083 | Q13: 01.2 | R13: FA010024083 | S13: 01.2
A14: Battery | B14: FPD_Battery | C14: pdf | D14: 3ECP410477-0001 | E14: B | G14: 3ECP400500-0015 | H14: _ | J14: 3ECP410477-0001 | K14: B | M14: 3ECP413651-0015 | N14: _ | P14: FA010024084 | Q14: 01.2 | R14: FA010024084 | S14: 01.2
A15: Air Supply | B15: FPD_Air Supply | C15: pdf | D15: 3ECP410463-0001 | E15: B | G15: 3ECP400500-0002 | H15: A | J15: 3ECP410463-0001 | K15: B | M15: 3ECP413651-0002 | N15: A | P15: FA010024081 | Q15: 01.2 | R15: FA010024081 | S15: 01.2
A16: Brake Control | B16: FPD_Brake Control | C16: pdf | D16: 3ECP410480-0001 | E16: C | G16: 3ECP400500-0018 | H16: B | J16: 3ECP307074-0001 | K16: E | M16: 3ECP413651-0018 | N16: A | P16: FA010024086 | Q16: 02.2 | R16: FA010024086 | S16: 02.2
A17: Bogie | B17: FPD_Bogie | C17: pdf | D17: 3ECP410466-0001 | E17: D | G17: 3ECP400500-0004 | H17: B | J17: 3ECP307081-0001 | K17: B | M17: 3ECP413651-0004 | N17: _ | P17: FA010024085 | Q17: 01.2 | R17: FA010024085 | S17: 01.2
A18: Wash Wiper | B18: FPD_Wash Wiper | C18: pdf | D18: 3ECP410473-0001 | E18: B | G18: 3ECP400500-0011 | H18: _ | J18: 3ECP307082-0001 | K18: _ | M18: 3ECP413651-0011 | N18: _ | P18: FA010024101 | Q18: 00.2 | R18: FA010024101 | S18: 00.2
A19: Windscreen heater | B19: FPD_Windscreen heater | C19: pdf | D19: 3ECP410474-0001 | E19: B | G19: 3ECP400500-0012 | H19: _ | J19: 3ECP410474-0001 | K19: B | M19: 3ECP413651-0012 | N19: _ | P19: FA010024102 | Q19: 00.2 | R19: FA010024102 | S19: 00.2
A20: Automatic Coupler | B20: FPD_Automatic Coupler | C20: pdf | D20: 3ECP410481-0001 | E20: C | G20: 3ECP400500-0019 | H20: A | J20: 3ECP307077-0001 | K20: B | M20: 3ECP413651-0019 | N20: A | P20: FA010024082 | Q20: 02.2 | R20: FA010024082 | S20: 02.2
A21: Horn | B21: FPD_Horn | C21: pdf | D21: 3ECP410468-0001 | E21: B | G21: 3ECP400500-0006 | H21: _ | J21: 3ECP410468-0001 | K21: B | M21: 3ECP413651-0006 | N21: _ | P21: FA010024094 | Q21: 00.2 | R21: FA010024094 | S21: 00.2
A22: Exterior and Interior Doors | B22: FPD_Exterior and Interior Doors | C22: pdf | D22: 3ECP410462-0001 | E22: C | G22: 3ECP400500-0001 | H22: A | J22: 3ECP307073-0001 | K22: D | M22: 3ECP413651-0001 | N22: A | P22: FA010024091 | Q22: 02.2 | R22: FA010024091 | S22: 02.2
A23: Cab HVAC | B23: FPD_Cab HVAC | C23: pdf | D23: 3ECP410470-0001 | E23: B | G23: 3ECP400500-0008 | H23: A | J23: 3ECP307084-0001 | K23: _ | M23: 3ECP413651-0008 | N23: A | P23: FA010024087 | Q23: 00.2 | R23: FA010024087 | S23: 00.2
... A30: Interior Lighting | B30: FPD_Interior Lighting | C30: pdf | D30: 3ECP410478-0001 | E30: B | G30: 3ECP400500-0016 | H30: _ | J30: 3ECP410478-0001 | K30: B | M30: 3ECP413651-0016 | N30: A | P30: FA010024095 | Q30: 01.2 | R30: FA010024095 | S30: 01.2
A31: Train Control Design System | B31: FPD_Train Control | C31: pdf | D31: \ | E31: \ | J31: 3ECP307076-0001 | K31: A | L31: manca
A32: Schematic diagram for French ATP MU | B32: FPD_ATP-MU | C32: pdf | J32: 90000056.D04 | K32: 5.0 | L32: manca
A33: Energy Meter System | B33: FPD_EMS | C33: pdf | J33: FA010031914 | K33: 00.1
A34: Functional Requirement Specification (FRS)
A35: Functional Vehicle Requirement Specification | B35: FRS_Vehicle | C35: pdf | D35: 3EST000224-9984 | E35: C | F35: 3EST000224-9984 | M35: 3ECP413839-0001 | N35: B | O35: 3ECP413839-0001 | P35: \ | Q35: \ | S35: \
A36: Drive Control | B36: FRS_Drive Control | C36: pdf | D36: 3EST000225-7909 | E36: A | F36: 3EST000225-7909 | G36: 3EST000225-7909 | H36: A | J36: 3ECP413571-0501 | K36: _ | M36: 3EST000225-7909 | N36: A | O36: 3EST000225-7909 | P36: FA020022675 | Q36: 03.2 4.0? | R36: FA020022675 | S36: 03.2 4.0?
A37: Conventional Train Control | B37: FRS_Conventional Train Control | C37: pdf | D37: 3EST000225-7916 | E37: A | F37: 3EST000225-7916 | G37: 3ECP413719-0903 | H37: _ | I37: manca | J37: FA02P021958B | K37: 2.0 | L37: 3ECP413719-0903 | M37: 3ECP413922-0903 | N37: _ | O37: 3ECP413922-0903 | P37: FA020023107 | Q37: 06.3 | R37: FA020023107 | S37: 06.3
A38: Train Protection - ATP | B38: FRS_Train Protection - ATP | C38: pdf | D38: FA020013231 | E38: 01 | F38: 3EST000225-7889 EC01P008999B | G38: FA020013231 | H38: 01 | I38: 3ECP414246-0902 | J38: FA020013231 | K38: 01 | L38: 3EST000225-7889 EC01P008999B | M38: FA020007630 | N38: 04 | O38: 3ECP413922-0902 | P38: FA020025863 | Q38: 01.3 | R38: FA020025863 | S38: 01.3
A39: Diagnostics | B39: FRS_Diagnostics | C39: pdf | D39: 3EST000225-7918 | E39: B | F39: 3EST000225-7918 | G39: 3EST000225-7918 | H39: B | I39: 3EST000225-7918 | J39: 3EST000225-7918 | K39: B | L39: 3EST000225-7918 | M39: 3ECP413922-1001 | N39: _ | O39: 3ECP413922-1001 | P39: FA020023413 | Q39: 01.2 | R39: FA020023413 | S39: 01.2
A40: Visualisation - MMI | B40: FRS_Visualisation - MMI | C40: pdf | D40: 3EST000225-7919 | E40: B | F40: 3EST000225-7919 | G40: 3EST000225-7919 | H40: B | I40: 3EST000225-7919 | J40: 3EST000225-7919 | K40: B | L40: 3EST000225-7919 | M40: 3ECP413922-1003 | N40: _ | O40: 3ECP413922-1003 | P40: FA020027681 | Q40: 03.2 | R40: FA020027681 | S40: 03.2
A41: TCMS - Operational | B41: FRS_TCMS - Operational | C41: pdf | D41: 3EST000225-7917 | E41: B | F41: 3EST000225-7917 | G41: 3EST000225-7917 | H41: B | I41: 3EST000225-7917 | J41: 3EST000225-7917 | K41: B | L41: 3EST000225-7917 | M41: 3ECP413922-0904 | N41: _ | O41: 3ECP413922-0904 | P41: FA020026278 | Q41: 02.2 | R41: FA020026278 | S41: 02.2
A42: Train to Wayside Communication (Teledia) | B42: FRS_Teledia | C42: pdf | D42: 3ECP413176-0001 | E42: _ | F42: 3ECP413176-0001 | G42: 3ECP413719-1200 | H42: _ | I42: 3ECP413719-1200 | J42: 3ECP413176-0001 | K42: _ | L42: 3ECP413176-0001 | M42: 3ECP413719-1200 | N42: _ | O42: 3ECP413719-1200 | P42: \ | Q42: \ | R42: \ | S42: \
A43: Line Voltage | B43: FRS_Line Voltage | C43: pdf | D43: 3EST000225-7907 | E43: C | F43: 3EST000225-7907 | G43: 3ECP413719-0401 | H43: _ | I43: manca | J43: 3ECP413571-0401 | K43: A | M43: 3EGH489028-2358 | N43: B | O43: 3EGH489028-2358 | P43: FA020022045 | Q43: 06.2 | R43: FA020022045 | S43: 06.2
A44: Aux Electrical Supply | B44: FRS_Aux Electrical Supply | C44: pdf | D44: 3EST000225-7914 | E44: B | F44: 3EST000225-7914 | G44: 3EST000225-7914 | H44: B | I44: 3EST000225-7914 | J44: 3ECP413571-0601 | K44: _ | M44: 3EST000225-7914 | N44: B | O44: 3EST000225-7914 | P44: FA020024537 | Q44: 03.2 | R44: FA020024537 | S44: 03.2
A45: Battery | B45: FRS_Battery | C45: pdf | D45: 3EST000225-7908 | E45: B | F45: 3EST000225-7908 | G45: 3EST000225-7908 | H45: B | I45: 3EST000225-7908 | J45: 3EST000225-7908 | K45: B | L45: 3EST000225-7908 | M45: 3EST000225-7908 | N45: B | O45: 3EST000225-7908 | P45: FA020024538 | Q45: 03.2 | R45: FA020024538 | S45: 03.2
A46: Air Supply | B46: FRS_Air Supply | C46: pdf | D46: 3EST000225-7915 | E46: D | F46: 3EST000225-7915 | G46: 3ECP413719-0603 | H46: _ | I46: 3ECP413719-0603 | J46: 3EST000225-7915 | K46: D | L46: 3EST000225-7915 | M46: 3ECP413719-0603 | N46: _ | O46: 3ECP413719-0603 | P46: FA020024531 | Q46: 01.3 | R46: FA020024531 | S46: 01.3
...

Sheet GENERAL
A1: DOC DESCRIPTION | B1: DOC ID | C1: DOC EXT | D1: VZI_Base | F1: VZI_New14 | H1: VZ_FR | J1: VZ_ES | L1: VZI-6_R1 | N1: VZI-4_R1 | P1: VZ_DAI | R1: VZ_Esxx
D2: File/Codice | E2: Rev | F2: File/Codice | G2: Rev | H2: File/Codice | I2: Rev | J2: File/Codice | K2: Rev | L2: Codice | M2: Rev | N2: Codice | O2: Rev | P2: Codice | Q2: Rev | R2: Codice | S2: Rev
A3: Functional Doc & Specification
A4: Architettura di Controllo Treno ed Interfacce di Comando | B4: FD_TCMS | C4: pdf | D4: 3ECP410429-0001 | E4: L | F4: 3ECP413973-0001 | G4: A | L4: FE010019098 | M4: 1.02
A5: Brake System | B5: FD_Brake | C5: pdf | D5: 3EGH489013-3044 | E5: F
A6: Air Supply | B6: FD_Air Supply | C6: pdf | D6: 3EGH489013-4928 | E6: A
A7: Descrizione SW PCU | B7: FD_PCU | C7: pdf | D7: 3EST000225-5111 | E7: C
A8: Descrizione SW Alta Tensione | B8: FD_High Voltage | C8: pdf | D8: 3EST000225-5113 | E8: C
A9: Descrizione SW Propulsione | B9: FD_Propulsion | C9: pdf | D9: 3EST000225-5115 | E9: C
A10: Descrizione SW DCU/L | B10: FD_DCU/L | C10: pdf | D10: 3EST000225-5117 | E10: B
A11: Descrizione SW DCU/M | B11: FD_DCU/M | C11: pdf | D11: 3EST000225-5118 | E11: G
A12: Descrizione SW ACM | B12: FD_ACM | C12: pdf | D12: 3EST000225-5119 | E12: E
A13: Descrizione SW DCU/C | B13: FD_DCU/C | C13: pdf | D13: 3EST000225-5120 | E13: C
A14: Descrizione SW LIM | B14: FD_LIM | C14: pdf | D14: 3EST000225-5132 | E14: _
A16: Product Description
A17: Converter unit TC1120 | B17: PDES_Converter | C17: pdf | D17: 3EST000228-5653 | E17: B
A18: Auxiliary converter module, CM-C S 15/10 WA V02 | B18: PDES_Auxiliary module | C18: pdf | D18: 3EST000226-1993 | E18: A
A19: Chopper converter module, CM-C L 30/07 WC V01 | B19: PDES_Chopper module | C19: pdf | D19: 3EST000226-1995 | E19: B
A20: Line converter module, CM-C M 15/15 WL V06 | B20: PDES_Line Module | C20: pdf | D20: 3EST000226-1994 | E20: B
A21: Motor converter module, CM-C S 15/10 WM V02 | B21: PDES_Motor Module | C21: pdf | D21: 3EST000226-1992 | E21: B
A22: TCMS Tech Description | B22: PDES_TCMS | C22: pdf | D22: 3EST000225-4855 | E22: E
A23: Brake Tech Description | B23: PDES_Brake | C23: pdf | D23: FTIT10002-I01TDE | E23: F00
A25: Test Specification & Report
A26: System Test Specification | B26: TS_VZI_Base | C26: pdf | D26: 3EST000225-6042 | E26: C
A27: EPVE63 Test Intervento protezioni azionamento | B27: TS_Test Protezioni azionamento EPVE63 | C27: pdf | L27: DC08060VE63 | M27: 01
A28: EPVE63 Report Intervento protezioni azionamento | B28: TS_Report Protezioni azionamento EPVE63 | C28: pdf | L28: DD04060VE63 | M28: 00
A29: Test Report HVSP | B29: TS_Report HVSP | C29: pdf | L29: DD040031058 | M29: 00.6
A30: Test High Voltage | B30: TS_Test High Voltage | C30: pdf | L30: EC070028470 | M30: 1.0
A31: Test Driver Control | B31: TS_Test Driver Control | C31: pdf | L31: EC070028753 | M31: 1.0
A32: Test Intervento protezioni azionamento | B32: TS_Test Protezioni azionamento | C32: pdf | L32: EC070045631 | M32: 2.0
A33: Combined test specification | B33: TS_Test Combined | C33: pdf | L33: EC070027996 | M33: 2.0
A34: Prove HVSP in combined test | B34: TS_Test HVSP Combined | C34: pdf | L34: EC070030298 | M34: 00.2

Sheet MAN_CPR
A1: DOC DESCRIPTION | B1: DOC ID | C1: DOC EXT | D1: TIPO | E1: VOLUME SUBVOLUME _TOMO | F1: CODICE | G1: VZI_Base | J1: VZI_New14 | M1: VZ_FR | P1: VZ-ES | S1: VZI-6_R1 | V1: VZI-4_R1
G2: REF | H2: REV | I2: DATA | J2: REF | K2: REV | L2: DATA | M2: REF | N2: REV | O2: DATA | P2: REF | Q2: REV | R2: DATA | S2: REV | V2: REV
A3: Descrizione generale e funzionamento | B3: =CONCATENATE(D3,"_",E3) -> PBC_01A | C3: pdf | D3: PBC | E3: 01A | F3: =CONCATENATE(G3,"-",H3) -> ETR1000V300-PBC-01A-14 | G3: =CONCATENATE("ETR1000V300-",$D3,"-",$E3) -> ETR1000V300-PBC-01A | H3: 14 | I3: 46113 | J3: =CONCATENATE("ETR1000V300-",$D3,"-",$E3) -> ETR1000V300-PBC-01A | K3: 14 | L3: 46113 | S3: 06 | V3: 06
A4: Norme d’Uso ed Interventi di Emergenza | B4: =CONCATENATE(D4,"_",E4) -> PBC_01B | C4: pdf | D4: PBC | E4: 01B | F4: =CONCATENATE(G4,"-",H4) -> ETR1000V300-PBC-01B-14 | G4: =CONCATENATE("ETR1000V300-",$D4,"-",$E4) -> ETR1000V300-PBC-01B | H4: 14 | I4: 45748 | J4: =CONCATENATE("ETR1000V300-",$D4,"-",$E4) -> ETR1000V300-PBC-01B | K4: 14 | L4: 45748 | M4: TBD | N4: TBD | O4: TBD | P4: TBD | Q4: TBD | R4: TBD | S4: 09 | V4: 09
A5: Manuale per il Personale di Bordo addetto alla Scorta | B5: =CONCATENATE(D5,"_",E5) -> PBS_01A | C5: pdf | D5: PBS | E5: 01A | F5: =CONCATENATE(G5,"-",H5) -> ETR1000V300-PBS-01A-04 | G5: =CONCATENATE("ETR1000V300-",$D5,"-",$E5) -> ETR1000V300-PBS-01A | H5: 04 | I5: 45748 | J5: =CONCATENATE("ETR1000V300-",$D5,"-",$E5) -> ETR1000V300-PBS-01A | K5: 04 | L5: 45748 | M5: esiste collana completa Giugno 2022 in | S5: 03 | V5: 03
A6: Cassa | B6: =CONCATENATE(D6,"_",E6) -> MR1_01A | C6: pdf | D6: MR1 | E6: 01A | F6: =CONCATENATE(G6,"-",H6) -> ETR1000V300-MR1-01A-08 | G6: =CONCATENATE("ETR1000V300-",$D6,"-",$E6) -> ETR1000V300-MR1-01A | H6: 08 | I6: 46113 | J6: =CONCATENATE("ETR1000V300-",$D6,"-",$E6) -> ETR1000V300-MR1-01A | K6: 08 | L6: 46113 | M6: SGF Base/ Documentazione Tecnica | S6: 05 | V6: 05
A7: Carrello | B7: =CONCATENATE(D7,"_",E7) -> MR1_02A | C7: pdf | D7: MR1 | E7: 02A | F7: =CONCATENATE(G7,"-",H7) -> ETR1000V300-MR1-02A-14 | G7: =CONCATENATE("ETR1000V300-",$D7,"-",$E7) -> ETR1000V300-MR1-02A | H7: 14 | I7: 46113 | J7: =CONCATENATE("ETR1000V300-",$D7,"-",$E7) -> ETR1000V300-MR1-02A | K7: 14 | L7: 46113 | M7: / ETR1000 I-F | S7: 08 | V7: 08
A8: Impianto pneumatico e freno | B8: =CONCATENATE(D8,"_",E8) -> MR1_03A | C8: pdf | D8: MR1 | E8: 03A | F8: =CONCATENATE(G8,"-",H8) -> ETR1000V300-MR1-03A-09 | G8: =CONCATENATE("ETR1000V300-",$D8,"-",$E8) -> ETR1000V300-MR1-03A | H8: 09 | I8: 46113 | J8: =CONCATENATE("ETR1000V300-",$D8,"-",$E8) -> ETR1000V300-MR1-03A | K8: 09 | L8: 46113 | M8: / Manualistica Corridoio I/F | S8: 04 | V8: 04
A9: Equipaggiamento elettrico ed elettropneumatico | B9: =CONCATENATE(D9,"_",E9) -> MR1_04A | C9: pdf | D9: MR1 | E9: 04A | F9: =CONCATENATE(G9,"-",H9) -> ETR1000V300-MR1-04A-10 | G9: =CONCATENATE("ETR1000V300-",$D9,"-",$E9) -> ETR1000V300-MR1-04A | H9: 10 | I9: 46113 | J9: =CONCATENATE("ETR1000V300-",$D9,"-",$E9) -> ETR1000V300-MR1-04A | K9: 10 | L9: 46113 | S9: 05 | V9: 05
A10: Logica di comando | B10: =CONCATENATE(D10,"_",E10) -> MR1_05A | C10: pdf | D10: MR1 | E10: 05A | F10: =CONCATENATE(G10,"-",H10) -> ETR1000V300-MR1-05A-04 | G10: =CONCATENATE("ETR1000V300-",$D10,"-",$E10) -> ETR1000V300-MR1-05A | H10: 04 | I10: 46113 | J10: =CONCATENATE("ETR1000V300-",$D10,"-",$E10) -> ETR1000V300-MR1-05A | K10: 04 | L10: 46113 | S10: 03 | V10: 03
A11: Logica di comando - Nodo TCN | B11: =CONCATENATE(D11,"_",E11) -> MR1_05B | C11: pdf | D11: MR1 | E11: 05B | F11: =CONCATENATE(G11,"-",H11) -> ETR1000V300-MR1-05B-02 | G11: =CONCATENATE("ETR1000V300-",$D11,"-",$E11) -> ETR1000V300-MR1-05B | H11: 02 | I11: giu-17 | J11: =CONCATENATE("ETR1000V300-",$D11,"-",$E11) -> ETR1000V300-MR1-05B | K11: 02 | L11: giu-17 | S11: 04 | V11: 04
A12: Azionamento di trazione | B12: =CONCATENATE(D12,"_",E12) -> MR1_06A | C12: pdf | D12: MR1 | E12: 06A | F12: =CONCATENATE(G12,"-",H12) -> ETR1000V300-MR1-06A-05 | G12: =CONCATENATE("ETR1000V300-",$D12,"-",$E12) -> ETR1000V300-MR1-06A | H12: 05 | I12: 46113 | J12: =CONCATENATE("ETR1000V300-",$D12,"-",$E12) -> ETR1000V300-MR1-06A | K12: 05 | L12: 46113 | S12: 04 | V12: 04
A13: Motore di trazione | B13: =CONCATENATE(D13,"_",E13) -> MR1_07A | C13: pdf | D13: MR1 | E13: 07A | F13: =CONCATENATE(G13,"-",H13) -> ETR1000V300-MR1-07A-07 | G13: =CONCATENATE("ETR1000V300-",$D13,"-",$E13) -> ETR1000V300-MR1-07A | H13: 07 | I13: 46113 | J13: =CONCATENATE("ETR1000V300-",$D13,"-",$E13) -> ETR1000V300-MR1-07A | K13: 07 | L13: 46113 | S13: 04 | V13: 04
A14: Passaggi esterni | B14: =CONCATENATE(D14,"_",E14) -> MR1_08A | C14: pdf | D14: MR1 | E14: 08A | F14: =CONCATENATE(G14,"-",H14) -> ETR1000V300-MR1-08A-05 | G14: =CONCATENATE("ETR1000V300-",$D14,"-",$E14) -> ETR1000V300-MR1-08A | H14: 05 | I14: 46113 | J14: =CONCATENATE("ETR1000V300-",$D14,"-",$E14) -> ETR1000V300-MR1-08A | K14: 05 | L14: 46113 | S14: 04 | V14: 04
A15: Sottosistema di climatizzazione | B15: =CONCATENATE(D15,"_",E15) -> MR1_09A | C15: pdf | D15: MR1 | E15: 09A | F15: =CONCATENATE(G15,"-",H15) -> ETR1000V300-MR1-09A-05 | G15: =CONCATENATE("ETR1000V300-",$D15,"-",$E15) -> ETR1000V300-MR1-09A | H15: 05 | I15: 46113 | J15: =CONCATENATE("ETR1000V300-",$D15,"-",$E15) -> ETR1000V300-MR1-09A | K15: 05 | L15: 46113 | S15: 04 | V15: 04
A16: Sottosistema di comunicazione | B16: =CONCATENATE(D16,"_",E16) -> MR1_10A | C16: pdf | D16: MR1 | E16: 10A | F16: =CONCATENATE(G16,"-",H16) -> ETR1000V300-MR1-10A-05 | G16: =CONCATENATE("ETR1000V300-",$D16,"-",$E16) -> ETR1000V300-MR1-10A | H16: 05 | I16: 46113 | J16: =CONCATENATE("ETR1000V300-",$D16,"-",$E16) -> ETR1000V300-MR1-10A | K16: 05 | L16: 46113 | S16: 03 | V16: 03
A17: Convertitore servizi ausiliari e caricabatterie | B17: =CONCATENATE(D17,"_",E17) -> MR1_11A | C17: pdf | D17: MR1 | E17: 11A | F17: =CONCATENATE(G17,"-",H17) -> ETR1000V300-MR1-11A-03 | G17: =CONCATENATE("ETR1000V300-",$D17,"-",$E17) -> ETR1000V300-MR1-11A | H17: 03 | I17: 46113 | J17: =CONCATENATE("ETR1000V300-",$D17,"-",$E17) -> ETR1000V300-MR1-11A | K17: 03 | L17: 46113 | S17: 03 | V17: 03
A18: Sottosistema diagnostica di bordo | B18: =CONCATENATE(D18,"_",E18) -> MR1_13A | C18: pdf | D18: MR1 | E18: 13A | F18: =CONCATENATE(G18,"-",H18) -> ETR1000V300-MR1-13A-03 | G18: =CONCATENATE("ETR1000V300-",$D18,"-",$E18) -> ETR1000V300-MR1-13A | H18: 03 | I18: 46113 | J18: =CONCATENATE("ETR1000V300-",$D18,"-",$E18) -> ETR1000V300-MR1-13A | K18: 03 | L18: 46113 | S18: 03 | V18: 03
A19: Allestimenti interni | B19: =CONCATENATE(D19,"_",E19) -> MR1_14A | C19: pdf | D19: MR1 | E19: 14A | F19: =CONCATENATE(G19,"-",H19) -> ETR1000V300-MR1-14A-06 | G19: =CONCATENATE("ETR1000V300-",$D19,"-",$E19) -> ETR1000V300-MR1-14A | H19: 06 | I19: 46113 | J19: =CONCATENATE("ETR1000V300-",$D19,"-",$E19) -> ETR1000V300-MR1-14A | K19: 06 | L19: 46113
A20: Allestimenti interni - Arredi comparto e cabina di guida | B20: =CONCATENATE(D20,"_",E20) -> MR1_14B | C20: pdf | D20: MR1 | E20: 14B | F20: =CONCATENATE(G20,"-",H20) -> ETR1000V300-MR1-14B-\ | G20: =CONCATENATE("ETR1000V300-",$D20,"-",$E20) -> ETR1000V300-MR1-14B | H20: \ | I20: \ | J20: =CONCATENATE("ETR1000V300-",$D20,"-",$E20) -> ETR1000V300-MR1-14B | K20: \ | L20: \ | S20: 03 | V20: 03
A21: Servizi Generali di Bordo - Toilette | B21: =CONCATENATE(D21,"_",E21) -> MR1_15A | C21: pdf | D21: MR1 | E21: 15A | F21: =CONCATENATE(G21,"-",H21) -> ETR1000V300-MR1-15A-06 | G21: =CONCATENATE("ETR1000V300-",$D21,"-",$E21) -> ETR1000V300-MR1-15A | H21: 06 | I21: 46113 | J21: =CONCATENATE("ETR1000V300-",$D21,"-",$E21) -> ETR1000V300-MR1-15A | K21: 06 | L21: 46113 | S21: 03 | V21: 03
A22: Servizi Generali di Bordo - Bar Bistrot | B22: =CONCATENATE(D22,"_",E22) -> MR1_15B | C22: pdf | D22: MR1 | E22: 15B | F22: =CONCATENATE(G22,"-",H22) -> ETR1000V300-MR1-15B-\ | G22: =CONCATENATE("ETR1000V300-",$D22,"-",$E22) -> ETR1000V300-MR1-15B | H22: \ | I22: \ | J22: =CONCATENATE("ETR1000V300-",$D22,"-",$E22) -> ETR1000V300-MR1-15B | K22: \ | L22: \ | S22: 03 | V22: 03
A23: Emergenza e recupero | B23: =CONCATENATE(D23,"_",E23) -> MR1_16A | C23: pdf | D23: MR1 | E23: 16A | F23: =CONCATENATE(G23,"-",H23) -> ETR1000V300-MR1-16A-07 | G23: =CONCATENATE("ETR1000V300-",$D23,"-",$E23) -> ETR1000V300-MR1-16A | H23: 07 | I23: 44228 | J23: =CONCATENATE("ETR1000V300-",$D23,"-",$E23) -> ETR1000V300-MR1-16A | K23: 07 | L23: 44228 | S23: 03 | V23: 03
A24: Telecomunicazioni TT | B24: =CONCATENATE(D24,"_",E24) -> MR1_18A | C24: pdf | D24: MR1 | E24: 18A | F24: =CONCATENATE(G24,"-",H24) -> ETR1000V300-MR1-18A-05 | G24: =CONCATENATE("ETR1000V300-",$D24,"-",$E24) -> ETR1000V300-MR1-18A | H24: 05 | I24: 46113 | J24: =CONCATENATE("ETR1000V300-",$D24,"-",$E24) -> ETR1000V300-MR1-18A | K24: 05 | L24: 46113 | S24: 03 | V24: 03
A25: Sottosistema di bordo generale | B25: =CONCATENATE(D25,"_",E25) -> MR1_20A | C25: pdf | D25: MR1 | E25: 20A | F25: =CONCATENATE(G25,"-",H25) -> ETR1000V300-MR1-20A-03 | G25: =CONCATENATE("ETR1000V300-",$D25,"-",$E25) -> ETR1000V300-MR1-20A | H25: 03 | I25: giu-20 | J25: =CONCATENATE("ETR1000V300-",$D25,"-",$E25) -> ETR1000V300-MR1-20A | K25: 03 | L25: giu-20 | S25: 05 | V25: 05
A26: Sottosistema di bordo ETCS specifico del treno | B26: =CONCATENATE(D26,"_",E26) -> MR1_20B | C26: pdf | D26: MR1 | E26: 20B | F26: =CONCATENATE(G26,"-",H26) -> ETR1000V300-MR1-20B-01 | G26: =CONCATENATE("ETR1000V300-",$D26,"-",$E26) -> ETR1000V300-MR1-20B | H26: 01 | I26: lug-17 | J26: =CONCATENATE("ETR1000V300-",$D26,"-",$E26) -> ETR1000V300-MR1-20B | K26: 01 | L26: lug-17 | S26: 02 | V26: 02
A27: SSB ERTMS/SCMT (ALA) - MANUALE GENERICO USO E MANUTENZIONE (B60A.000012.640.06I) | B27: =CONCATENATE(D27,"_",E27) -> MR1_20A_ALA | C27: pdf | D27: MR1 | E27: 20A_ALA | F27: =CONCATENATE(G27,"-",H27) -> ETR1000V300-MR1-20A_ALA-08 | G27: =CONCATENATE("ETR1000V300-",$D27,"-",$E27) -> ETR1000V300-MR1-20A_ALA | H27: 08 | I27: 43966 | J27: =CONCATENATE("ETR1000V300-",$D27,"-",$E27) -> ETR1000V300-MR1-20A_ALA | K27: 08 | L27: 43966
A28: SSB ERTMS/SCMT (ELO) - MANUALE GENERICO USO E MANUTENZIONE (B60X.0100506.G00.00IT rev.02.00) | B28: =CONCATENATE(D28,"_",E28) -> MR1_20A_ELO | C28: pdf | D28: MR1 | E28: 20A_ELO | F28: =CONCATENATE(G28,"-",H28) -> ETR1000V300-MR1-20A_ELO-05 | G28: =CONCATENATE("ETR1000V300-",$D28,"-",$E28) -> ETR1000V300-MR1-20A_ELO | H28: 05 | I28: 46113 | J28: =CONCATENATE("ETR1000V300-",$D28,"-",$E28) -> ETR1000V300-MR1-20A_ELO | K28: 05 | L28: 46113
A29: Sotto Sistema di Bordo ERTMS BL3 CON SCMT INTEGRATO (B60A.0100914.G00.00IT) | B29: =CONCATENATE(D29,"_",E29) -> MR1_20B_ELO | C29: pdf | D29: MR1 | E29: 20B_ELO | F29: =CONCATENATE(G29,"-",H29) -> ETR1000V300-MR1-20B_ELO-02 | G29: =CONCATENATE("ETR1000V300-",$D29,"-",$E29) -> ETR1000V300-MR1-20B_ELO | H29: 02 | I29: 45717 | J29: =CONCATENATE("ETR1000V300-",$D29,"-",$E29) -> ETR1000V300-MR1-20B_ELO | K29: 02 | L29: 45717
A30: PGDJ DIS-JRU FTP - PRODOTTO GENERICO DIS-JRU (FT11P035105GE03B) | B30: =CONCATENATE(D30,"_",E30) -> MR1_31A_JRU | C30: pdf | D30: MR1 | E30: 31A_JRU | F30: =CONCATENATE(G30,"-",H30) -> ETR1000V300-MR1-31A_JRU-\ | G30: =CONCATENATE("ETR1000V300-",$D30,"-",$E30) -> ETR1000V300-MR1-31A_JRU | H30: \ | I30: 44256 | J30: =CONCATENATE("ETR1000V300-",$D30,"-",$E30) -> ETR1000V300-MR1-31A_JRU | K30: \ | L30: 44256
A31: Sistema informativo di condotta Generale (DIS) | B31: =CONCATENATE(D31,"_",E31) -> MR1_31A | C31: pdf | D31: MR1 | E31: 31A | F31: =CONCATENATE(G31,"-",H31) -> ETR1000V300-MR1-31A-02 | G31: =CONCATENATE("ETR1000V300-",$D31,"-",$E31) -> ETR1000V300-MR1-31A | H31: 02 | I31: gen-18 | J31: =CONCATENATE("ETR1000V300-",$D31,"-",$E31) -> ETR1000V300-MR1-31A | K31: 02 | L31: gen-18 | S31: 04 | V31: 04
A32: Cassa | B32: =CONCATENATE(D32,"_",E32) -> MR2_01A | C32: pdf | D32: MR2 | E32: 01A | F32: =CONCATENATE(G32,"-",H32) -> ETR1000V300-MR2-01A-07 | G32: =CONCATENATE("ETR1000V300-",$D32,"-",$E32) -> ETR1000V300-MR2-01A | H32: 07 | I32: 46113 | J32: =CONCATENATE("ETR1000V300-",$D32,"-",$E32) -> ETR1000V300-MR2-01A | K32: 07 | L32: 46113
A33: Carrello | B33: =CONCATENATE(D33,"_",E33) -> MR2_02A | C33: pdf | D33: MR2 | E33: 02A | F33: =CONCATENATE(G33,"-",H33) -> ETR1000V300-MR2-02A-13 | G33: =CONCATENATE("ETR1000V300-",$D33,"-",$E33) -> ETR1000V300-MR2-02A | H33: 13 | I33: 46113 | J33: =CONCATENATE("ETR1000V300-",$D33,"-",$E33) -> ETR1000V300-MR2-02A | K33: 13 | L33: 46113
A34: Impianto pneumatico e freno | B34: =CONCATENATE(D34,"_",E34) -> MR2_03A | C34: pdf | D34: MR2 | E34: 03A | F34: =CONCATENATE(G34,"-",H34) -> ETR1000V300-MR2-03A-06 | G34: =CONCATENATE("ETR1000V300-",$D34,"-",$E34) -> ETR1000V300-MR2-03A | H34: 06 | I34: 46113 | J34: =CONCATENATE("ETR1000V300-",$D34,"-",$E34) -> ETR1000V300-MR2-03A | K34: 06 | L34: 46113
A35: Equipaggiamento elettrico ed elettropneumatico | B35: =CONCATENATE(D35,"_",E35) -> MR2_04A | C35: pdf | D35: MR2 | E35: 04A | F35: =CONCATENATE(G35,"-",H35) -> ETR1000V300-MR2-04A-10 | G35: =CONCATENATE("ETR1000V300-",$D35,"-",$E35) -> ETR1000V300-MR2-04A | H35: 10 | I35: 46113 | J35: =CONCATENATE("ETR1000V300-",$D35,"-",$E35) -> ETR1000V300-MR2-04A | K35: 10 | L35: 46113
A36: Logica di comando | B36: =CONCATENATE(D36,"_",E36) -> MR2_05A | C36: pdf | D36: MR2 | E36: 05A | F36: =CONCATENATE(G36,"-",H36) -> ETR1000V300-MR2-05A-03 | G36: =CONCATENATE("ETR1000V300-",$D36,"-",$E36) -> ETR1000V300-MR2-05A | H36: 03 | I36: 46113 | J36: =CONCATENATE("ETR1000V300-",$D36,"-",$E36) -> ETR1000V300-MR2-05A | K36: 03 | L36: 46113
A37: Logica di comando - Nodo TCN | B37: =CONCATENATE(D37,"_",E37) -> MR2_05B | C37: pdf | D37: MR2 | E37: 05B | F37: =CONCATENATE(G37,"-",H37) -> ETR1000V300-MR2-05B-02 | G37: =CONCATENATE("ETR1000V300-",$D37,"-",$E37) -> ETR1000V300-MR2-05B | H37: 02 | I37: giu-17 | J37: =CONCATENATE("ETR1000V300-",$D37,"-",$E37) -> ETR1000V300-MR2-05B | K37: 02 | L37: giu-17
A38: Azionamento di trazione | B38: =CONCATENATE(D38,"_",E38) -> MR2_06A | C38: pdf | D38: MR2 | E38: 06A | F38: =CONCATENATE(G38,"-",H38) -> ETR1000V300-MR2-06A-04 | G38: =CONCATENATE("ETR1000V300-",$D38,"-",$E38) -> ETR1000V300-MR2-06A | H38: 04 | I38: 46113 | J38: =CONCATENATE("ETR1000V300-",$D38,"-",$E38) -> ETR1000V300-MR2-06A | K38: 04 | L38: 46113
A39: Motore di trazione | B39: =CONCATENATE(D39,"_",E39) -> MR2_07A | C39: pdf | D39: MR2 | E39: 07A | F39: =CONCATENATE(G39,"-",H39) -> ETR1000V300-MR2-07A-05 | G39: =CONCATENATE("ETR1000V300-",$D39,"-",$E39) -> ETR1000V300-MR2-07A | H39: 05 | I39: 46113 | J39: =CONCATENATE("ETR1000V300-",$D39,"-",$E39) -> ETR1000V300-MR2-07A | K39: 05 | L39: 46113
A40: Passaggi esterni | B40: =CONCATENATE(D40,"_",E40) -> MR2_08A | C40: pdf | D40: MR2 | E40: 08A | F40: =CONCATENATE(G40,"-",H40) -> ETR1000V300-MR2-08A-04 | G40: =CONCATENATE("ETR1000V300-",$D40,"-",$E40) -> ETR1000V300-MR2-08A | H40: 04 | I40: 46113 | J40: =CONCATENATE("ETR1000V300-",$D40,"-",$E40) -> ETR1000V300-MR2-08A | K40: 04 | L40: 46113
...

Sheet DIAGNOSTIC
A1: DOC DESCRIPTION | B1: DOC ID | C1: DOC EXT | D1: VZI_Base | F1: VZI_New14 | H1: VZ_FR | J1: VZ_ES | L1: VZI-6_R1 | N1: VZI-4_R1 | P1: VZ_DAI | R1: VZ_Esxx
D2: File/Codice | E2: Rev | F2: File/Codice | G2: Rev | H2: File/Codice | I2: Rev | J2: File/Codice | K2: Rev | L2: Codice | M2: Rev | N2: Codice | O2: Rev | P2: Codice | Q2: Rev | R2: Codice | S2: Rev
A3: Telediagnostica
A4: Sviluppo regole (Algoritmi Diagnostici) | B4: DIA_Regole | C4: xlsm | D4: Sviluppo_Regole_TI_rev1.1 | E4: \ | F4: SVILUPPO REGOLE_ 14_FR_SP_Rev_0.1 | G4: \ | H4: SVILUPPO REGOLE_ 14_FR_SP_Rev_0.1 | I4: \ | J4: SVILUPPO REGOLE_ 14_FR_SP_Rev_0.1 | K4: \
A5: Event Report/List | B5: DIA_Event | C5: xlsx | D5: EventReport_VZI_3.9.0.3 | E5: \ | F5: EventReport_VZI14_BL3_5.1.0.3 2 | G5: \ | H5: EventReport VZIF 11.4.0 | I5: \ | J5: EventReport_VZS 21.2.0.3 | L5: FP010036055 | M5: 3.32
A6: Teledia Signal List | B6: DIA_Signal | C6: xlsx | L6: FP020046917 | M6: 3.32
A7: PropulsionDiagnosticDataset | B7: DIA_Dataset_Propulsion | C7: xlsx | L7: PropulsionDiagnosticDataset | M7: 00.12
A8: EMS ICD diagnostic event | B8: DIA_Event EMS | C8: xlsx | H8: EC130034365 | I8: 00

Sheet Funzioni
A1: FUNC ID | B1: DESCRIZIONE FUNZIONE | C1: DOC CARTELLA | D1: DOC ID | E1: Info DOC | F1: VZI_Base | G1: VZI_New14 | H1: VZ_FR | I1: VZ_ES | J1: VZI-6_R1 | K1: VZI-4_R1 | L1: VZ_DAI
A2: Park_Brake_01 | B2: Comando applicazione/rilascio FAM da banco di manovra | D2: =IF($A2="","",HYPERLINK(CONCATENATE(Cartelle!$D$6,$A2),CONCATENATE("#Sharepoint//",$A2))) -> #Sharepoint//Park_Brake_01
C3: CONFIG | D3: FS_DM1 | E3: Link | F3: {=HYPERLINK(CONCATENATE(Cartelle!$D$5,F$1,"/",$C3,"/",MID($D3,1,FIND("_",$D3)-1),"/",INDIRECT(CONCATENATE("'" & $C3 & "'!",ADDRESS(MATCH($D3, INDIRECT("'" & $C3 & "'!$B:$B"), 0),MATCH(F$1, INDIRECT("'" & $C3 & "'!$1:$1"), 0)))),".",INDIRECT(CONCATENATE("'"&$C3&"'!",ADDRESS(MATCH($D3,INDIRECT("'"&$C3&"'!$B:$B"),0),3))),"#page=",F4),CONCATENATE("#Sharepoint//",$D3))} -> #Sharepoint//FS_DM1 | J3: {=HYPERLINK(CONCATENATE(Cartelle!$D$5,INDEX(INDIRECT("'" & $C3 & "'!$1:$1"), 1, MATCH(INDIRECT(CONCATENATE("'" & $C3 & "'!",ADDRESS(MATCH($D3, INDIRECT("'" & $C3 & "'!$B:$B"), 0),MATCH(J$1, INDIRECT("'" & $C3 & "'!$1:$1"), 0)))),INDIRECT(CONCATENATE("'" & $C3 & "'!",MATCH($D3, INDIRECT("'" & $C3 & "'!$B:$B"), 0),":",MATCH($D3, INDIRECT("'" & $C3 & "'!$B:$B"), 0))),0)),"/",$C3,"/",MID($D3,1,FIND("_",$D3)-1),"/",INDIRECT(CONCATENATE("'" & $C3 & "'!",ADDRESS(MATCH($D3, INDIRECT("'" & $C3 & "'!$B:$B"), 0),MATCH(J$1, INDIRECT("'" & $C3 & "'!$1:$1"), 0)))),".",INDIRECT(CONCATENATE("'"&$C3&"'!",ADDRESS(MATCH($D3,INDIRECT("'"&$C3&"'!$B:$B"),0),3))),"#page=",J4),CONCATENATE("#Sharepoint//",$D3))} -> #Sharepoint//FS_DM1
E4: Rif. Pagina | F4: 276 | G4: 243 | J4: 144
E5: Componenti circuito elettrico | F5: GG-A024 = Pulsante parking JE-K0005 = MIO-S-DX4 | J5: GG-A024 = Pulsante parking GC-K025 = Relè abilitazione cabina GC-K018 = Relè temporizz GC-K011 = Relè abilitazione cabina JE-K005 = RIO-LP MASTER
E6: Descrizione circuitale | F6: La pressione di GG-A024 chiude 2 contatti interni (1 ordinario, 1 ridondato), collegando 2 linee 110V a 2 ingressi della MIO: BRA_PARK_COM Le 2 linee 110 derivano direttamente dal bus 180, tramite due fusibili rispettivamente JE-F007 e JE-F009. | J6: La pressione di GG-A024 chiude 2 contatti interni (1 ordinario, 1 ridondato), collegando 2 linee 110V a 2 ingressi della RIO: BRA_PARK_COM_N e BRA_PARK_COM_R Le 2 linee 110 derivano direttamente dal bus 180, tramite due fusibili rispettivamente JE-F007 e JE-F009. Un contatto del pulsante inoltre alimenta un circuito che intercetta, sulle casse portanti con disponibilità del freno di parcheggio, il comando di rilascio del TCMS verso le valvole di attuazione del parking brake stesso. Tale circuito viene alimentato tramite i relè di banco GC-K011 e GC-K025 e attuato per mezzo del relè temporizzato GC-K018. Tutta questa catena alimenta un relè GG-K028 presenti sulle casse portanti con disponibilità di freno di parcheggio.
C7: CONFIG | D7: FS_TT2 | E7: Link | F7: {=HYPERLINK(CONCATENATE(Cartelle!$D$5,F$1,"/",$C7,"/",MID($D7,1,FIND("_",$D7)-1),"/",INDIRECT(CONCATENATE("'" & $C7 & "'!",ADDRESS(MATCH($D7, INDIRECT("'" & $C7 & "'!$B:$B"), 0),MATCH(F$1, INDIRECT("'" & $C7 & "'!$1:$1"), 0)))),".",INDIRECT(CONCATENATE("'"&$C7&"'!",ADDRESS(MATCH($D7,INDIRECT("'"&$C7&"'!$B:$B"),0),3))),"#page=",F8),CONCATENATE("#Sharepoint//",$D7))} -> #Sharepoint//FS_TT2 | J7: {=HYPERLINK(CONCATENATE(Cartelle!$D$5,INDEX(INDIRECT("'" & $C7 & "'!$1:$1"), 1, MATCH(INDIRECT(CONCATENATE("'" & $C7 & "'!",ADDRESS(MATCH($D7, INDIRECT("'" & $C7 & "'!$B:$B"), 0),MATCH(J$1, INDIRECT("'" & $C7 & "'!$1:$1"), 0)))),INDIRECT(CONCATENATE("'" & $C7 & "'!",MATCH($D7, INDIRECT("'" & $C7 & "'!$B:$B"), 0),":",MATCH($D7, INDIRECT("'" & $C7 & "'!$B:$B"), 0))),0)),"/",$C7,"/",MID($D7,1,FIND("_",$D7)-1),"/",INDIRECT(CONCATENATE("'" & $C7 & "'!",ADDRESS(MATCH($D7, INDIRECT("'" & $C7 & "'!$B:$B"), 0),MATCH(J$1, INDIRECT("'" & $C7 & "'!$1:$1"), 0)))),".",INDIRECT(CONCATENATE("'"&$C7&"'!",ADDRESS(MATCH($D7,INDIRECT("'"&$C7&"'!$B:$B"),0),3))),"#page=",J8),CONCATENATE("#Sharepoint//",$D7))} -> #Sharepoint//FS_TT2
E8: Rif. Pagina | F8: 171 | J8: 131
E9: Componenti circuito elettrico | F9: EVFS1 = Valvola applicazione parking brake JE-K009 = RIO JE-K010 = RIO GG-K016 = Relè RER | J9: GG-K016 = Relè RER GG-K028 = Relè di taglio per il comando di rilascio del PB dato da TCMS attraverso BRA_EVFS1_COM EVFS1 = Valvola applicazione parking brake JE-K009 = RIO JE-K010 = RIO
E10: Descrizione circuitale | F10: Il segnale di rilascio del praking brake verso la EVFS1 viene fornito dalle RIO BRA-EVFS1_COM. Il comando verso EVFS1 è sezionato solamente da un relè GG-K016 chiamato RER che si abilita con un contatto relativo all'inserzione della chiave di banco | J10: Il comando di GG-K028 è dato dalla catena circuitale introdotta nelle DM che serve a evitare che il TCMS possa comandare impropriamente il circuito di rilascio del freno di stazionamento chiamato anche Parking brake oppure Freno a molla FAM. Il comando verso EVFS1 è sezionato pertanto da un relè GG-K016 chiamato RER che si abilita con un contatto relativo all'inserzione della chiave di banco e dal relè GG-K028 facente capo alla catena introdotta nelle DM rispetto al circuito della flotta base. Lo stato di quest'ultimo relè è diagnosticato tramite 2 ingressi RIO ridondati chiamati BRA_EVFS1-PRO_N e BRA_EVFS1-PRO_R
C11: CONFIG | D11: FRS_Brake Control | E11: Link | F11: {=HYPERLINK(CONCATENATE(Cartelle!$D$5,F$1,"/",$C11,"/",MID($D11,1,FIND("_",$D11)-1),"/",INDIRECT(CONCATENATE("'" & $C11 & "'!",ADDRESS(MATCH($D11, INDIRECT("'" & $C11 & "'!$B:$B"), 0),MATCH(F$1, INDIRECT("'" & $C11 & "'!$1:$1"), 0)))),".",INDIRECT(CONCATENATE("'"&$C11&"'!",ADDRESS(MATCH($D11,INDIRECT("'"&$C11&"'!$B:$B"),0),3))),"#page=",F12),CONCATENATE("#Sharepoint//",$D11))} -> #Sharepoint//FRS_Brake Control | J11: {=HYPERLINK(CONCATENATE(Cartelle!$D$5,INDEX(INDIRECT("'" & $C11 & "'!$1:$1"), 1, MATCH(INDIRECT(CONCATENATE("'" & $C11 & "'!",ADDRESS(MATCH($D11, INDIRECT("'" & $C11 & "'!$B:$B"), 0),MATCH(J$1, INDIRECT("'" & $C11 & "'!$1:$1"), 0)))),INDIRECT(CONCATENATE("'" & $C11 & "'!",MATCH($D11, INDIRECT("'" & $C11 & "'!$B:$B"), 0),":",MATCH($D11, INDIRECT("'" & $C11 & "'!$B:$B"), 0))),0)),"/",$C11,"/",MID($D11,1,FIND("_",$D11)-1),"/",INDIRECT(CONCATENATE("'" & $C11 & "'!",ADDRESS(MATCH($D11, INDIRECT("'" & $C11 & "'!$B:$B"), 0),MATCH(J$1, INDIRECT("'" & $C11 & "'!$1:$1"), 0)))),".",INDIRECT(CONCATENATE("'"&$C11&"'!",ADDRESS(MATCH($D11,INDIRECT("'"&$C11&"'!$B:$B"),0),3))),"#page=",J12),CONCATENATE("#Sharepoint//",$D11))} -> #Sharepoint//FRS_Brake Control
E12: Rif. Pagina | F12: 117 | J12: 154
E13: Requisiti specifici | F13: \ | J13: Rispetto a FRS VZI_Base, aggiunto requisiti .3980 e .TRS.343 per inibire elettricamente il TCMS in caso di comando di sblocco PB non dovuto. Tali requisiti sono stati implementati con il circuito di cui alle descrizioni circuitali di cui sopra, il quale utilizza gli ingressi di comando BRA_PARK_COM di comando e lo stato delle variabili BRA_EVFS1-PRO_N e BRA_EVFS1-PRO_R per verificare che sia stato comandato effettivamente un rilascio da pulsante e da macchinista, e che non sia stato rilasciato esclusivamente dal TCMS
C14: CONFIG | D14: FPD_Brake Control | E14: Link | F14: {=HYPERLINK(CONCATENATE(Cartelle!$D$5,F$1,"/",$C14,"/",MID($D14,1,FIND("_",$D14)-1),"/",INDIRECT(CONCATENATE("'" & $C14 & "'!",ADDRESS(MATCH($D14, INDIRECT("'" & $C14 & "'!$B:$B"), 0),MATCH(F$1, INDIRECT("'" & $C14 & "'!$1:$1"), 0)))),".",INDIRECT(CONCATENATE("'"&$C14&"'!",ADDRESS(MATCH($D14,INDIRECT("'"&$C14&"'!$B:$B"),0),3))),"#page=",F15),CONCATENATE("#Sharepoint//",$D14))} -> #Sharepoint//FPD_Brake Control | J14: {=HYPERLINK(CONCATENATE(Cartelle!$D$5,INDEX(INDIRECT("'" & $C14 & "'!$1:$1"), 1, MATCH(INDIRECT(CONCATENATE("'" & $C14 & "'!",ADDRESS(MATCH($D14, INDIRECT("'" & $C14 & "'!$B:$B"), 0),MATCH(J$1, INDIRECT("'" & $C14 & "'!$1:$1"), 0)))),INDIRECT(CONCATENATE("'" & $C14 & "'!",MATCH($D14, INDIRECT("'" & $C14 & "'!$B:$B"), 0),":",MATCH($D14, INDIRECT("'" & $C14 & "'!$B:$B"), 0))),0)),"/",$C14,"/",MID($D14,1,FIND("_",$D14)-1),"/",INDIRECT(CONCATENATE("'" & $C14 & "'!",ADDRESS(MATCH($D14, INDIRECT("'" & $C14 & "'!$B:$B"), 0),MATCH(J$1, INDIRECT("'" & $C14 & "'!$1:$1"), 0)))),".",INDIRECT(CONCATENATE("'"&$C14&"'!",ADDRESS(MATCH($D14,INDIRECT("'"&$C14&"'!$B:$B"),0),3))),"#page=",J15),CONCATENATE("#Sharepoint//",$D14))} -> #Sharepoint//FPD_Brake Control
E15: Rif. Pagina | F15: 18 | J15: 18
A16: Hot_Axle_Box_01 | B16: Funzione di monitoraggio Hot Axle Box Detection (HABD) | D16: =IF($A16="","",HYPERLINK(CONCATENATE(Cartelle!$D$6,$A16),CONCATENATE("#Sharepoint//",$A16))) -> #Sharepoint//Hot_Axle_Box_01
C17: CONFIG | D17: FS_DM1 | E17: Link | F17: {=HYPERLINK(CONCATENATE(Cartelle!$D$5,F$1,"/",$C17,"/",MID($D17,1,FIND("_",$D17)-1),"/",INDIRECT(CONCATENATE("'" & $C17 & "'!",ADDRESS(MATCH($D17, INDIRECT("'" & $C17 & "'!$B:$B"), 0),MATCH(F$1, INDIRECT("'" & $C17 & "'!$1:$1"), 0)))),".",INDIRECT(CONCATENATE("'"&$C17&"'!",ADDRESS(MATCH($D17,INDIRECT("'"&$C17&"'!$B:$B"),0),3))),"#page=",F18),CONCATENATE("#Sharepoint//",$D17))} -> #Sharepoint//FS_DM1 | J17: {=HYPERLINK(CONCATENATE(Cartelle!$D$5,INDEX(INDIRECT("'" & $C17 & "'!$1:$1"), 1, MATCH(INDIRECT(CONCATENATE("'" & $C17 & "'!",ADDRESS(MATCH($D17, INDIRECT("'" & $C17 & "'!$B:$B"), 0),MATCH(J$1, INDIRECT("'" & $C17 & "'!$1:$1"), 0)))),INDIRECT(CONCATENATE("'" & $C17 & "'!",MATCH($D17, INDIRECT("'" & $C17 & "'!$B:$B"), 0),":",MATCH($D17, INDIRECT("'" & $C17 & "'!$B:$B"), 0))),0)),"/",$C17,"/",MID($D17,1,FIND("_",$D17)-1),"/",INDIRECT(CONCATENATE("'" & $C17 & "'!",ADDRESS(MATCH($D17, INDIRECT("'" & $C17 & "'!$B:$B"), 0),MATCH(J$1, INDIRECT("'" & $C17 & "'!$1:$1"), 0)))),".",INDIRECT(CONCATENATE("'"&$C17&"'!",ADDRESS(MATCH($D17,INDIRECT("'"&$C17&"'!$B:$B"),0),3))),"#page=",J18),CONCATENATE("#Sharepoint//",$D17))} -> #Sharepoint//FS_DM1
E18: Rif. Pagina | F18: 388 | J18: 264
E19: Componenti circuito elettrico | F19: GC-Q024 = Relè abilitazione cabina LCA GC-Q026 = Relè abilitazione cabina LCA SB-K018 = Relè accoppiamento JB-K003 = Relè apertura Loop HABD JB-K004 = Relè apertura Loop HABD GG-K016 = Relè apertura Loop DNRA GG-K017 = Relè apertura Loop DNRA GC-A018 H2B = spia Locked Axle | J19: JB-K003 = Relè apertura Loop HABD JB-K004 = Relè apertura Loop HABD JE-K009 = RIO OTC_FUSE_LOOP JE-K010 = RIO OTC_FUSE LOOP GC-A018 H2B = spia HABD Alarm
E20: Descrizione circuitale | F20: L'informazione di apertura loop HBDA è data dai termofusibili, essa comanda la disalimetazione dei relè JB-K003 e JB-K004, questi tramite i contatti AI-B1 passano l'informazione al TCMS, OTC_FUSE_LOOP. L'accensione della spia HABD-DNRA deriva daii contatti C1-D1 e C3-D3 di JB-K003 e JB-K004, i quali comandano il loop DNRA stesso. L'informazione di apertura è propagata dai contatti di JB-K003 e JB-K004 verso i relè GG-K016 e GG-K017 i quali comandano l'accensione della spia GC-A018. Il filo treno-loop DNRA viene alimentato alla tensione di batteria nella cabina non abilitata attraverso l’interruttore magnetotermico di protezione GG-F004 e i contatti del relè di accoppiamento Rcm SB-K018 e di abilitazione cabina LCA. GC-Q024 e Q026 | J20: L'informazione di apertura loop HABDA è data dai termofusibili, essa comanda la disalimetazione dei relè JB-K003 e JB-K004, questi tramite i contatti A1 - B1 passano l'informazione al TCMS tramite i DI RIO JE-K009 e JE-K010, OTC_FUSE_LOOP. Il TCMS a seguito comanda l'accensione della spia GC-A18 relativa al solo allarme HABD, tramite le uscite JE-K005 e JE-K006, OTC_HABD_ALARM
C21: CONFIG | D21: FRS_Bogies | E21: Link | F21: {=HYPERLINK(CONCATENATE(Cartelle!$D$5,F$1,"/",$C21,"/",MID($D21,1,FIND("_",$D21)-1),"/",INDIRECT(CONCATENATE("'" & $C21 & "'!",ADDRESS(MATCH($D21, INDIRECT("'" & $C21 & "'!$B:$B"), 0),MATCH(F$1, INDIRECT("'" & $C21 & "'!$1:$1"), 0)))),".",INDIRECT(CONCATENATE("'"&$C21&"'!",ADDRESS(MATCH($D21,INDIRECT("'"&$C21&"'!$B:$B"),0),3))),"#page=",F22),CONCATENATE("#Sharepoint//",$D21))} -> #Sharepoint//FRS_Bogies | G21: {=HYPERLINK(CONCATENATE(Cartelle!$D$5,INDEX(INDIRECT("'" & $C21 & "'!$1:$1"), 1, MATCH(INDIRECT(CONCATENATE("'" & $C21 & "'!",ADDRESS(MATCH($D21, INDIRECT("'" & $C21 & "'!$B:$B"), 0),MATCH(G$1, INDIRECT("'" & $C21 & "'!$1:$1"), 0)))),INDIRECT(CONCATENATE("'" & $C21 & "'!",MATCH($D21, INDIRECT("'" & $C21 & "'!$B:$B"), 0),":",MATCH($D21, INDIRECT("'" & $C21 & "'!$B:$B"), 0))),0)),"/",$C21,"/",MID($D21,1,FIND("_",$D21)-1),"/",INDIRECT(CONCATENATE("'" & $C21 & "'!",ADDRESS(MATCH($D21, INDIRECT("'" & $C21 & "'!$B:$B"), 0),MATCH(G$1, INDIRECT("'" & $C21 & "'!$1:$1"), 0)))),".",INDIRECT(CONCATENATE("'"&$C21&"'!",ADDRESS(MATCH($D21,INDIRECT("'"&$C21&"'!$B:$B"),0),3))),"#page=",G22),CONCATENATE("#Sharepoint//",$D21))} -> #Sharepoint//FRS_Bogies | J21: {=HYPERLINK(CONCATENATE(Cartelle!$D$5,INDEX(INDIRECT("'" & $C21 & "'!$1:$1"), 1, MATCH(INDIRECT(CONCATENATE("'" & $C21 & "'!",ADDRESS(MATCH($D21, INDIRECT("'" & $C21 & "'!$B:$B"), 0),MATCH(J$1, INDIRECT("'" & $C21 & "'!$1:$1"), 0)))),INDIRECT(CONCATENATE("'" & $C21 & "'!",MATCH($D21, INDIRECT("'" & $C21 & "'!$B:$B"), 0),":",MATCH($D21, INDIRECT("'" & $C21 & "'!$B:$B"), 0))),0)),"/",$C21,"/",MID($D21,1,FIND("_",$D21)-1),"/",INDIRECT(CONCATENATE("'" & $C21 & "'!",ADDRESS(MATCH($D21, INDIRECT("'" & $C21 & "'!$B:$B"), 0),MATCH(J$1, INDIRECT("'" & $C21 & "'!$1:$1"), 0)))),".",INDIRECT(CONCATENATE("'"&$C21&"'!",ADDRESS(MATCH($D21,INDIRECT("'"&$C21&"'!$B:$B"),0),3))),"#page=",J22),CONCATENATE("#Sharepoint//",$D21))} -> #Sharepoint//FRS_Bogies
E22: Rif. Pagina | F22: 14 | G22: 12 | J22: 1
E23: Requisiti specifici | F23: Europe.CONCEPT.392: in caso di bypass DNRA, limite velocità a 200 km/h Europe.CONCEPT.355: evento di warning se Temp gearbox >= 145 °C | G23: Europe.CONCEPT.392: in caso di bypass DNRA, limite velocità inibito se attivo stato "DNRA - BMS Local Monitoring" Europe.CONCEPT.355: evento di warning se Temp gearbox >= 135 °C Europe.CONCEPT.377: generazione evento di warning o allarme in base a gradiente temperatura Europe.CONCEPT.380: mantenimento in memoria degli allarmi generati dalle letture PT100 Europe.CONCEPT.381: introduzione dell'evento di reset allarme tramite softkey Europe.CONCEPT.378: in caso di allarme temp riduttore, il TCMS applica un blocco alla trazione se la di vel è > 80 km/h, che si ripristina quando la vel scende < 80 km/h con manipolatore T/F in coasting Europe.CONCEPT.383: il limite di vel si disattiva quando il PDC resetta l'allarme di temp, anche se la condizione di allarme è ancora presente Europe.CONCEPT.384: la limitazione di vel si riattiva in caso l'allarme, precedentemente resettato, si ripresenti | J23: TBD
C24: CONFIG | D24: FPD_xx | E24: Link | F24: {=HYPERLINK(CONCATENATE(Cartelle!$D$5,F$1,"/",$C24,"/",MID($D24,1,FIND("_",$D24)-1),"/",INDIRECT(CONCATENATE("'" & $C24 & "'!",ADDRESS(MATCH($D24, INDIRECT("'" & $C24 & "'!$B:$B"), 0),MATCH(F$1, INDIRECT("'" & $C24 & "'!$1:$1"), 0)))),".pdf#page=",F25),CONCATENATE("#Sharepoint//",$D24))} -> #N/A | J24: {=HYPERLINK(CONCATENATE(Cartelle!$D$5,J$1,"/CONFIG/",MID($D24,1,FIND("_",$D24)-1),"/",INDIRECT(CONCATENATE("'CONFIG'!",ADDRESS(MATCH($D24, CONFIG!$B:$B, 0),MATCH(J$1, CONFIG!$1:$1, 0)))),".pdf#page=",J25),CONCATENATE("#Sharepoint//",$D24))} -> #N/A
E25: Rif. Pagina | F25: 1 | J25: 1
A26: Func_XXX | B26: xxxxx | C26: HW + SW | D26: \
C27: CONFIG | D27: FS_DM1 | E27: Link | F27: {=HYPERLINK(CONCATENATE(Cartelle!$D$5,F$1,"/",$C27,"/",MID($D27,1,FIND("_",$D27)-1),"/",INDIRECT(CONCATENATE("'" & $C27 & "'!",ADDRESS(MATCH($D27, INDIRECT("'" & $C27 & "'!$B:$B"), 0),MATCH(F$1, INDIRECT("'" & $C27 & "'!$1:$1"), 0)))),".",INDIRECT(CONCATENATE("'"&$C27&"'!",ADDRESS(MATCH($D27,INDIRECT("'"&$C27&"'!$B:$B"),0),3))),"#page=",F28),CONCATENATE("#Sharepoint//",$D27))} -> #Sharepoint//FS_DM1 | J27: {=HYPERLINK(CONCATENATE(Cartelle!$D$5,INDEX(INDIRECT("'" & $C27 & "'!$1:$1"), 1, MATCH(INDIRECT(CONCATENATE("'" & $C27 & "'!",ADDRESS(MATCH($D27, INDIRECT("'" & $C27 & "'!$B:$B"), 0),MATCH(J$1, INDIRECT("'" & $C27 & "'!$1:$1"), 0)))),INDIRECT(CONCATENATE("'" & $C27 & "'!",MATCH($D27, INDIRECT("'" & $C27 & "'!$B:$B"), 0),":",MATCH($D27, INDIRECT("'" & $C27 & "'!$B:$B"), 0))),0)),"/",$C27,"/",MID($D27,1,FIND("_",$D27)-1),"/",INDIRECT(CONCATENATE("'" & $C27 & "'!",ADDRESS(MATCH($D27, INDIRECT("'" & $C27 & "'!$B:$B"), 0),MATCH(J$1, INDIRECT("'" & $C27 & "'!$1:$1"), 0)))),".",INDIRECT(CONCATENATE("'"&$C27&"'!",ADDRESS(MATCH($D27,INDIRECT("'"&$C27&"'!$B:$B"),0),3))),"#page=",J28),CONCATENATE("#Sharepoint//",$D27))} -> #Sharepoint//FS_DM1
B28: {=INDIRECT("'" & $C33 & "'!B5")} -> PBS_01A | E28: Rif. Pagina | F28: 1 | J28: 1
C29: CONFIG | D29: FRS_xx | E29: Link | F29: {=HYPERLINK(CONCATENATE(Cartelle!$D$5,F$1,"/CONFIG/",MID($D29,1,FIND("_",$D29)-1),"/",INDIRECT(CONCATENATE("'CONFIG'!",ADDRESS(MATCH($D29, CONFIG!$B:$B, 0),MATCH(F$1, CONFIG!$1:$1, 0)))),".pdf#page=",F30),CONCATENATE("#Sharepoint//",$D29))} -> #N/A | J29: {=HYPERLINK(CONCATENATE(Cartelle!$D$5,J$1,"/CONFIG/",MID($D29,1,FIND("_",$D29)-1),"/",INDIRECT(CONCATENATE("'CONFIG'!",ADDRESS(MATCH($D29, CONFIG!$B:$B, 0),MATCH(J$1, CONFIG!$1:$1, 0)))),".pdf#page=",J30),CONCATENATE("#Sharepoint//",$D29))} -> #N/A
E30: Rif. Pagina | F30: 1 | J30: 1
C31: CONFIG | D31: FPD_xx | E31: Link | F31: {=HYPERLINK(CONCATENATE(Cartelle!$D$5,F$1,"/CONFIG/",MID($D31,1,FIND("_",$D31)-1),"/",INDIRECT(CONCATENATE("'CONFIG'!",ADDRESS(MATCH($D31, CONFIG!$B:$B, 0),MATCH(F$1, CONFIG!$1:$1, 0)))),".pdf#page=",F32),CONCATENATE("#Sharepoint//",$D31))} -> #N/A | J31: {=HYPERLINK(CONCATENATE(Cartelle!$D$5,J$1,"/CONFIG/",MID($D31,1,FIND("_",$D31)-1),"/",INDIRECT(CONCATENATE("'CONFIG'!",ADDRESS(MATCH($D31, CONFIG!$B:$B, 0),MATCH(J$1, CONFIG!$1:$1, 0)))),".pdf#page=",J32),CONCATENATE("#Sharepoint//",$D31))} -> #N/A
E32: Rif. Pagina | F32: 1 | J32: 1
C33: MAN_CPR | D33: PBC_01A | E33: Link | F33: {=HYPERLINK(CONCATENATE(Cartelle!$D$5,F$1,"/",$C33,"/",MID($D33,1,FIND("_",$D33)-1),"/",INDIRECT(CONCATENATE("'" & $C33 & "'!",ADDRESS(MATCH($D33, INDIRECT("'" & $C33 & "'!$B:$B"), 0),MATCH(F$1, INDIRECT("'" & $C33 & "'!$1:$1"), 0)))),".",INDIRECT(CONCATENATE("'"&$C33&"'!",ADDRESS(MATCH($D33,INDIRECT("'"&$C33&"'!$B:$B"),0),3))),"#page=",F34),CONCATENATE("#Sharepoint//",$D33))} -> #Sharepoint//PBC_01A | G33: {=HYPERLINK(CONCATENATE(Cartelle!$D$5,INDEX(INDIRECT("'" & $C33 & "'!$1:$1"), 1, MATCH(INDIRECT(CONCATENATE("'" & $C33 & "'!",ADDRESS(MATCH($D33, INDIRECT("'" & $C33 & "'!$B:$B"), 0),MATCH(G$1, INDIRECT("'" & $C33 & "'!$1:$1"), 0)))),INDIRECT(CONCATENATE("'" & $C33 & "'!",MATCH($D33, INDIRECT("'" & $C33 & "'!$B:$B"), 0),":",MATCH($D33, INDIRECT("'" & $C33 & "'!$B:$B"), 0))),0)),"/",$C33,"/",MID($D33,1,FIND("_",$D33)-1),"/",INDIRECT(CONCATENATE("'" & $C33 & "'!",ADDRESS(MATCH($D33, INDIRECT("'" & $C33 & "'!$B:$B"), 0),MATCH(G$1, INDIRECT("'" & $C33 & "'!$1:$1"), 0)))),".",INDIRECT(CONCATENATE("'"&$C33&"'!",ADDRESS(MATCH($D33,INDIRECT("'"&$C33&"'!$B:$B"),0),3))),"#page=",G34),CONCATENATE("#Sharepoint//",$D33))} -> #Sharepoint//PBC_01A
E34: Rif. Pagina | F34: 1 | G34: 1
E35: Descrizione
C36: DIAGNOSTIC | D36: DIA_Regole | E36: Link | F36: {=HYPERLINK(CONCATENATE(Cartelle!$D$5,F$1,"/",$C36,"/",MID($D36,1,FIND("_",$D36)-1),"/",INDIRECT(CONCATENATE("'" & $C36 & "'!",ADDRESS(MATCH($D36, INDIRECT("'" & $C36 & "'!$B:$B"), 0),MATCH(F$1, INDIRECT("'" & $C36 & "'!$1:$1"), 0)))),".",INDIRECT(CONCATENATE("'"&$C36&"'!",ADDRESS(MATCH($D36,INDIRECT("'"&$C36&"'!$B:$B"),0),3))),"#page=",F37),CONCATENATE("#Sharepoint//",$D36))} -> #Sharepoint//DIA_Regole
E37: Pagina | F37: 1
B38: TBD Sottocartelle GENERAL sulla base del prefisso | C38: GENERAL | D38: FD_TCMS | E38: Link | F38: {=HYPERLINK(CONCATENATE(Cartelle!$D$5,F$1,"/",$C38,"/",MID($D38,1,FIND("_",$D38)-1),"/",INDIRECT(CONCATENATE("'" & $C38 & "'!",ADDRESS(MATCH($D38, INDIRECT("'" & $C38 & "'!$B:$B"), 0),MATCH(F$1, INDIRECT("'" & $C38 & "'!$1:$1"), 0)))),".",INDIRECT(CONCATENATE("'"&$C38&"'!",ADDRESS(MATCH($D38,INDIRECT("'"&$C38&"'!$B:$B"),0),3))),"#page=",F39),CONCATENATE("#Sharepoint//",$D38))} -> #Sharepoint//FD_TCMS
E39: Pagina | F39: 1
A40: LV_Country_code_selection | B40: Selezione su IDU del paese corrente, per informare la PCU sui pantografi selezionabili | D40: \
...

Sheet PBS (TBD)
A1: Impianto | B1: Gruppo/Componente | C1: P/N | D1: Applicabilità flotte | K1: Manuale | N1: CPR | Q1: Raccolta doc | S1: Schema elettrico | U1: Schema Pneumatico
D2: VZI_Base | E2: VZI_New14 | F2: VZ_FR | G2: VZ_ES | H2: VZI-6_R1 | I2: VZI-4_R1 | J2: VZ_DAI | K2: File | L2: Pag | M2: Link | N2: File | O2: Pag | P2: Link | Q2: Cartella | R2: Link | S2: Pag | T2: Link | U2: Pag | V2: Link
A3: PANTOGRAFO | D3: . | E3: . | F3: . | G3: . | H3: . | I3: . | J3: .
B4: CAPTAZIONE | D4: .. | E4: .. | F4: .. | G4: .. | H4: .. | I4: .. | J4: ..
B5: Pantografo 25 kV | C5: 10574479 | D5: T4-T5 | E5: T4-T5 | F5: X | H5: T4-T5 | K5: ETR1000V300-MR1-04A-Equip elettrico ed elettropneumatico-06 - TOMO 1.pdf | L5: 161 | M5: =HYPERLINK(CONCATENATE(Cartelle!$A$2,Cartelle!$D$2,Cartelle!#REF!,'PBS (TBD)'!K5,"#page=",'PBS (TBD)'!L5),"#") -> #REF! | N5: ETR1000-CPR_04C_2.05.1002_Pantografo_Mar21.pdf | O5: 93 | P5: =HYPERLINK(CONCATENATE(Cartelle!$A$2,Cartelle!#REF!,Cartelle!#REF!,'PBS (TBD)'!N5,"#page=",'PBS (TBD)'!O5),"#") -> #REF!
B6: Pantografo 3 kV | C6: 10542152 | D6: TT2-TT7 | E6: TT2-TT7 | F6: X | H6: TT2-TT7 | K6: ETR1000V300-MR1-04A-Equip elettrico ed elettropneumatico-06 - TOMO 1.pdf | L6: 180 | M6: =HYPERLINK(CONCATENATE(Cartelle!$A$2,Cartelle!$D$2,Cartelle!#REF!,'PBS (TBD)'!K6,"#page=",'PBS (TBD)'!L6),"#") -> #REF! | N6: ETR1000-CPR_04C_2.05.1002_Pantografo_Mar21.pdf | O6: 33 | P6: =HYPERLINK(CONCATENATE(Cartelle!$A$2,Cartelle!#REF!,Cartelle!#REF!,'PBS (TBD)'!N6,"#page=",'PBS (TBD)'!O6),"#") -> #REF!
B7: Pantografo 1,5 kV
B8: CONTROLLO | D8: .. | E8: .. | F8: .. | G8: .. | H8: .. | I8: .. | J8: ..
B9: PPU | C9: 0102895 | D9: TT2-T4-T5-TT7
B10: PPU | C10: 232C10395F | E10: TT2-T4-T5-TT7 | Q10: 232C10395F | R10: =HYPERLINK(CONCATENATE(Cartelle!$A$2,Cartelle!#REF!,'PBS (TBD)'!Q10),"#") -> #REF!
B11: PPU | C11: 231C100036B | H11: TT2-T4-T5-TT7
A12: TCMS | D12: . | E12: . | F12: . | G12: . | H12: . | I12: . | J12: .
B13: CONTROLLO | D13: .. | E13: .. | F13: .. | G13: .. | H13: .. | I13: .. | J13: ..
B14: CCU-O Dual MVB (DCY1110B) | C14: 3EST000225-5707 | D14: DM1-DM8 | E14: DM1-DM8 | K14: ETR1000V300-MR1-05A-Logica di comando-03.pdf | L14: 113 | M14: =HYPERLINK(CONCATENATE(Cartelle!$A$2,Cartelle!$D$2,Cartelle!#REF!,'PBS (TBD)'!K14,"#page=",'PBS (TBD)'!L14),"#") -> #REF! | N14: ETR1000-CPR_05_2.05.1004_Logica di comando_Aprile2021.pdf | O14: 48 | P14: =HYPERLINK(CONCATENATE(Cartelle!$A$2,Cartelle!#REF!,Cartelle!#REF!,'PBS (TBD)'!N14,"#page=",'PBS (TBD)'!O14),"#") -> #REF!
B15: CCU-C 2ETH (DCY1550A) | C15: 3EST000225-5711 | D15: DM1-M3-DM8 | E15: DM1-M3-DM8 | K15: ETR1000V300-MR1-05A-Logica di comando-03.pdf | L15: 121 | M15: =HYPERLINK(CONCATENATE(Cartelle!$A$2,Cartelle!$D$2,Cartelle!#REF!,'PBS (TBD)'!K15,"#page=",'PBS (TBD)'!L15),"#") -> #REF! | N15: ETR1000-CPR_05_2.05.1004_Logica di comando_Aprile2021.pdf | O15: 52 | P15: =HYPERLINK(CONCATENATE(Cartelle!$A$2,Cartelle!#REF!,Cartelle!#REF!,'PBS (TBD)'!N15,"#page=",'PBS (TBD)'!O15),"#") -> #REF!
B16: CCU-S (DCY 1660A) | C16: 3EST000221-6430 | D16: DM1-DM8 | E16: DM1-DM8 | K16: ETR1000V300-MR1-05A-Logica di comando-03.pdf | L16: 124 | M16: =HYPERLINK(CONCATENATE(Cartelle!$A$2,Cartelle!$D$2,Cartelle!#REF!,'PBS (TBD)'!K16,"#page=",'PBS (TBD)'!L16),"#") -> #REF! | N16: ETR1000-CPR_05_2.05.1004_Logica di comando_Aprile2021.pdf | O16: 44 | P16: =HYPERLINK(CONCATENATE(Cartelle!$A$2,Cartelle!#REF!,Cartelle!#REF!,'PBS (TBD)'!N16,"#page=",'PBS (TBD)'!O16),"#") -> #REF!
B17: MIO-DXH4-S (DCS 2222B) | C17: 3EST000228-0629 | D17: DM1-DM8 | K17: ETR1000V300-MR1-05A-Logica di comando-03.pdf | L17: 175 | M17: =HYPERLINK(CONCATENATE(Cartelle!$A$2,Cartelle!$D$2,Cartelle!#REF!,'PBS (TBD)'!K17,"#page=",'PBS (TBD)'!L17),"#") -> #REF! | N17: ETR1000-CPR_05_2.05.1004_Logica di comando_Aprile2021.pdf | O17: 70 | P17: =HYPERLINK(CONCATENATE(Cartelle!$A$2,Cartelle!#REF!,Cartelle!#REF!,'PBS (TBD)'!N17,"#page=",'PBS (TBD)'!O17),"#") -> #REF!
B18: MIO-S (DCS 2222C) | C18: 3EST000230-5830 | E18: DM1-DM8 | N18: ETR1000-CPR_05_2.05.1004_Logica di comando_Aprile2021.pdf | O18: 28 | P18: =HYPERLINK(CONCATENATE(Cartelle!$A$2,Cartelle!#REF!,Cartelle!#REF!,'PBS (TBD)'!N18,"#page=",'PBS (TBD)'!O18),"#") -> #REF!
